2018-07-13 14:40:56,026 /Users/Shared/dbj/api.kuaibi/micro_service/common/logger.py[func:__init__ line:23] [INFO] init log
2018-07-13 14:43:47,686 /Users/Shared/dbj/api.kuaibi/micro_service/common/logger.py[func:__init__ line:23] [INFO] init log
2018-07-13 14:43:49,062 /Users/Shared/dbj/api.kuaibi/micro_service/main.py[func:<module> line:19] [ERROR] error
2018-07-13 14:43:49,062 /Users/Shared/dbj/api.kuaibi/micro_service/main.py[func:<module> line:20] [DEBUG] debug
2018-07-13 14:44:26,362 /Users/Shared/dbj/api.kuaibi/micro_service/common/logger.py[func:__init__ line:23] [INFO] init log
2018-07-13 14:44:27,307 /Users/Shared/dbj/api.kuaibi/micro_service/main.py[func:<module> line:19] [ERROR] error
2018-07-13 14:44:27,307 /Users/Shared/dbj/api.kuaibi/micro_service/main.py[func:<module> line:20] [DEBUG] debug
2018-07-13 14:44:27,553 /usr/local/Cellar/python3/3.6.1/Frameworks/Python.framework/Versions/3.6/lib/python3.6/site-packages/werkzeug/_internal.py[func:_log line:88] [INFO]  * Running on http://0.0.0.0:5002/ (Press CTRL+C to quit)
2018-07-13 14:44:27,642 /usr/local/Cellar/python3/3.6.1/Frameworks/Python.framework/Versions/3.6/lib/python3.6/site-packages/werkzeug/_internal.py[func:_log line:88] [INFO]  * Restarting with fsevents reloader
2018-07-13 14:44:28,923 /Users/Shared/dbj/api.kuaibi/micro_service/common/logger.py[func:__init__ line:23] [INFO] init log
2018-07-13 14:44:29,795 /Users/Shared/dbj/api.kuaibi/micro_service/main.py[func:<module> line:19] [ERROR] error
2018-07-13 14:44:29,795 /Users/Shared/dbj/api.kuaibi/micro_service/main.py[func:<module> line:20] [DEBUG] debug
2018-07-13 14:44:30,026 /usr/local/lib/python3.6/site-packages/werkzeug/_internal.py[func:_log line:88] [WARNING]  * Debugger is active!
2018-07-13 14:44:30,064 /usr/local/lib/python3.6/site-packages/werkzeug/_internal.py[func:_log line:88] [INFO]  * Debugger PIN: 202-833-239
2018-07-13 14:45:54,133 /Users/Shared/dbj/api.kuaibi/micro_service/common/logger.py[func:__init__ line:23] [INFO] init log
2018-07-13 14:45:55,366 /Users/Shared/dbj/api.kuaibi/micro_service/main.py[func:<module> line:19] [ERROR] error
2018-07-13 14:45:55,367 /Users/Shared/dbj/api.kuaibi/micro_service/main.py[func:<module> line:20] [DEBUG] debug
2018-07-13 14:45:55,604 /usr/local/Cellar/python3/3.6.1/Frameworks/Python.framework/Versions/3.6/lib/python3.6/site-packages/werkzeug/_internal.py[func:_log line:88] [INFO]  * Running on http://0.0.0.0:5002/ (Press CTRL+C to quit)
2018-07-13 14:45:55,677 /usr/local/Cellar/python3/3.6.1/Frameworks/Python.framework/Versions/3.6/lib/python3.6/site-packages/werkzeug/_internal.py[func:_log line:88] [INFO]  * Restarting with fsevents reloader
2018-07-13 14:45:56,805 /Users/Shared/dbj/api.kuaibi/micro_service/common/logger.py[func:__init__ line:23] [INFO] init log
2018-07-13 14:45:57,626 /Users/Shared/dbj/api.kuaibi/micro_service/main.py[func:<module> line:19] [ERROR] error
2018-07-13 14:45:57,626 /Users/Shared/dbj/api.kuaibi/micro_service/main.py[func:<module> line:20] [DEBUG] debug
2018-07-13 14:45:57,843 /usr/local/lib/python3.6/site-packages/werkzeug/_internal.py[func:_log line:88] [WARNING]  * Debugger is active!
2018-07-13 14:45:57,883 /usr/local/lib/python3.6/site-packages/werkzeug/_internal.py[func:_log line:88] [INFO]  * Debugger PIN: 202-833-239
2018-07-13 14:46:18,781 /usr/local/lib/python3.6/site-packages/werkzeug/_internal.py[func:_log line:88] [INFO]  * Detected change in '/Users/Shared/dbj/api.kuaibi/micro_service/micro_services/api_kuaibiji/service.py', reloading
2018-07-13 14:46:18,783 /usr/local/lib/python3.6/site-packages/werkzeug/_internal.py[func:_log line:88] [INFO]  * Detected change in '/Users/Shared/dbj/api.kuaibi/micro_service/micro_services/api_kuaibiji/service.py', reloading
2018-07-13 14:46:21,447 /Users/Shared/dbj/api.kuaibi/micro_service/common/logger.py[func:__init__ line:23] [INFO] init log
2018-07-13 14:46:22,469 /Users/Shared/dbj/api.kuaibi/micro_service/main.py[func:<module> line:19] [ERROR] error
2018-07-13 14:46:22,470 /Users/Shared/dbj/api.kuaibi/micro_service/main.py[func:<module> line:20] [DEBUG] debug
2018-07-13 14:46:22,702 /usr/local/Cellar/python3/3.6.1/Frameworks/Python.framework/Versions/3.6/lib/python3.6/site-packages/werkzeug/_internal.py[func:_log line:88] [INFO]  * Running on http://0.0.0.0:5002/ (Press CTRL+C to quit)
2018-07-13 14:46:22,771 /usr/local/Cellar/python3/3.6.1/Frameworks/Python.framework/Versions/3.6/lib/python3.6/site-packages/werkzeug/_internal.py[func:_log line:88] [INFO]  * Restarting with fsevents reloader
2018-07-13 14:46:23,914 /Users/Shared/dbj/api.kuaibi/micro_service/common/logger.py[func:__init__ line:23] [INFO] init log
2018-07-13 14:46:24,767 /Users/Shared/dbj/api.kuaibi/micro_service/main.py[func:<module> line:19] [ERROR] error
2018-07-13 14:46:24,767 /Users/Shared/dbj/api.kuaibi/micro_service/main.py[func:<module> line:20] [DEBUG] debug
2018-07-13 14:46:24,993 /usr/local/lib/python3.6/site-packages/werkzeug/_internal.py[func:_log line:88] [WARNING]  * Debugger is active!
2018-07-13 14:46:25,034 /usr/local/lib/python3.6/site-packages/werkzeug/_internal.py[func:_log line:88] [INFO]  * Debugger PIN: 202-833-239
2018-07-13 14:46:27,438 /usr/local/lib/python3.6/site-packages/werkzeug/_internal.py[func:_log line:88] [INFO] 127.0.0.1 - - [13/Jul/2018 14:46:27] "GET / HTTP/1.1" 200 -
2018-07-13 14:46:27,733 /usr/local/lib/python3.6/site-packages/werkzeug/_internal.py[func:_log line:88] [INFO] 127.0.0.1 - - [13/Jul/2018 14:46:27] "GET /favicon.ico HTTP/1.1" 404 -
2018-07-13 14:46:31,081 /usr/local/lib/python3.6/site-packages/werkzeug/_internal.py[func:_log line:88] [INFO] 127.0.0.1 - - [13/Jul/2018 14:46:31] "GET /notebook HTTP/1.1" 404 -
2018-07-13 14:46:56,287 /usr/local/lib/python3.6/site-packages/werkzeug/_internal.py[func:_log line:88] [INFO] 127.0.0.1 - - [13/Jul/2018 14:46:56] "GET /notebook/notebook HTTP/1.1" 200 -
2018-07-13 14:47:48,337 /Users/Shared/dbj/api.kuaibi/micro_service/common/logger.py[func:__init__ line:23] [INFO] init log
2018-07-13 14:47:49,558 /Users/Shared/dbj/api.kuaibi/micro_service/main.py[func:<module> line:19] [ERROR] error
2018-07-13 14:47:49,558 /Users/Shared/dbj/api.kuaibi/micro_service/main.py[func:<module> line:20] [DEBUG] debug
2018-07-13 14:47:49,804 /usr/local/Cellar/python3/3.6.1/Frameworks/Python.framework/Versions/3.6/lib/python3.6/site-packages/werkzeug/_internal.py[func:_log line:88] [INFO]  * Running on http://0.0.0.0:5002/ (Press CTRL+C to quit)
2018-07-13 14:47:49,881 /usr/local/Cellar/python3/3.6.1/Frameworks/Python.framework/Versions/3.6/lib/python3.6/site-packages/werkzeug/_internal.py[func:_log line:88] [INFO]  * Restarting with fsevents reloader
2018-07-13 14:47:51,046 /Users/Shared/dbj/api.kuaibi/micro_service/common/logger.py[func:__init__ line:23] [INFO] init log
2018-07-13 14:47:52,039 /Users/Shared/dbj/api.kuaibi/micro_service/main.py[func:<module> line:19] [ERROR] error
2018-07-13 14:47:52,039 /Users/Shared/dbj/api.kuaibi/micro_service/main.py[func:<module> line:20] [DEBUG] debug
2018-07-13 14:47:52,290 /usr/local/lib/python3.6/site-packages/werkzeug/_internal.py[func:_log line:88] [WARNING]  * Debugger is active!
2018-07-13 14:47:52,331 /usr/local/lib/python3.6/site-packages/werkzeug/_internal.py[func:_log line:88] [INFO]  * Debugger PIN: 202-833-239
2018-07-13 14:47:53,436 /usr/local/lib/python3.6/site-packages/werkzeug/_internal.py[func:_log line:88] [INFO] 127.0.0.1 - - [13/Jul/2018 14:47:53] "GET /notebook/notebook HTTP/1.1" 200 -
2018-07-13 14:48:01,429 /usr/local/lib/python3.6/site-packages/werkzeug/_internal.py[func:_log line:88] [INFO] 127.0.0.1 - - [13/Jul/2018 14:48:01] "GET /notebook/notebook HTTP/1.1" 200 -
2018-07-13 14:48:31,572 /usr/local/lib/python3.6/site-packages/werkzeug/_internal.py[func:_log line:88] [INFO] 127.0.0.1 - - [13/Jul/2018 14:48:31] "GET /notebook/notebook HTTP/1.1" 200 -
2018-07-13 14:48:54,675 /usr/local/lib/python3.6/site-packages/werkzeug/_internal.py[func:_log line:88] [INFO]  * Detected change in '/Users/Shared/dbj/api.kuaibi/micro_service/micro_services/api_kuaibiji/app/views/notebook.py', reloading
2018-07-13 14:48:54,679 /usr/local/lib/python3.6/site-packages/werkzeug/_internal.py[func:_log line:88] [INFO]  * Detected change in '/Users/Shared/dbj/api.kuaibi/micro_service/micro_services/api_kuaibiji/app/views/notebook.py', reloading
2018-07-13 14:48:59,493 /Users/Shared/dbj/api.kuaibi/micro_service/common/logger.py[func:__init__ line:23] [INFO] init log
2018-07-13 14:49:00,659 /Users/Shared/dbj/api.kuaibi/micro_service/main.py[func:<module> line:19] [ERROR] error
2018-07-13 14:49:00,660 /Users/Shared/dbj/api.kuaibi/micro_service/main.py[func:<module> line:20] [DEBUG] debug
2018-07-13 14:49:00,903 /usr/local/Cellar/python3/3.6.1/Frameworks/Python.framework/Versions/3.6/lib/python3.6/site-packages/werkzeug/_internal.py[func:_log line:88] [INFO]  * Running on http://0.0.0.0:5002/ (Press CTRL+C to quit)
2018-07-13 14:49:00,980 /usr/local/Cellar/python3/3.6.1/Frameworks/Python.framework/Versions/3.6/lib/python3.6/site-packages/werkzeug/_internal.py[func:_log line:88] [INFO]  * Restarting with fsevents reloader
2018-07-13 14:49:02,157 /Users/Shared/dbj/api.kuaibi/micro_service/common/logger.py[func:__init__ line:23] [INFO] init log
2018-07-13 14:49:02,992 /Users/Shared/dbj/api.kuaibi/micro_service/main.py[func:<module> line:19] [ERROR] error
2018-07-13 14:49:02,992 /Users/Shared/dbj/api.kuaibi/micro_service/main.py[func:<module> line:20] [DEBUG] debug
2018-07-13 14:49:03,215 /usr/local/lib/python3.6/site-packages/werkzeug/_internal.py[func:_log line:88] [WARNING]  * Debugger is active!
2018-07-13 14:49:03,252 /usr/local/lib/python3.6/site-packages/werkzeug/_internal.py[func:_log line:88] [INFO]  * Debugger PIN: 202-833-239
2018-07-13 14:49:37,007 /usr/local/lib/python3.6/site-packages/werkzeug/_internal.py[func:_log line:88] [INFO] 127.0.0.1 - - [13/Jul/2018 14:49:37] "GET /notebook/notebook HTTP/1.1" 500 -
2018-07-13 14:49:37,058 /usr/local/lib/python3.6/site-packages/werkzeug/_internal.py[func:_log line:88] [INFO] 127.0.0.1 - - [13/Jul/2018 14:49:37] "GET /notebook/notebook?__debugger__=yes&cmd=resource&f=style.css HTTP/1.1" 200 -
2018-07-13 14:49:37,063 /usr/local/lib/python3.6/site-packages/werkzeug/_internal.py[func:_log line:88] [INFO] 127.0.0.1 - - [13/Jul/2018 14:49:37] "GET /notebook/notebook?__debugger__=yes&cmd=resource&f=debugger.js HTTP/1.1" 200 -
2018-07-13 14:49:37,066 /usr/local/lib/python3.6/site-packages/werkzeug/_internal.py[func:_log line:88] [INFO] 127.0.0.1 - - [13/Jul/2018 14:49:37] "GET /notebook/notebook?__debugger__=yes&cmd=resource&f=jquery.js HTTP/1.1" 200 -
2018-07-13 14:49:37,114 /usr/local/lib/python3.6/site-packages/werkzeug/_internal.py[func:_log line:88] [INFO] 127.0.0.1 - - [13/Jul/2018 14:49:37] "GET /notebook/notebook?__debugger__=yes&cmd=resource&f=ubuntu.ttf HTTP/1.1" 200 -
2018-07-13 14:49:37,212 /usr/local/lib/python3.6/site-packages/werkzeug/_internal.py[func:_log line:88] [INFO] 127.0.0.1 - - [13/Jul/2018 14:49:37] "GET /notebook/notebook?__debugger__=yes&cmd=resource&f=console.png HTTP/1.1" 200 -
2018-07-13 14:49:37,560 /usr/local/lib/python3.6/site-packages/werkzeug/_internal.py[func:_log line:88] [INFO] 127.0.0.1 - - [13/Jul/2018 14:49:37] "GET /notebook/notebook?__debugger__=yes&cmd=resource&f=console.png HTTP/1.1" 200 -
2018-07-13 14:50:04,741 /usr/local/Cellar/python3/3.6.1/Frameworks/Python.framework/Versions/3.6/lib/python3.6/site-packages/grpc/_server.py[func:_call_behavior line:393] [ERROR] Exception calling application: filter() got an unexpected keyword argument 'id'
Traceback (most recent call last):
  File "/usr/local/Cellar/python3/3.6.1/Frameworks/Python.framework/Versions/3.6/lib/python3.6/site-packages/grpc/_server.py", line 385, in _call_behavior
    return behavior(argument, context), True
  File "/Users/Shared/dbj/api.kuaibi/micro_service/micro_services/notebook/services/notebook_service.py", line 23, in GetNotebookInfo
    return get_notebook(request, context)
  File "/Users/Shared/dbj/api.kuaibi/micro_service/micro_services/notebook/handlers/get_notebook_handler.py", line 37, in get_notebook
    books = notebook_manger.notebook_from(user_id)
  File "/Users/Shared/dbj/api.kuaibi/micro_service/micro_services/notebook/database/notebook_manger.py", line 44, in notebook_from
    res = self.session.query(model).filter(id=_id).all()
TypeError: filter() got an unexpected keyword argument 'id'
2018-07-13 14:51:31,932 /usr/local/lib/python3.6/site-packages/werkzeug/_internal.py[func:_log line:88] [INFO]  * Detected change in '/Users/Shared/dbj/api.kuaibi/micro_service/micro_services/notebook/database/notebook_manger.py', reloading
2018-07-13 14:51:31,937 /usr/local/lib/python3.6/site-packages/werkzeug/_internal.py[func:_log line:88] [INFO]  * Detected change in '/Users/Shared/dbj/api.kuaibi/micro_service/micro_services/notebook/database/notebook_manger.py', reloading
2018-07-13 14:51:54,957 /Users/Shared/dbj/api.kuaibi/micro_service/common/logger.py[func:__init__ line:23] [INFO] init log
2018-07-13 14:51:56,160 /Users/Shared/dbj/api.kuaibi/micro_service/main.py[func:<module> line:19] [ERROR] error
2018-07-13 14:51:56,160 /Users/Shared/dbj/api.kuaibi/micro_service/main.py[func:<module> line:20] [DEBUG] debug
2018-07-13 14:51:56,409 /usr/local/Cellar/python3/3.6.1/Frameworks/Python.framework/Versions/3.6/lib/python3.6/site-packages/werkzeug/_internal.py[func:_log line:88] [INFO]  * Running on http://0.0.0.0:5002/ (Press CTRL+C to quit)
2018-07-13 14:51:56,485 /usr/local/Cellar/python3/3.6.1/Frameworks/Python.framework/Versions/3.6/lib/python3.6/site-packages/werkzeug/_internal.py[func:_log line:88] [INFO]  * Restarting with fsevents reloader
2018-07-13 14:51:57,681 /Users/Shared/dbj/api.kuaibi/micro_service/common/logger.py[func:__init__ line:23] [INFO] init log
2018-07-13 14:51:58,619 /Users/Shared/dbj/api.kuaibi/micro_service/main.py[func:<module> line:19] [ERROR] error
2018-07-13 14:51:58,619 /Users/Shared/dbj/api.kuaibi/micro_service/main.py[func:<module> line:20] [DEBUG] debug
2018-07-13 14:51:58,884 /usr/local/lib/python3.6/site-packages/werkzeug/_internal.py[func:_log line:88] [WARNING]  * Debugger is active!
2018-07-13 14:51:58,924 /usr/local/lib/python3.6/site-packages/werkzeug/_internal.py[func:_log line:88] [INFO]  * Debugger PIN: 202-833-239
2018-07-13 14:52:07,955 /usr/local/Cellar/python3/3.6.1/Frameworks/Python.framework/Versions/3.6/lib/python3.6/site-packages/grpc/_server.py[func:_call_behavior line:393] [ERROR] Exception calling application: (pymysql.err.OperationalError) (2003, "Can't connect to MySQL server on 'localhost' ([Errno 61] Connection refused)") (Background on this error at: http://sqlalche.me/e/e3q8)
Traceback (most recent call last):
  File "/usr/local/Cellar/python3/3.6.1/Frameworks/Python.framework/Versions/3.6/lib/python3.6/site-packages/pymysql/connections.py", line 582, in connect
    **kwargs)
  File "/usr/local/Cellar/python3/3.6.1/Frameworks/Python.framework/Versions/3.6/lib/python3.6/socket.py", line 722, in create_connection
    raise err
  File "/usr/local/Cellar/python3/3.6.1/Frameworks/Python.framework/Versions/3.6/lib/python3.6/socket.py", line 713, in create_connection
    sock.connect(sa)
ConnectionRefusedError: [Errno 61] Connection refused

During handling of the above exception, another exception occurred:

Traceback (most recent call last):
  File "/usr/local/Cellar/python3/3.6.1/Frameworks/Python.framework/Versions/3.6/lib/python3.6/site-packages/sqlalchemy/engine/base.py", line 2158, in _wrap_pool_connect
    return fn()
  File "/usr/local/Cellar/python3/3.6.1/Frameworks/Python.framework/Versions/3.6/lib/python3.6/site-packages/sqlalchemy/pool.py", line 403, in connect
    return _ConnectionFairy._checkout(self)
  File "/usr/local/Cellar/python3/3.6.1/Frameworks/Python.framework/Versions/3.6/lib/python3.6/site-packages/sqlalchemy/pool.py", line 791, in _checkout
    fairy = _ConnectionRecord.checkout(pool)
  File "/usr/local/Cellar/python3/3.6.1/Frameworks/Python.framework/Versions/3.6/lib/python3.6/site-packages/sqlalchemy/pool.py", line 532, in checkout
    rec = pool._do_get()
  File "/usr/local/Cellar/python3/3.6.1/Frameworks/Python.framework/Versions/3.6/lib/python3.6/site-packages/sqlalchemy/pool.py", line 1196, in _do_get
    self._dec_overflow()
  File "/usr/local/Cellar/python3/3.6.1/Frameworks/Python.framework/Versions/3.6/lib/python3.6/site-packages/sqlalchemy/util/langhelpers.py", line 66, in __exit__
    compat.reraise(exc_type, exc_value, exc_tb)
  File "/usr/local/Cellar/python3/3.6.1/Frameworks/Python.framework/Versions/3.6/lib/python3.6/site-packages/sqlalchemy/util/compat.py", line 249, in reraise
    raise value
  File "/usr/local/Cellar/python3/3.6.1/Frameworks/Python.framework/Versions/3.6/lib/python3.6/site-packages/sqlalchemy/pool.py", line 1193, in _do_get
    return self._create_connection()
  File "/usr/local/Cellar/python3/3.6.1/Frameworks/Python.framework/Versions/3.6/lib/python3.6/site-packages/sqlalchemy/pool.py", line 350, in _create_connection
    return _ConnectionRecord(self)
  File "/usr/local/Cellar/python3/3.6.1/Frameworks/Python.framework/Versions/3.6/lib/python3.6/site-packages/sqlalchemy/pool.py", line 477, in __init__
    self.__connect(first_connect_check=True)
  File "/usr/local/Cellar/python3/3.6.1/Frameworks/Python.framework/Versions/3.6/lib/python3.6/site-packages/sqlalchemy/pool.py", line 674, in __connect
    connection = pool._invoke_creator(self)
  File "/usr/local/Cellar/python3/3.6.1/Frameworks/Python.framework/Versions/3.6/lib/python3.6/site-packages/sqlalchemy/engine/strategies.py", line 106, in connect
    return dialect.connect(*cargs, **cparams)
  File "/usr/local/Cellar/python3/3.6.1/Frameworks/Python.framework/Versions/3.6/lib/python3.6/site-packages/sqlalchemy/engine/default.py", line 412, in connect
    return self.dbapi.connect(*cargs, **cparams)
  File "/usr/local/Cellar/python3/3.6.1/Frameworks/Python.framework/Versions/3.6/lib/python3.6/site-packages/pymysql/__init__.py", line 94, in Connect
    return Connection(*args, **kwargs)
  File "/usr/local/Cellar/python3/3.6.1/Frameworks/Python.framework/Versions/3.6/lib/python3.6/site-packages/pymysql/connections.py", line 327, in __init__
    self.connect()
  File "/usr/local/Cellar/python3/3.6.1/Frameworks/Python.framework/Versions/3.6/lib/python3.6/site-packages/pymysql/connections.py", line 629, in connect
    raise exc
pymysql.err.OperationalError: (2003, "Can't connect to MySQL server on 'localhost' ([Errno 61] Connection refused)")

The above exception was the direct cause of the following exception:

Traceback (most recent call last):
  File "/usr/local/Cellar/python3/3.6.1/Frameworks/Python.framework/Versions/3.6/lib/python3.6/site-packages/grpc/_server.py", line 385, in _call_behavior
    return behavior(argument, context), True
  File "/Users/Shared/dbj/api.kuaibi/micro_service/micro_services/notebook/services/notebook_service.py", line 23, in GetNotebookInfo
    return get_notebook(request, context)
  File "/Users/Shared/dbj/api.kuaibi/micro_service/micro_services/notebook/handlers/get_notebook_handler.py", line 37, in get_notebook
    books = notebook_manger.notebook_from(user_id)
  File "/Users/Shared/dbj/api.kuaibi/micro_service/micro_services/notebook/database/notebook_manger.py", line 44, in notebook_from
    res = self.session.query(model).filter(model.id == _id).all()
  File "/usr/local/Cellar/python3/3.6.1/Frameworks/Python.framework/Versions/3.6/lib/python3.6/site-packages/sqlalchemy/orm/query.py", line 2836, in all
    return list(self)
  File "/usr/local/Cellar/python3/3.6.1/Frameworks/Python.framework/Versions/3.6/lib/python3.6/site-packages/sqlalchemy/orm/query.py", line 2988, in __iter__
    return self._execute_and_instances(context)
  File "/usr/local/Cellar/python3/3.6.1/Frameworks/Python.framework/Versions/3.6/lib/python3.6/site-packages/sqlalchemy/orm/query.py", line 3009, in _execute_and_instances
    close_with_result=True)
  File "/usr/local/Cellar/python3/3.6.1/Frameworks/Python.framework/Versions/3.6/lib/python3.6/site-packages/sqlalchemy/orm/query.py", line 3018, in _get_bind_args
    **kw
  File "/usr/local/Cellar/python3/3.6.1/Frameworks/Python.framework/Versions/3.6/lib/python3.6/site-packages/sqlalchemy/orm/query.py", line 3000, in _connection_from_session
    conn = self.session.connection(**kw)
  File "/usr/local/Cellar/python3/3.6.1/Frameworks/Python.framework/Versions/3.6/lib/python3.6/site-packages/sqlalchemy/orm/session.py", line 1035, in connection
    execution_options=execution_options)
  File "/usr/local/Cellar/python3/3.6.1/Frameworks/Python.framework/Versions/3.6/lib/python3.6/site-packages/sqlalchemy/orm/session.py", line 1040, in _connection_for_bind
    engine, execution_options)
  File "/usr/local/Cellar/python3/3.6.1/Frameworks/Python.framework/Versions/3.6/lib/python3.6/site-packages/sqlalchemy/orm/session.py", line 409, in _connection_for_bind
    conn = bind.contextual_connect()
  File "/usr/local/Cellar/python3/3.6.1/Frameworks/Python.framework/Versions/3.6/lib/python3.6/site-packages/sqlalchemy/engine/base.py", line 2123, in contextual_connect
    self._wrap_pool_connect(self.pool.connect, None),
  File "/usr/local/Cellar/python3/3.6.1/Frameworks/Python.framework/Versions/3.6/lib/python3.6/site-packages/sqlalchemy/engine/base.py", line 2162, in _wrap_pool_connect
    e, dialect, self)
  File "/usr/local/Cellar/python3/3.6.1/Frameworks/Python.framework/Versions/3.6/lib/python3.6/site-packages/sqlalchemy/engine/base.py", line 1476, in _handle_dbapi_exception_noconnection
    exc_info
  File "/usr/local/Cellar/python3/3.6.1/Frameworks/Python.framework/Versions/3.6/lib/python3.6/site-packages/sqlalchemy/util/compat.py", line 265, in raise_from_cause
    reraise(type(exception), exception, tb=exc_tb, cause=cause)
  File "/usr/local/Cellar/python3/3.6.1/Frameworks/Python.framework/Versions/3.6/lib/python3.6/site-packages/sqlalchemy/util/compat.py", line 248, in reraise
    raise value.with_traceback(tb)
  File "/usr/local/Cellar/python3/3.6.1/Frameworks/Python.framework/Versions/3.6/lib/python3.6/site-packages/sqlalchemy/engine/base.py", line 2158, in _wrap_pool_connect
    return fn()
  File "/usr/local/Cellar/python3/3.6.1/Frameworks/Python.framework/Versions/3.6/lib/python3.6/site-packages/sqlalchemy/pool.py", line 403, in connect
    return _ConnectionFairy._checkout(self)
  File "/usr/local/Cellar/python3/3.6.1/Frameworks/Python.framework/Versions/3.6/lib/python3.6/site-packages/sqlalchemy/pool.py", line 791, in _checkout
    fairy = _ConnectionRecord.checkout(pool)
  File "/usr/local/Cellar/python3/3.6.1/Frameworks/Python.framework/Versions/3.6/lib/python3.6/site-packages/sqlalchemy/pool.py", line 532, in checkout
    rec = pool._do_get()
  File "/usr/local/Cellar/python3/3.6.1/Frameworks/Python.framework/Versions/3.6/lib/python3.6/site-packages/sqlalchemy/pool.py", line 1196, in _do_get
    self._dec_overflow()
  File "/usr/local/Cellar/python3/3.6.1/Frameworks/Python.framework/Versions/3.6/lib/python3.6/site-packages/sqlalchemy/util/langhelpers.py", line 66, in __exit__
    compat.reraise(exc_type, exc_value, exc_tb)
  File "/usr/local/Cellar/python3/3.6.1/Frameworks/Python.framework/Versions/3.6/lib/python3.6/site-packages/sqlalchemy/util/compat.py", line 249, in reraise
    raise value
  File "/usr/local/Cellar/python3/3.6.1/Frameworks/Python.framework/Versions/3.6/lib/python3.6/site-packages/sqlalchemy/pool.py", line 1193, in _do_get
    return self._create_connection()
  File "/usr/local/Cellar/python3/3.6.1/Frameworks/Python.framework/Versions/3.6/lib/python3.6/site-packages/sqlalchemy/pool.py", line 350, in _create_connection
    return _ConnectionRecord(self)
  File "/usr/local/Cellar/python3/3.6.1/Frameworks/Python.framework/Versions/3.6/lib/python3.6/site-packages/sqlalchemy/pool.py", line 477, in __init__
    self.__connect(first_connect_check=True)
  File "/usr/local/Cellar/python3/3.6.1/Frameworks/Python.framework/Versions/3.6/lib/python3.6/site-packages/sqlalchemy/pool.py", line 674, in __connect
    connection = pool._invoke_creator(self)
  File "/usr/local/Cellar/python3/3.6.1/Frameworks/Python.framework/Versions/3.6/lib/python3.6/site-packages/sqlalchemy/engine/strategies.py", line 106, in connect
    return dialect.connect(*cargs, **cparams)
  File "/usr/local/Cellar/python3/3.6.1/Frameworks/Python.framework/Versions/3.6/lib/python3.6/site-packages/sqlalchemy/engine/default.py", line 412, in connect
    return self.dbapi.connect(*cargs, **cparams)
  File "/usr/local/Cellar/python3/3.6.1/Frameworks/Python.framework/Versions/3.6/lib/python3.6/site-packages/pymysql/__init__.py", line 94, in Connect
    return Connection(*args, **kwargs)
  File "/usr/local/Cellar/python3/3.6.1/Frameworks/Python.framework/Versions/3.6/lib/python3.6/site-packages/pymysql/connections.py", line 327, in __init__
    self.connect()
  File "/usr/local/Cellar/python3/3.6.1/Frameworks/Python.framework/Versions/3.6/lib/python3.6/site-packages/pymysql/connections.py", line 629, in connect
    raise exc
sqlalchemy.exc.OperationalError: (pymysql.err.OperationalError) (2003, "Can't connect to MySQL server on 'localhost' ([Errno 61] Connection refused)") (Background on this error at: http://sqlalche.me/e/e3q8)
2018-07-13 14:52:08,030 /usr/local/lib/python3.6/site-packages/werkzeug/_internal.py[func:_log line:88] [INFO] 127.0.0.1 - - [13/Jul/2018 14:52:08] "GET /notebook/notebook HTTP/1.1" 500 -
2018-07-13 14:52:08,081 /usr/local/lib/python3.6/site-packages/werkzeug/_internal.py[func:_log line:88] [INFO] 127.0.0.1 - - [13/Jul/2018 14:52:08] "GET /notebook/notebook?__debugger__=yes&cmd=resource&f=style.css HTTP/1.1" 200 -
2018-07-13 14:52:08,084 /usr/local/lib/python3.6/site-packages/werkzeug/_internal.py[func:_log line:88] [INFO] 127.0.0.1 - - [13/Jul/2018 14:52:08] "GET /notebook/notebook?__debugger__=yes&cmd=resource&f=debugger.js HTTP/1.1" 200 -
2018-07-13 14:52:08,087 /usr/local/lib/python3.6/site-packages/werkzeug/_internal.py[func:_log line:88] [INFO] 127.0.0.1 - - [13/Jul/2018 14:52:08] "GET /notebook/notebook?__debugger__=yes&cmd=resource&f=jquery.js HTTP/1.1" 200 -
2018-07-13 14:52:20,564 /usr/local/Cellar/python3/3.6.1/Frameworks/Python.framework/Versions/3.6/lib/python3.6/site-packages/grpc/_server.py[func:_call_behavior line:393] [ERROR] Exception calling application: (pymysql.err.OperationalError) (2003, "Can't connect to MySQL server on 'localhost' ([Errno 61] Connection refused)") (Background on this error at: http://sqlalche.me/e/e3q8)
Traceback (most recent call last):
  File "/usr/local/Cellar/python3/3.6.1/Frameworks/Python.framework/Versions/3.6/lib/python3.6/site-packages/pymysql/connections.py", line 582, in connect
    **kwargs)
  File "/usr/local/Cellar/python3/3.6.1/Frameworks/Python.framework/Versions/3.6/lib/python3.6/socket.py", line 722, in create_connection
    raise err
  File "/usr/local/Cellar/python3/3.6.1/Frameworks/Python.framework/Versions/3.6/lib/python3.6/socket.py", line 713, in create_connection
    sock.connect(sa)
ConnectionRefusedError: [Errno 61] Connection refused

During handling of the above exception, another exception occurred:

Traceback (most recent call last):
  File "/usr/local/Cellar/python3/3.6.1/Frameworks/Python.framework/Versions/3.6/lib/python3.6/site-packages/sqlalchemy/engine/base.py", line 2158, in _wrap_pool_connect
    return fn()
  File "/usr/local/Cellar/python3/3.6.1/Frameworks/Python.framework/Versions/3.6/lib/python3.6/site-packages/sqlalchemy/pool.py", line 403, in connect
    return _ConnectionFairy._checkout(self)
  File "/usr/local/Cellar/python3/3.6.1/Frameworks/Python.framework/Versions/3.6/lib/python3.6/site-packages/sqlalchemy/pool.py", line 791, in _checkout
    fairy = _ConnectionRecord.checkout(pool)
  File "/usr/local/Cellar/python3/3.6.1/Frameworks/Python.framework/Versions/3.6/lib/python3.6/site-packages/sqlalchemy/pool.py", line 532, in checkout
    rec = pool._do_get()
  File "/usr/local/Cellar/python3/3.6.1/Frameworks/Python.framework/Versions/3.6/lib/python3.6/site-packages/sqlalchemy/pool.py", line 1196, in _do_get
    self._dec_overflow()
  File "/usr/local/Cellar/python3/3.6.1/Frameworks/Python.framework/Versions/3.6/lib/python3.6/site-packages/sqlalchemy/util/langhelpers.py", line 66, in __exit__
    compat.reraise(exc_type, exc_value, exc_tb)
  File "/usr/local/Cellar/python3/3.6.1/Frameworks/Python.framework/Versions/3.6/lib/python3.6/site-packages/sqlalchemy/util/compat.py", line 249, in reraise
    raise value
  File "/usr/local/Cellar/python3/3.6.1/Frameworks/Python.framework/Versions/3.6/lib/python3.6/site-packages/sqlalchemy/pool.py", line 1193, in _do_get
    return self._create_connection()
  File "/usr/local/Cellar/python3/3.6.1/Frameworks/Python.framework/Versions/3.6/lib/python3.6/site-packages/sqlalchemy/pool.py", line 350, in _create_connection
    return _ConnectionRecord(self)
  File "/usr/local/Cellar/python3/3.6.1/Frameworks/Python.framework/Versions/3.6/lib/python3.6/site-packages/sqlalchemy/pool.py", line 477, in __init__
    self.__connect(first_connect_check=True)
  File "/usr/local/Cellar/python3/3.6.1/Frameworks/Python.framework/Versions/3.6/lib/python3.6/site-packages/sqlalchemy/pool.py", line 674, in __connect
    connection = pool._invoke_creator(self)
  File "/usr/local/Cellar/python3/3.6.1/Frameworks/Python.framework/Versions/3.6/lib/python3.6/site-packages/sqlalchemy/engine/strategies.py", line 106, in connect
    return dialect.connect(*cargs, **cparams)
  File "/usr/local/Cellar/python3/3.6.1/Frameworks/Python.framework/Versions/3.6/lib/python3.6/site-packages/sqlalchemy/engine/default.py", line 412, in connect
    return self.dbapi.connect(*cargs, **cparams)
  File "/usr/local/Cellar/python3/3.6.1/Frameworks/Python.framework/Versions/3.6/lib/python3.6/site-packages/pymysql/__init__.py", line 94, in Connect
    return Connection(*args, **kwargs)
  File "/usr/local/Cellar/python3/3.6.1/Frameworks/Python.framework/Versions/3.6/lib/python3.6/site-packages/pymysql/connections.py", line 327, in __init__
    self.connect()
  File "/usr/local/Cellar/python3/3.6.1/Frameworks/Python.framework/Versions/3.6/lib/python3.6/site-packages/pymysql/connections.py", line 629, in connect
    raise exc
pymysql.err.OperationalError: (2003, "Can't connect to MySQL server on 'localhost' ([Errno 61] Connection refused)")

The above exception was the direct cause of the following exception:

Traceback (most recent call last):
  File "/usr/local/Cellar/python3/3.6.1/Frameworks/Python.framework/Versions/3.6/lib/python3.6/site-packages/grpc/_server.py", line 385, in _call_behavior
    return behavior(argument, context), True
  File "/Users/Shared/dbj/api.kuaibi/micro_service/micro_services/notebook/services/notebook_service.py", line 23, in GetNotebookInfo
    return get_notebook(request, context)
  File "/Users/Shared/dbj/api.kuaibi/micro_service/micro_services/notebook/handlers/get_notebook_handler.py", line 37, in get_notebook
    books = notebook_manger.notebook_from(user_id)
  File "/Users/Shared/dbj/api.kuaibi/micro_service/micro_services/notebook/database/notebook_manger.py", line 44, in notebook_from
    res = self.session.query(model).filter(model.id == _id).all()
  File "/usr/local/Cellar/python3/3.6.1/Frameworks/Python.framework/Versions/3.6/lib/python3.6/site-packages/sqlalchemy/orm/query.py", line 2836, in all
    return list(self)
  File "/usr/local/Cellar/python3/3.6.1/Frameworks/Python.framework/Versions/3.6/lib/python3.6/site-packages/sqlalchemy/orm/query.py", line 2988, in __iter__
    return self._execute_and_instances(context)
  File "/usr/local/Cellar/python3/3.6.1/Frameworks/Python.framework/Versions/3.6/lib/python3.6/site-packages/sqlalchemy/orm/query.py", line 3009, in _execute_and_instances
    close_with_result=True)
  File "/usr/local/Cellar/python3/3.6.1/Frameworks/Python.framework/Versions/3.6/lib/python3.6/site-packages/sqlalchemy/orm/query.py", line 3018, in _get_bind_args
    **kw
  File "/usr/local/Cellar/python3/3.6.1/Frameworks/Python.framework/Versions/3.6/lib/python3.6/site-packages/sqlalchemy/orm/query.py", line 3000, in _connection_from_session
    conn = self.session.connection(**kw)
  File "/usr/local/Cellar/python3/3.6.1/Frameworks/Python.framework/Versions/3.6/lib/python3.6/site-packages/sqlalchemy/orm/session.py", line 1035, in connection
    execution_options=execution_options)
  File "/usr/local/Cellar/python3/3.6.1/Frameworks/Python.framework/Versions/3.6/lib/python3.6/site-packages/sqlalchemy/orm/session.py", line 1040, in _connection_for_bind
    engine, execution_options)
  File "/usr/local/Cellar/python3/3.6.1/Frameworks/Python.framework/Versions/3.6/lib/python3.6/site-packages/sqlalchemy/orm/session.py", line 409, in _connection_for_bind
    conn = bind.contextual_connect()
  File "/usr/local/Cellar/python3/3.6.1/Frameworks/Python.framework/Versions/3.6/lib/python3.6/site-packages/sqlalchemy/engine/base.py", line 2123, in contextual_connect
    self._wrap_pool_connect(self.pool.connect, None),
  File "/usr/local/Cellar/python3/3.6.1/Frameworks/Python.framework/Versions/3.6/lib/python3.6/site-packages/sqlalchemy/engine/base.py", line 2162, in _wrap_pool_connect
    e, dialect, self)
  File "/usr/local/Cellar/python3/3.6.1/Frameworks/Python.framework/Versions/3.6/lib/python3.6/site-packages/sqlalchemy/engine/base.py", line 1476, in _handle_dbapi_exception_noconnection
    exc_info
  File "/usr/local/Cellar/python3/3.6.1/Frameworks/Python.framework/Versions/3.6/lib/python3.6/site-packages/sqlalchemy/util/compat.py", line 265, in raise_from_cause
    reraise(type(exception), exception, tb=exc_tb, cause=cause)
  File "/usr/local/Cellar/python3/3.6.1/Frameworks/Python.framework/Versions/3.6/lib/python3.6/site-packages/sqlalchemy/util/compat.py", line 248, in reraise
    raise value.with_traceback(tb)
  File "/usr/local/Cellar/python3/3.6.1/Frameworks/Python.framework/Versions/3.6/lib/python3.6/site-packages/sqlalchemy/engine/base.py", line 2158, in _wrap_pool_connect
    return fn()
  File "/usr/local/Cellar/python3/3.6.1/Frameworks/Python.framework/Versions/3.6/lib/python3.6/site-packages/sqlalchemy/pool.py", line 403, in connect
    return _ConnectionFairy._checkout(self)
  File "/usr/local/Cellar/python3/3.6.1/Frameworks/Python.framework/Versions/3.6/lib/python3.6/site-packages/sqlalchemy/pool.py", line 791, in _checkout
    fairy = _ConnectionRecord.checkout(pool)
  File "/usr/local/Cellar/python3/3.6.1/Frameworks/Python.framework/Versions/3.6/lib/python3.6/site-packages/sqlalchemy/pool.py", line 532, in checkout
    rec = pool._do_get()
  File "/usr/local/Cellar/python3/3.6.1/Frameworks/Python.framework/Versions/3.6/lib/python3.6/site-packages/sqlalchemy/pool.py", line 1196, in _do_get
    self._dec_overflow()
  File "/usr/local/Cellar/python3/3.6.1/Frameworks/Python.framework/Versions/3.6/lib/python3.6/site-packages/sqlalchemy/util/langhelpers.py", line 66, in __exit__
    compat.reraise(exc_type, exc_value, exc_tb)
  File "/usr/local/Cellar/python3/3.6.1/Frameworks/Python.framework/Versions/3.6/lib/python3.6/site-packages/sqlalchemy/util/compat.py", line 249, in reraise
    raise value
  File "/usr/local/Cellar/python3/3.6.1/Frameworks/Python.framework/Versions/3.6/lib/python3.6/site-packages/sqlalchemy/pool.py", line 1193, in _do_get
    return self._create_connection()
  File "/usr/local/Cellar/python3/3.6.1/Frameworks/Python.framework/Versions/3.6/lib/python3.6/site-packages/sqlalchemy/pool.py", line 350, in _create_connection
    return _ConnectionRecord(self)
  File "/usr/local/Cellar/python3/3.6.1/Frameworks/Python.framework/Versions/3.6/lib/python3.6/site-packages/sqlalchemy/pool.py", line 477, in __init__
    self.__connect(first_connect_check=True)
  File "/usr/local/Cellar/python3/3.6.1/Frameworks/Python.framework/Versions/3.6/lib/python3.6/site-packages/sqlalchemy/pool.py", line 674, in __connect
    connection = pool._invoke_creator(self)
  File "/usr/local/Cellar/python3/3.6.1/Frameworks/Python.framework/Versions/3.6/lib/python3.6/site-packages/sqlalchemy/engine/strategies.py", line 106, in connect
    return dialect.connect(*cargs, **cparams)
  File "/usr/local/Cellar/python3/3.6.1/Frameworks/Python.framework/Versions/3.6/lib/python3.6/site-packages/sqlalchemy/engine/default.py", line 412, in connect
    return self.dbapi.connect(*cargs, **cparams)
  File "/usr/local/Cellar/python3/3.6.1/Frameworks/Python.framework/Versions/3.6/lib/python3.6/site-packages/pymysql/__init__.py", line 94, in Connect
    return Connection(*args, **kwargs)
  File "/usr/local/Cellar/python3/3.6.1/Frameworks/Python.framework/Versions/3.6/lib/python3.6/site-packages/pymysql/connections.py", line 327, in __init__
    self.connect()
  File "/usr/local/Cellar/python3/3.6.1/Frameworks/Python.framework/Versions/3.6/lib/python3.6/site-packages/pymysql/connections.py", line 629, in connect
    raise exc
sqlalchemy.exc.OperationalError: (pymysql.err.OperationalError) (2003, "Can't connect to MySQL server on 'localhost' ([Errno 61] Connection refused)") (Background on this error at: http://sqlalche.me/e/e3q8)
2018-07-13 14:52:20,709 /usr/local/lib/python3.6/site-packages/werkzeug/_internal.py[func:_log line:88] [INFO] 127.0.0.1 - - [13/Jul/2018 14:52:20] "GET /notebook/notebook HTTP/1.1" 500 -
2018-07-13 14:52:20,742 /usr/local/lib/python3.6/site-packages/werkzeug/_internal.py[func:_log line:88] [INFO] 127.0.0.1 - - [13/Jul/2018 14:52:20] "GET /notebook/notebook?__debugger__=yes&cmd=resource&f=style.css HTTP/1.1" 200 -
2018-07-13 14:52:20,755 /usr/local/lib/python3.6/site-packages/werkzeug/_internal.py[func:_log line:88] [INFO] 127.0.0.1 - - [13/Jul/2018 14:52:20] "GET /notebook/notebook?__debugger__=yes&cmd=resource&f=jquery.js HTTP/1.1" 200 -
2018-07-13 14:52:20,758 /usr/local/lib/python3.6/site-packages/werkzeug/_internal.py[func:_log line:88] [INFO] 127.0.0.1 - - [13/Jul/2018 14:52:20] "GET /notebook/notebook?__debugger__=yes&cmd=resource&f=debugger.js HTTP/1.1" 200 -
2018-07-13 14:52:20,812 /usr/local/lib/python3.6/site-packages/werkzeug/_internal.py[func:_log line:88] [INFO] 127.0.0.1 - - [13/Jul/2018 14:52:20] "GET /notebook/notebook?__debugger__=yes&cmd=resource&f=ubuntu.ttf HTTP/1.1" 200 -
2018-07-13 14:52:20,865 /usr/local/lib/python3.6/site-packages/werkzeug/_internal.py[func:_log line:88] [INFO] 127.0.0.1 - - [13/Jul/2018 14:52:20] "GET /notebook/notebook?__debugger__=yes&cmd=resource&f=console.png HTTP/1.1" 200 -
2018-07-13 14:52:34,731 /Users/Shared/dbj/api.kuaibi/micro_service/common/logger.py[func:__init__ line:23] [INFO] init log
2018-07-13 14:52:35,762 /Users/Shared/dbj/api.kuaibi/micro_service/main.py[func:<module> line:19] [ERROR] error
2018-07-13 14:52:35,762 /Users/Shared/dbj/api.kuaibi/micro_service/main.py[func:<module> line:20] [DEBUG] debug
2018-07-13 14:52:36,006 /usr/local/Cellar/python3/3.6.1/Frameworks/Python.framework/Versions/3.6/lib/python3.6/site-packages/werkzeug/_internal.py[func:_log line:88] [INFO]  * Running on http://0.0.0.0:5002/ (Press CTRL+C to quit)
2018-07-13 14:52:36,073 /usr/local/Cellar/python3/3.6.1/Frameworks/Python.framework/Versions/3.6/lib/python3.6/site-packages/werkzeug/_internal.py[func:_log line:88] [INFO]  * Restarting with fsevents reloader
2018-07-13 14:52:37,080 /Users/Shared/dbj/api.kuaibi/micro_service/common/logger.py[func:__init__ line:23] [INFO] init log
2018-07-13 14:52:37,926 /Users/Shared/dbj/api.kuaibi/micro_service/main.py[func:<module> line:19] [ERROR] error
2018-07-13 14:52:37,926 /Users/Shared/dbj/api.kuaibi/micro_service/main.py[func:<module> line:20] [DEBUG] debug
2018-07-13 14:52:38,155 /usr/local/lib/python3.6/site-packages/werkzeug/_internal.py[func:_log line:88] [WARNING]  * Debugger is active!
2018-07-13 14:52:38,190 /usr/local/lib/python3.6/site-packages/werkzeug/_internal.py[func:_log line:88] [INFO]  * Debugger PIN: 202-833-239
2018-07-13 14:52:52,911 /usr/local/Cellar/python3/3.6.1/Frameworks/Python.framework/Versions/3.6/lib/python3.6/site-packages/grpc/_server.py[func:_call_behavior line:393] [ERROR] Exception calling application: (pymysql.err.OperationalError) (2003, "Can't connect to MySQL server on 'localhost' ([Errno 61] Connection refused)") (Background on this error at: http://sqlalche.me/e/e3q8)
Traceback (most recent call last):
  File "/usr/local/Cellar/python3/3.6.1/Frameworks/Python.framework/Versions/3.6/lib/python3.6/site-packages/pymysql/connections.py", line 582, in connect
    **kwargs)
  File "/usr/local/Cellar/python3/3.6.1/Frameworks/Python.framework/Versions/3.6/lib/python3.6/socket.py", line 722, in create_connection
    raise err
  File "/usr/local/Cellar/python3/3.6.1/Frameworks/Python.framework/Versions/3.6/lib/python3.6/socket.py", line 713, in create_connection
    sock.connect(sa)
ConnectionRefusedError: [Errno 61] Connection refused

During handling of the above exception, another exception occurred:

Traceback (most recent call last):
  File "/usr/local/Cellar/python3/3.6.1/Frameworks/Python.framework/Versions/3.6/lib/python3.6/site-packages/sqlalchemy/engine/base.py", line 2158, in _wrap_pool_connect
    return fn()
  File "/usr/local/Cellar/python3/3.6.1/Frameworks/Python.framework/Versions/3.6/lib/python3.6/site-packages/sqlalchemy/pool.py", line 403, in connect
    return _ConnectionFairy._checkout(self)
  File "/usr/local/Cellar/python3/3.6.1/Frameworks/Python.framework/Versions/3.6/lib/python3.6/site-packages/sqlalchemy/pool.py", line 791, in _checkout
    fairy = _ConnectionRecord.checkout(pool)
  File "/usr/local/Cellar/python3/3.6.1/Frameworks/Python.framework/Versions/3.6/lib/python3.6/site-packages/sqlalchemy/pool.py", line 532, in checkout
    rec = pool._do_get()
  File "/usr/local/Cellar/python3/3.6.1/Frameworks/Python.framework/Versions/3.6/lib/python3.6/site-packages/sqlalchemy/pool.py", line 1196, in _do_get
    self._dec_overflow()
  File "/usr/local/Cellar/python3/3.6.1/Frameworks/Python.framework/Versions/3.6/lib/python3.6/site-packages/sqlalchemy/util/langhelpers.py", line 66, in __exit__
    compat.reraise(exc_type, exc_value, exc_tb)
  File "/usr/local/Cellar/python3/3.6.1/Frameworks/Python.framework/Versions/3.6/lib/python3.6/site-packages/sqlalchemy/util/compat.py", line 249, in reraise
    raise value
  File "/usr/local/Cellar/python3/3.6.1/Frameworks/Python.framework/Versions/3.6/lib/python3.6/site-packages/sqlalchemy/pool.py", line 1193, in _do_get
    return self._create_connection()
  File "/usr/local/Cellar/python3/3.6.1/Frameworks/Python.framework/Versions/3.6/lib/python3.6/site-packages/sqlalchemy/pool.py", line 350, in _create_connection
    return _ConnectionRecord(self)
  File "/usr/local/Cellar/python3/3.6.1/Frameworks/Python.framework/Versions/3.6/lib/python3.6/site-packages/sqlalchemy/pool.py", line 477, in __init__
    self.__connect(first_connect_check=True)
  File "/usr/local/Cellar/python3/3.6.1/Frameworks/Python.framework/Versions/3.6/lib/python3.6/site-packages/sqlalchemy/pool.py", line 674, in __connect
    connection = pool._invoke_creator(self)
  File "/usr/local/Cellar/python3/3.6.1/Frameworks/Python.framework/Versions/3.6/lib/python3.6/site-packages/sqlalchemy/engine/strategies.py", line 106, in connect
    return dialect.connect(*cargs, **cparams)
  File "/usr/local/Cellar/python3/3.6.1/Frameworks/Python.framework/Versions/3.6/lib/python3.6/site-packages/sqlalchemy/engine/default.py", line 412, in connect
    return self.dbapi.connect(*cargs, **cparams)
  File "/usr/local/Cellar/python3/3.6.1/Frameworks/Python.framework/Versions/3.6/lib/python3.6/site-packages/pymysql/__init__.py", line 94, in Connect
    return Connection(*args, **kwargs)
  File "/usr/local/Cellar/python3/3.6.1/Frameworks/Python.framework/Versions/3.6/lib/python3.6/site-packages/pymysql/connections.py", line 327, in __init__
    self.connect()
  File "/usr/local/Cellar/python3/3.6.1/Frameworks/Python.framework/Versions/3.6/lib/python3.6/site-packages/pymysql/connections.py", line 629, in connect
    raise exc
pymysql.err.OperationalError: (2003, "Can't connect to MySQL server on 'localhost' ([Errno 61] Connection refused)")

The above exception was the direct cause of the following exception:

Traceback (most recent call last):
  File "/usr/local/Cellar/python3/3.6.1/Frameworks/Python.framework/Versions/3.6/lib/python3.6/site-packages/grpc/_server.py", line 385, in _call_behavior
    return behavior(argument, context), True
  File "/Users/Shared/dbj/api.kuaibi/micro_service/micro_services/notebook/services/notebook_service.py", line 23, in GetNotebookInfo
    return get_notebook(request, context)
  File "/Users/Shared/dbj/api.kuaibi/micro_service/micro_services/notebook/handlers/get_notebook_handler.py", line 37, in get_notebook
    books = notebook_manger.notebook_from(user_id)
  File "/Users/Shared/dbj/api.kuaibi/micro_service/micro_services/notebook/database/notebook_manger.py", line 44, in notebook_from
    res = self.session.query(model).filter(model.id == _id).all()
  File "/usr/local/Cellar/python3/3.6.1/Frameworks/Python.framework/Versions/3.6/lib/python3.6/site-packages/sqlalchemy/orm/query.py", line 2836, in all
    return list(self)
  File "/usr/local/Cellar/python3/3.6.1/Frameworks/Python.framework/Versions/3.6/lib/python3.6/site-packages/sqlalchemy/orm/query.py", line 2988, in __iter__
    return self._execute_and_instances(context)
  File "/usr/local/Cellar/python3/3.6.1/Frameworks/Python.framework/Versions/3.6/lib/python3.6/site-packages/sqlalchemy/orm/query.py", line 3009, in _execute_and_instances
    close_with_result=True)
  File "/usr/local/Cellar/python3/3.6.1/Frameworks/Python.framework/Versions/3.6/lib/python3.6/site-packages/sqlalchemy/orm/query.py", line 3018, in _get_bind_args
    **kw
  File "/usr/local/Cellar/python3/3.6.1/Frameworks/Python.framework/Versions/3.6/lib/python3.6/site-packages/sqlalchemy/orm/query.py", line 3000, in _connection_from_session
    conn = self.session.connection(**kw)
  File "/usr/local/Cellar/python3/3.6.1/Frameworks/Python.framework/Versions/3.6/lib/python3.6/site-packages/sqlalchemy/orm/session.py", line 1035, in connection
    execution_options=execution_options)
  File "/usr/local/Cellar/python3/3.6.1/Frameworks/Python.framework/Versions/3.6/lib/python3.6/site-packages/sqlalchemy/orm/session.py", line 1040, in _connection_for_bind
    engine, execution_options)
  File "/usr/local/Cellar/python3/3.6.1/Frameworks/Python.framework/Versions/3.6/lib/python3.6/site-packages/sqlalchemy/orm/session.py", line 409, in _connection_for_bind
    conn = bind.contextual_connect()
  File "/usr/local/Cellar/python3/3.6.1/Frameworks/Python.framework/Versions/3.6/lib/python3.6/site-packages/sqlalchemy/engine/base.py", line 2123, in contextual_connect
    self._wrap_pool_connect(self.pool.connect, None),
  File "/usr/local/Cellar/python3/3.6.1/Frameworks/Python.framework/Versions/3.6/lib/python3.6/site-packages/sqlalchemy/engine/base.py", line 2162, in _wrap_pool_connect
    e, dialect, self)
  File "/usr/local/Cellar/python3/3.6.1/Frameworks/Python.framework/Versions/3.6/lib/python3.6/site-packages/sqlalchemy/engine/base.py", line 1476, in _handle_dbapi_exception_noconnection
    exc_info
  File "/usr/local/Cellar/python3/3.6.1/Frameworks/Python.framework/Versions/3.6/lib/python3.6/site-packages/sqlalchemy/util/compat.py", line 265, in raise_from_cause
    reraise(type(exception), exception, tb=exc_tb, cause=cause)
  File "/usr/local/Cellar/python3/3.6.1/Frameworks/Python.framework/Versions/3.6/lib/python3.6/site-packages/sqlalchemy/util/compat.py", line 248, in reraise
    raise value.with_traceback(tb)
  File "/usr/local/Cellar/python3/3.6.1/Frameworks/Python.framework/Versions/3.6/lib/python3.6/site-packages/sqlalchemy/engine/base.py", line 2158, in _wrap_pool_connect
    return fn()
  File "/usr/local/Cellar/python3/3.6.1/Frameworks/Python.framework/Versions/3.6/lib/python3.6/site-packages/sqlalchemy/pool.py", line 403, in connect
    return _ConnectionFairy._checkout(self)
  File "/usr/local/Cellar/python3/3.6.1/Frameworks/Python.framework/Versions/3.6/lib/python3.6/site-packages/sqlalchemy/pool.py", line 791, in _checkout
    fairy = _ConnectionRecord.checkout(pool)
  File "/usr/local/Cellar/python3/3.6.1/Frameworks/Python.framework/Versions/3.6/lib/python3.6/site-packages/sqlalchemy/pool.py", line 532, in checkout
    rec = pool._do_get()
  File "/usr/local/Cellar/python3/3.6.1/Frameworks/Python.framework/Versions/3.6/lib/python3.6/site-packages/sqlalchemy/pool.py", line 1196, in _do_get
    self._dec_overflow()
  File "/usr/local/Cellar/python3/3.6.1/Frameworks/Python.framework/Versions/3.6/lib/python3.6/site-packages/sqlalchemy/util/langhelpers.py", line 66, in __exit__
    compat.reraise(exc_type, exc_value, exc_tb)
  File "/usr/local/Cellar/python3/3.6.1/Frameworks/Python.framework/Versions/3.6/lib/python3.6/site-packages/sqlalchemy/util/compat.py", line 249, in reraise
    raise value
  File "/usr/local/Cellar/python3/3.6.1/Frameworks/Python.framework/Versions/3.6/lib/python3.6/site-packages/sqlalchemy/pool.py", line 1193, in _do_get
    return self._create_connection()
  File "/usr/local/Cellar/python3/3.6.1/Frameworks/Python.framework/Versions/3.6/lib/python3.6/site-packages/sqlalchemy/pool.py", line 350, in _create_connection
    return _ConnectionRecord(self)
  File "/usr/local/Cellar/python3/3.6.1/Frameworks/Python.framework/Versions/3.6/lib/python3.6/site-packages/sqlalchemy/pool.py", line 477, in __init__
    self.__connect(first_connect_check=True)
  File "/usr/local/Cellar/python3/3.6.1/Frameworks/Python.framework/Versions/3.6/lib/python3.6/site-packages/sqlalchemy/pool.py", line 674, in __connect
    connection = pool._invoke_creator(self)
  File "/usr/local/Cellar/python3/3.6.1/Frameworks/Python.framework/Versions/3.6/lib/python3.6/site-packages/sqlalchemy/engine/strategies.py", line 106, in connect
    return dialect.connect(*cargs, **cparams)
  File "/usr/local/Cellar/python3/3.6.1/Frameworks/Python.framework/Versions/3.6/lib/python3.6/site-packages/sqlalchemy/engine/default.py", line 412, in connect
    return self.dbapi.connect(*cargs, **cparams)
  File "/usr/local/Cellar/python3/3.6.1/Frameworks/Python.framework/Versions/3.6/lib/python3.6/site-packages/pymysql/__init__.py", line 94, in Connect
    return Connection(*args, **kwargs)
  File "/usr/local/Cellar/python3/3.6.1/Frameworks/Python.framework/Versions/3.6/lib/python3.6/site-packages/pymysql/connections.py", line 327, in __init__
    self.connect()
  File "/usr/local/Cellar/python3/3.6.1/Frameworks/Python.framework/Versions/3.6/lib/python3.6/site-packages/pymysql/connections.py", line 629, in connect
    raise exc
sqlalchemy.exc.OperationalError: (pymysql.err.OperationalError) (2003, "Can't connect to MySQL server on 'localhost' ([Errno 61] Connection refused)") (Background on this error at: http://sqlalche.me/e/e3q8)
2018-07-13 14:52:52,995 /usr/local/lib/python3.6/site-packages/werkzeug/_internal.py[func:_log line:88] [INFO] 127.0.0.1 - - [13/Jul/2018 14:52:52] "GET /notebook/notebook HTTP/1.1" 500 -
2018-07-13 14:52:53,060 /usr/local/lib/python3.6/site-packages/werkzeug/_internal.py[func:_log line:88] [INFO] 127.0.0.1 - - [13/Jul/2018 14:52:53] "GET /notebook/notebook?__debugger__=yes&cmd=resource&f=style.css HTTP/1.1" 200 -
2018-07-13 14:52:53,063 /usr/local/lib/python3.6/site-packages/werkzeug/_internal.py[func:_log line:88] [INFO] 127.0.0.1 - - [13/Jul/2018 14:52:53] "GET /notebook/notebook?__debugger__=yes&cmd=resource&f=debugger.js HTTP/1.1" 200 -
2018-07-13 14:52:53,066 /usr/local/lib/python3.6/site-packages/werkzeug/_internal.py[func:_log line:88] [INFO] 127.0.0.1 - - [13/Jul/2018 14:52:53] "GET /notebook/notebook?__debugger__=yes&cmd=resource&f=jquery.js HTTP/1.1" 200 -
2018-07-13 14:52:53,107 /usr/local/lib/python3.6/site-packages/werkzeug/_internal.py[func:_log line:88] [INFO] 127.0.0.1 - - [13/Jul/2018 14:52:53] "GET /notebook/notebook?__debugger__=yes&cmd=resource&f=ubuntu.ttf HTTP/1.1" 200 -
2018-07-13 14:52:53,163 /usr/local/lib/python3.6/site-packages/werkzeug/_internal.py[func:_log line:88] [INFO] 127.0.0.1 - - [13/Jul/2018 14:52:53] "GET /notebook/notebook?__debugger__=yes&cmd=resource&f=console.png HTTP/1.1" 200 -
2018-07-13 14:53:04,905 /usr/local/Cellar/python3/3.6.1/Frameworks/Python.framework/Versions/3.6/lib/python3.6/site-packages/grpc/_server.py[func:_call_behavior line:393] [ERROR] Exception calling application: (pymysql.err.OperationalError) (2003, "Can't connect to MySQL server on 'localhost' ([Errno 61] Connection refused)") (Background on this error at: http://sqlalche.me/e/e3q8)
Traceback (most recent call last):
  File "/usr/local/Cellar/python3/3.6.1/Frameworks/Python.framework/Versions/3.6/lib/python3.6/site-packages/pymysql/connections.py", line 582, in connect
    **kwargs)
  File "/usr/local/Cellar/python3/3.6.1/Frameworks/Python.framework/Versions/3.6/lib/python3.6/socket.py", line 722, in create_connection
    raise err
  File "/usr/local/Cellar/python3/3.6.1/Frameworks/Python.framework/Versions/3.6/lib/python3.6/socket.py", line 713, in create_connection
    sock.connect(sa)
ConnectionRefusedError: [Errno 61] Connection refused

During handling of the above exception, another exception occurred:

Traceback (most recent call last):
  File "/usr/local/Cellar/python3/3.6.1/Frameworks/Python.framework/Versions/3.6/lib/python3.6/site-packages/sqlalchemy/engine/base.py", line 2158, in _wrap_pool_connect
    return fn()
  File "/usr/local/Cellar/python3/3.6.1/Frameworks/Python.framework/Versions/3.6/lib/python3.6/site-packages/sqlalchemy/pool.py", line 403, in connect
    return _ConnectionFairy._checkout(self)
  File "/usr/local/Cellar/python3/3.6.1/Frameworks/Python.framework/Versions/3.6/lib/python3.6/site-packages/sqlalchemy/pool.py", line 791, in _checkout
    fairy = _ConnectionRecord.checkout(pool)
  File "/usr/local/Cellar/python3/3.6.1/Frameworks/Python.framework/Versions/3.6/lib/python3.6/site-packages/sqlalchemy/pool.py", line 532, in checkout
    rec = pool._do_get()
  File "/usr/local/Cellar/python3/3.6.1/Frameworks/Python.framework/Versions/3.6/lib/python3.6/site-packages/sqlalchemy/pool.py", line 1196, in _do_get
    self._dec_overflow()
  File "/usr/local/Cellar/python3/3.6.1/Frameworks/Python.framework/Versions/3.6/lib/python3.6/site-packages/sqlalchemy/util/langhelpers.py", line 66, in __exit__
    compat.reraise(exc_type, exc_value, exc_tb)
  File "/usr/local/Cellar/python3/3.6.1/Frameworks/Python.framework/Versions/3.6/lib/python3.6/site-packages/sqlalchemy/util/compat.py", line 249, in reraise
    raise value
  File "/usr/local/Cellar/python3/3.6.1/Frameworks/Python.framework/Versions/3.6/lib/python3.6/site-packages/sqlalchemy/pool.py", line 1193, in _do_get
    return self._create_connection()
  File "/usr/local/Cellar/python3/3.6.1/Frameworks/Python.framework/Versions/3.6/lib/python3.6/site-packages/sqlalchemy/pool.py", line 350, in _create_connection
    return _ConnectionRecord(self)
  File "/usr/local/Cellar/python3/3.6.1/Frameworks/Python.framework/Versions/3.6/lib/python3.6/site-packages/sqlalchemy/pool.py", line 477, in __init__
    self.__connect(first_connect_check=True)
  File "/usr/local/Cellar/python3/3.6.1/Frameworks/Python.framework/Versions/3.6/lib/python3.6/site-packages/sqlalchemy/pool.py", line 674, in __connect
    connection = pool._invoke_creator(self)
  File "/usr/local/Cellar/python3/3.6.1/Frameworks/Python.framework/Versions/3.6/lib/python3.6/site-packages/sqlalchemy/engine/strategies.py", line 106, in connect
    return dialect.connect(*cargs, **cparams)
  File "/usr/local/Cellar/python3/3.6.1/Frameworks/Python.framework/Versions/3.6/lib/python3.6/site-packages/sqlalchemy/engine/default.py", line 412, in connect
    return self.dbapi.connect(*cargs, **cparams)
  File "/usr/local/Cellar/python3/3.6.1/Frameworks/Python.framework/Versions/3.6/lib/python3.6/site-packages/pymysql/__init__.py", line 94, in Connect
    return Connection(*args, **kwargs)
  File "/usr/local/Cellar/python3/3.6.1/Frameworks/Python.framework/Versions/3.6/lib/python3.6/site-packages/pymysql/connections.py", line 327, in __init__
    self.connect()
  File "/usr/local/Cellar/python3/3.6.1/Frameworks/Python.framework/Versions/3.6/lib/python3.6/site-packages/pymysql/connections.py", line 629, in connect
    raise exc
pymysql.err.OperationalError: (2003, "Can't connect to MySQL server on 'localhost' ([Errno 61] Connection refused)")

The above exception was the direct cause of the following exception:

Traceback (most recent call last):
  File "/usr/local/Cellar/python3/3.6.1/Frameworks/Python.framework/Versions/3.6/lib/python3.6/site-packages/grpc/_server.py", line 385, in _call_behavior
    return behavior(argument, context), True
  File "/Users/Shared/dbj/api.kuaibi/micro_service/micro_services/notebook/services/notebook_service.py", line 23, in GetNotebookInfo
    return get_notebook(request, context)
  File "/Users/Shared/dbj/api.kuaibi/micro_service/micro_services/notebook/handlers/get_notebook_handler.py", line 37, in get_notebook
    books = notebook_manger.notebook_from(user_id)
  File "/Users/Shared/dbj/api.kuaibi/micro_service/micro_services/notebook/database/notebook_manger.py", line 44, in notebook_from
    res = self.session.query(model).filter(model.id == _id).all()
  File "/usr/local/Cellar/python3/3.6.1/Frameworks/Python.framework/Versions/3.6/lib/python3.6/site-packages/sqlalchemy/orm/query.py", line 2836, in all
    return list(self)
  File "/usr/local/Cellar/python3/3.6.1/Frameworks/Python.framework/Versions/3.6/lib/python3.6/site-packages/sqlalchemy/orm/query.py", line 2988, in __iter__
    return self._execute_and_instances(context)
  File "/usr/local/Cellar/python3/3.6.1/Frameworks/Python.framework/Versions/3.6/lib/python3.6/site-packages/sqlalchemy/orm/query.py", line 3009, in _execute_and_instances
    close_with_result=True)
  File "/usr/local/Cellar/python3/3.6.1/Frameworks/Python.framework/Versions/3.6/lib/python3.6/site-packages/sqlalchemy/orm/query.py", line 3018, in _get_bind_args
    **kw
  File "/usr/local/Cellar/python3/3.6.1/Frameworks/Python.framework/Versions/3.6/lib/python3.6/site-packages/sqlalchemy/orm/query.py", line 3000, in _connection_from_session
    conn = self.session.connection(**kw)
  File "/usr/local/Cellar/python3/3.6.1/Frameworks/Python.framework/Versions/3.6/lib/python3.6/site-packages/sqlalchemy/orm/session.py", line 1035, in connection
    execution_options=execution_options)
  File "/usr/local/Cellar/python3/3.6.1/Frameworks/Python.framework/Versions/3.6/lib/python3.6/site-packages/sqlalchemy/orm/session.py", line 1040, in _connection_for_bind
    engine, execution_options)
  File "/usr/local/Cellar/python3/3.6.1/Frameworks/Python.framework/Versions/3.6/lib/python3.6/site-packages/sqlalchemy/orm/session.py", line 409, in _connection_for_bind
    conn = bind.contextual_connect()
  File "/usr/local/Cellar/python3/3.6.1/Frameworks/Python.framework/Versions/3.6/lib/python3.6/site-packages/sqlalchemy/engine/base.py", line 2123, in contextual_connect
    self._wrap_pool_connect(self.pool.connect, None),
  File "/usr/local/Cellar/python3/3.6.1/Frameworks/Python.framework/Versions/3.6/lib/python3.6/site-packages/sqlalchemy/engine/base.py", line 2162, in _wrap_pool_connect
    e, dialect, self)
  File "/usr/local/Cellar/python3/3.6.1/Frameworks/Python.framework/Versions/3.6/lib/python3.6/site-packages/sqlalchemy/engine/base.py", line 1476, in _handle_dbapi_exception_noconnection
    exc_info
  File "/usr/local/Cellar/python3/3.6.1/Frameworks/Python.framework/Versions/3.6/lib/python3.6/site-packages/sqlalchemy/util/compat.py", line 265, in raise_from_cause
    reraise(type(exception), exception, tb=exc_tb, cause=cause)
  File "/usr/local/Cellar/python3/3.6.1/Frameworks/Python.framework/Versions/3.6/lib/python3.6/site-packages/sqlalchemy/util/compat.py", line 248, in reraise
    raise value.with_traceback(tb)
  File "/usr/local/Cellar/python3/3.6.1/Frameworks/Python.framework/Versions/3.6/lib/python3.6/site-packages/sqlalchemy/engine/base.py", line 2158, in _wrap_pool_connect
    return fn()
  File "/usr/local/Cellar/python3/3.6.1/Frameworks/Python.framework/Versions/3.6/lib/python3.6/site-packages/sqlalchemy/pool.py", line 403, in connect
    return _ConnectionFairy._checkout(self)
  File "/usr/local/Cellar/python3/3.6.1/Frameworks/Python.framework/Versions/3.6/lib/python3.6/site-packages/sqlalchemy/pool.py", line 791, in _checkout
    fairy = _ConnectionRecord.checkout(pool)
  File "/usr/local/Cellar/python3/3.6.1/Frameworks/Python.framework/Versions/3.6/lib/python3.6/site-packages/sqlalchemy/pool.py", line 532, in checkout
    rec = pool._do_get()
  File "/usr/local/Cellar/python3/3.6.1/Frameworks/Python.framework/Versions/3.6/lib/python3.6/site-packages/sqlalchemy/pool.py", line 1196, in _do_get
    self._dec_overflow()
  File "/usr/local/Cellar/python3/3.6.1/Frameworks/Python.framework/Versions/3.6/lib/python3.6/site-packages/sqlalchemy/util/langhelpers.py", line 66, in __exit__
    compat.reraise(exc_type, exc_value, exc_tb)
  File "/usr/local/Cellar/python3/3.6.1/Frameworks/Python.framework/Versions/3.6/lib/python3.6/site-packages/sqlalchemy/util/compat.py", line 249, in reraise
    raise value
  File "/usr/local/Cellar/python3/3.6.1/Frameworks/Python.framework/Versions/3.6/lib/python3.6/site-packages/sqlalchemy/pool.py", line 1193, in _do_get
    return self._create_connection()
  File "/usr/local/Cellar/python3/3.6.1/Frameworks/Python.framework/Versions/3.6/lib/python3.6/site-packages/sqlalchemy/pool.py", line 350, in _create_connection
    return _ConnectionRecord(self)
  File "/usr/local/Cellar/python3/3.6.1/Frameworks/Python.framework/Versions/3.6/lib/python3.6/site-packages/sqlalchemy/pool.py", line 477, in __init__
    self.__connect(first_connect_check=True)
  File "/usr/local/Cellar/python3/3.6.1/Frameworks/Python.framework/Versions/3.6/lib/python3.6/site-packages/sqlalchemy/pool.py", line 674, in __connect
    connection = pool._invoke_creator(self)
  File "/usr/local/Cellar/python3/3.6.1/Frameworks/Python.framework/Versions/3.6/lib/python3.6/site-packages/sqlalchemy/engine/strategies.py", line 106, in connect
    return dialect.connect(*cargs, **cparams)
  File "/usr/local/Cellar/python3/3.6.1/Frameworks/Python.framework/Versions/3.6/lib/python3.6/site-packages/sqlalchemy/engine/default.py", line 412, in connect
    return self.dbapi.connect(*cargs, **cparams)
  File "/usr/local/Cellar/python3/3.6.1/Frameworks/Python.framework/Versions/3.6/lib/python3.6/site-packages/pymysql/__init__.py", line 94, in Connect
    return Connection(*args, **kwargs)
  File "/usr/local/Cellar/python3/3.6.1/Frameworks/Python.framework/Versions/3.6/lib/python3.6/site-packages/pymysql/connections.py", line 327, in __init__
    self.connect()
  File "/usr/local/Cellar/python3/3.6.1/Frameworks/Python.framework/Versions/3.6/lib/python3.6/site-packages/pymysql/connections.py", line 629, in connect
    raise exc
sqlalchemy.exc.OperationalError: (pymysql.err.OperationalError) (2003, "Can't connect to MySQL server on 'localhost' ([Errno 61] Connection refused)") (Background on this error at: http://sqlalche.me/e/e3q8)
2018-07-13 14:53:05,019 /usr/local/lib/python3.6/site-packages/werkzeug/_internal.py[func:_log line:88] [INFO] 127.0.0.1 - - [13/Jul/2018 14:53:05] "GET /notebook/notebook HTTP/1.1" 500 -
2018-07-13 14:53:05,049 /usr/local/lib/python3.6/site-packages/werkzeug/_internal.py[func:_log line:88] [INFO] 127.0.0.1 - - [13/Jul/2018 14:53:05] "GET /notebook/notebook?__debugger__=yes&cmd=resource&f=style.css HTTP/1.1" 200 -
2018-07-13 14:53:05,070 /usr/local/lib/python3.6/site-packages/werkzeug/_internal.py[func:_log line:88] [INFO] 127.0.0.1 - - [13/Jul/2018 14:53:05] "GET /notebook/notebook?__debugger__=yes&cmd=resource&f=debugger.js HTTP/1.1" 200 -
2018-07-13 14:53:05,073 /usr/local/lib/python3.6/site-packages/werkzeug/_internal.py[func:_log line:88] [INFO] 127.0.0.1 - - [13/Jul/2018 14:53:05] "GET /notebook/notebook?__debugger__=yes&cmd=resource&f=jquery.js HTTP/1.1" 200 -
2018-07-13 14:53:05,133 /usr/local/lib/python3.6/site-packages/werkzeug/_internal.py[func:_log line:88] [INFO] 127.0.0.1 - - [13/Jul/2018 14:53:05] "GET /notebook/notebook?__debugger__=yes&cmd=resource&f=ubuntu.ttf HTTP/1.1" 200 -
2018-07-13 14:53:05,187 /usr/local/lib/python3.6/site-packages/werkzeug/_internal.py[func:_log line:88] [INFO] 127.0.0.1 - - [13/Jul/2018 14:53:05] "GET /notebook/notebook?__debugger__=yes&cmd=resource&f=console.png HTTP/1.1" 200 -
2018-07-13 14:53:10,686 /usr/local/Cellar/python3/3.6.1/Frameworks/Python.framework/Versions/3.6/lib/python3.6/site-packages/grpc/_server.py[func:_call_behavior line:393] [ERROR] Exception calling application: (pymysql.err.OperationalError) (2003, "Can't connect to MySQL server on 'localhost' ([Errno 61] Connection refused)") (Background on this error at: http://sqlalche.me/e/e3q8)
Traceback (most recent call last):
  File "/usr/local/Cellar/python3/3.6.1/Frameworks/Python.framework/Versions/3.6/lib/python3.6/site-packages/pymysql/connections.py", line 582, in connect
    **kwargs)
  File "/usr/local/Cellar/python3/3.6.1/Frameworks/Python.framework/Versions/3.6/lib/python3.6/socket.py", line 722, in create_connection
    raise err
  File "/usr/local/Cellar/python3/3.6.1/Frameworks/Python.framework/Versions/3.6/lib/python3.6/socket.py", line 713, in create_connection
    sock.connect(sa)
ConnectionRefusedError: [Errno 61] Connection refused

During handling of the above exception, another exception occurred:

Traceback (most recent call last):
  File "/usr/local/Cellar/python3/3.6.1/Frameworks/Python.framework/Versions/3.6/lib/python3.6/site-packages/sqlalchemy/engine/base.py", line 2158, in _wrap_pool_connect
    return fn()
  File "/usr/local/Cellar/python3/3.6.1/Frameworks/Python.framework/Versions/3.6/lib/python3.6/site-packages/sqlalchemy/pool.py", line 403, in connect
    return _ConnectionFairy._checkout(self)
  File "/usr/local/Cellar/python3/3.6.1/Frameworks/Python.framework/Versions/3.6/lib/python3.6/site-packages/sqlalchemy/pool.py", line 791, in _checkout
    fairy = _ConnectionRecord.checkout(pool)
  File "/usr/local/Cellar/python3/3.6.1/Frameworks/Python.framework/Versions/3.6/lib/python3.6/site-packages/sqlalchemy/pool.py", line 532, in checkout
    rec = pool._do_get()
  File "/usr/local/Cellar/python3/3.6.1/Frameworks/Python.framework/Versions/3.6/lib/python3.6/site-packages/sqlalchemy/pool.py", line 1196, in _do_get
    self._dec_overflow()
  File "/usr/local/Cellar/python3/3.6.1/Frameworks/Python.framework/Versions/3.6/lib/python3.6/site-packages/sqlalchemy/util/langhelpers.py", line 66, in __exit__
    compat.reraise(exc_type, exc_value, exc_tb)
  File "/usr/local/Cellar/python3/3.6.1/Frameworks/Python.framework/Versions/3.6/lib/python3.6/site-packages/sqlalchemy/util/compat.py", line 249, in reraise
    raise value
  File "/usr/local/Cellar/python3/3.6.1/Frameworks/Python.framework/Versions/3.6/lib/python3.6/site-packages/sqlalchemy/pool.py", line 1193, in _do_get
    return self._create_connection()
  File "/usr/local/Cellar/python3/3.6.1/Frameworks/Python.framework/Versions/3.6/lib/python3.6/site-packages/sqlalchemy/pool.py", line 350, in _create_connection
    return _ConnectionRecord(self)
  File "/usr/local/Cellar/python3/3.6.1/Frameworks/Python.framework/Versions/3.6/lib/python3.6/site-packages/sqlalchemy/pool.py", line 477, in __init__
    self.__connect(first_connect_check=True)
  File "/usr/local/Cellar/python3/3.6.1/Frameworks/Python.framework/Versions/3.6/lib/python3.6/site-packages/sqlalchemy/pool.py", line 674, in __connect
    connection = pool._invoke_creator(self)
  File "/usr/local/Cellar/python3/3.6.1/Frameworks/Python.framework/Versions/3.6/lib/python3.6/site-packages/sqlalchemy/engine/strategies.py", line 106, in connect
    return dialect.connect(*cargs, **cparams)
  File "/usr/local/Cellar/python3/3.6.1/Frameworks/Python.framework/Versions/3.6/lib/python3.6/site-packages/sqlalchemy/engine/default.py", line 412, in connect
    return self.dbapi.connect(*cargs, **cparams)
  File "/usr/local/Cellar/python3/3.6.1/Frameworks/Python.framework/Versions/3.6/lib/python3.6/site-packages/pymysql/__init__.py", line 94, in Connect
    return Connection(*args, **kwargs)
  File "/usr/local/Cellar/python3/3.6.1/Frameworks/Python.framework/Versions/3.6/lib/python3.6/site-packages/pymysql/connections.py", line 327, in __init__
    self.connect()
  File "/usr/local/Cellar/python3/3.6.1/Frameworks/Python.framework/Versions/3.6/lib/python3.6/site-packages/pymysql/connections.py", line 629, in connect
    raise exc
pymysql.err.OperationalError: (2003, "Can't connect to MySQL server on 'localhost' ([Errno 61] Connection refused)")

The above exception was the direct cause of the following exception:

Traceback (most recent call last):
  File "/usr/local/Cellar/python3/3.6.1/Frameworks/Python.framework/Versions/3.6/lib/python3.6/site-packages/grpc/_server.py", line 385, in _call_behavior
    return behavior(argument, context), True
  File "/Users/Shared/dbj/api.kuaibi/micro_service/micro_services/notebook/services/notebook_service.py", line 23, in GetNotebookInfo
    return get_notebook(request, context)
  File "/Users/Shared/dbj/api.kuaibi/micro_service/micro_services/notebook/handlers/get_notebook_handler.py", line 37, in get_notebook
    books = notebook_manger.notebook_from(user_id)
  File "/Users/Shared/dbj/api.kuaibi/micro_service/micro_services/notebook/database/notebook_manger.py", line 44, in notebook_from
    res = self.session.query(model).filter(model.id == _id).all()
  File "/usr/local/Cellar/python3/3.6.1/Frameworks/Python.framework/Versions/3.6/lib/python3.6/site-packages/sqlalchemy/orm/query.py", line 2836, in all
    return list(self)
  File "/usr/local/Cellar/python3/3.6.1/Frameworks/Python.framework/Versions/3.6/lib/python3.6/site-packages/sqlalchemy/orm/query.py", line 2988, in __iter__
    return self._execute_and_instances(context)
  File "/usr/local/Cellar/python3/3.6.1/Frameworks/Python.framework/Versions/3.6/lib/python3.6/site-packages/sqlalchemy/orm/query.py", line 3009, in _execute_and_instances
    close_with_result=True)
  File "/usr/local/Cellar/python3/3.6.1/Frameworks/Python.framework/Versions/3.6/lib/python3.6/site-packages/sqlalchemy/orm/query.py", line 3018, in _get_bind_args
    **kw
  File "/usr/local/Cellar/python3/3.6.1/Frameworks/Python.framework/Versions/3.6/lib/python3.6/site-packages/sqlalchemy/orm/query.py", line 3000, in _connection_from_session
    conn = self.session.connection(**kw)
  File "/usr/local/Cellar/python3/3.6.1/Frameworks/Python.framework/Versions/3.6/lib/python3.6/site-packages/sqlalchemy/orm/session.py", line 1035, in connection
    execution_options=execution_options)
  File "/usr/local/Cellar/python3/3.6.1/Frameworks/Python.framework/Versions/3.6/lib/python3.6/site-packages/sqlalchemy/orm/session.py", line 1040, in _connection_for_bind
    engine, execution_options)
  File "/usr/local/Cellar/python3/3.6.1/Frameworks/Python.framework/Versions/3.6/lib/python3.6/site-packages/sqlalchemy/orm/session.py", line 409, in _connection_for_bind
    conn = bind.contextual_connect()
  File "/usr/local/Cellar/python3/3.6.1/Frameworks/Python.framework/Versions/3.6/lib/python3.6/site-packages/sqlalchemy/engine/base.py", line 2123, in contextual_connect
    self._wrap_pool_connect(self.pool.connect, None),
  File "/usr/local/Cellar/python3/3.6.1/Frameworks/Python.framework/Versions/3.6/lib/python3.6/site-packages/sqlalchemy/engine/base.py", line 2162, in _wrap_pool_connect
    e, dialect, self)
  File "/usr/local/Cellar/python3/3.6.1/Frameworks/Python.framework/Versions/3.6/lib/python3.6/site-packages/sqlalchemy/engine/base.py", line 1476, in _handle_dbapi_exception_noconnection
    exc_info
  File "/usr/local/Cellar/python3/3.6.1/Frameworks/Python.framework/Versions/3.6/lib/python3.6/site-packages/sqlalchemy/util/compat.py", line 265, in raise_from_cause
    reraise(type(exception), exception, tb=exc_tb, cause=cause)
  File "/usr/local/Cellar/python3/3.6.1/Frameworks/Python.framework/Versions/3.6/lib/python3.6/site-packages/sqlalchemy/util/compat.py", line 248, in reraise
    raise value.with_traceback(tb)
  File "/usr/local/Cellar/python3/3.6.1/Frameworks/Python.framework/Versions/3.6/lib/python3.6/site-packages/sqlalchemy/engine/base.py", line 2158, in _wrap_pool_connect
    return fn()
  File "/usr/local/Cellar/python3/3.6.1/Frameworks/Python.framework/Versions/3.6/lib/python3.6/site-packages/sqlalchemy/pool.py", line 403, in connect
    return _ConnectionFairy._checkout(self)
  File "/usr/local/Cellar/python3/3.6.1/Frameworks/Python.framework/Versions/3.6/lib/python3.6/site-packages/sqlalchemy/pool.py", line 791, in _checkout
    fairy = _ConnectionRecord.checkout(pool)
  File "/usr/local/Cellar/python3/3.6.1/Frameworks/Python.framework/Versions/3.6/lib/python3.6/site-packages/sqlalchemy/pool.py", line 532, in checkout
    rec = pool._do_get()
  File "/usr/local/Cellar/python3/3.6.1/Frameworks/Python.framework/Versions/3.6/lib/python3.6/site-packages/sqlalchemy/pool.py", line 1196, in _do_get
    self._dec_overflow()
  File "/usr/local/Cellar/python3/3.6.1/Frameworks/Python.framework/Versions/3.6/lib/python3.6/site-packages/sqlalchemy/util/langhelpers.py", line 66, in __exit__
    compat.reraise(exc_type, exc_value, exc_tb)
  File "/usr/local/Cellar/python3/3.6.1/Frameworks/Python.framework/Versions/3.6/lib/python3.6/site-packages/sqlalchemy/util/compat.py", line 249, in reraise
    raise value
  File "/usr/local/Cellar/python3/3.6.1/Frameworks/Python.framework/Versions/3.6/lib/python3.6/site-packages/sqlalchemy/pool.py", line 1193, in _do_get
    return self._create_connection()
  File "/usr/local/Cellar/python3/3.6.1/Frameworks/Python.framework/Versions/3.6/lib/python3.6/site-packages/sqlalchemy/pool.py", line 350, in _create_connection
    return _ConnectionRecord(self)
  File "/usr/local/Cellar/python3/3.6.1/Frameworks/Python.framework/Versions/3.6/lib/python3.6/site-packages/sqlalchemy/pool.py", line 477, in __init__
    self.__connect(first_connect_check=True)
  File "/usr/local/Cellar/python3/3.6.1/Frameworks/Python.framework/Versions/3.6/lib/python3.6/site-packages/sqlalchemy/pool.py", line 674, in __connect
    connection = pool._invoke_creator(self)
  File "/usr/local/Cellar/python3/3.6.1/Frameworks/Python.framework/Versions/3.6/lib/python3.6/site-packages/sqlalchemy/engine/strategies.py", line 106, in connect
    return dialect.connect(*cargs, **cparams)
  File "/usr/local/Cellar/python3/3.6.1/Frameworks/Python.framework/Versions/3.6/lib/python3.6/site-packages/sqlalchemy/engine/default.py", line 412, in connect
    return self.dbapi.connect(*cargs, **cparams)
  File "/usr/local/Cellar/python3/3.6.1/Frameworks/Python.framework/Versions/3.6/lib/python3.6/site-packages/pymysql/__init__.py", line 94, in Connect
    return Connection(*args, **kwargs)
  File "/usr/local/Cellar/python3/3.6.1/Frameworks/Python.framework/Versions/3.6/lib/python3.6/site-packages/pymysql/connections.py", line 327, in __init__
    self.connect()
  File "/usr/local/Cellar/python3/3.6.1/Frameworks/Python.framework/Versions/3.6/lib/python3.6/site-packages/pymysql/connections.py", line 629, in connect
    raise exc
sqlalchemy.exc.OperationalError: (pymysql.err.OperationalError) (2003, "Can't connect to MySQL server on 'localhost' ([Errno 61] Connection refused)") (Background on this error at: http://sqlalche.me/e/e3q8)
2018-07-13 14:53:10,773 /usr/local/lib/python3.6/site-packages/werkzeug/_internal.py[func:_log line:88] [INFO] 127.0.0.1 - - [13/Jul/2018 14:53:10] "GET /notebook/notebook HTTP/1.1" 500 -
2018-07-13 14:53:10,823 /usr/local/lib/python3.6/site-packages/werkzeug/_internal.py[func:_log line:88] [INFO] 127.0.0.1 - - [13/Jul/2018 14:53:10] "GET /notebook/notebook?__debugger__=yes&cmd=resource&f=debugger.js HTTP/1.1" 200 -
2018-07-13 14:53:10,826 /usr/local/lib/python3.6/site-packages/werkzeug/_internal.py[func:_log line:88] [INFO] 127.0.0.1 - - [13/Jul/2018 14:53:10] "GET /notebook/notebook?__debugger__=yes&cmd=resource&f=style.css HTTP/1.1" 200 -
2018-07-13 14:53:10,829 /usr/local/lib/python3.6/site-packages/werkzeug/_internal.py[func:_log line:88] [INFO] 127.0.0.1 - - [13/Jul/2018 14:53:10] "GET /notebook/notebook?__debugger__=yes&cmd=resource&f=jquery.js HTTP/1.1" 200 -
2018-07-13 14:53:10,889 /usr/local/lib/python3.6/site-packages/werkzeug/_internal.py[func:_log line:88] [INFO] 127.0.0.1 - - [13/Jul/2018 14:53:10] "GET /notebook/notebook?__debugger__=yes&cmd=resource&f=ubuntu.ttf HTTP/1.1" 200 -
2018-07-13 14:53:10,946 /usr/local/lib/python3.6/site-packages/werkzeug/_internal.py[func:_log line:88] [INFO] 127.0.0.1 - - [13/Jul/2018 14:53:10] "GET /notebook/notebook?__debugger__=yes&cmd=resource&f=console.png HTTP/1.1" 200 -
2018-07-13 14:53:31,748 /usr/local/lib/python3.6/site-packages/werkzeug/_internal.py[func:_log line:88] [INFO] 127.0.0.1 - - [13/Jul/2018 14:53:31] "GET /notebook/notebook HTTP/1.1" 500 -
2018-07-13 14:53:31,793 /usr/local/lib/python3.6/site-packages/werkzeug/_internal.py[func:_log line:88] [INFO] 127.0.0.1 - - [13/Jul/2018 14:53:31] "GET /notebook/notebook?__debugger__=yes&cmd=resource&f=debugger.js HTTP/1.1" 200 -
2018-07-13 14:53:31,796 /usr/local/lib/python3.6/site-packages/werkzeug/_internal.py[func:_log line:88] [INFO] 127.0.0.1 - - [13/Jul/2018 14:53:31] "GET /notebook/notebook?__debugger__=yes&cmd=resource&f=jquery.js HTTP/1.1" 200 -
2018-07-13 14:53:31,798 /usr/local/lib/python3.6/site-packages/werkzeug/_internal.py[func:_log line:88] [INFO] 127.0.0.1 - - [13/Jul/2018 14:53:31] "GET /notebook/notebook?__debugger__=yes&cmd=resource&f=style.css HTTP/1.1" 200 -
2018-07-13 14:53:31,861 /usr/local/lib/python3.6/site-packages/werkzeug/_internal.py[func:_log line:88] [INFO] 127.0.0.1 - - [13/Jul/2018 14:53:31] "GET /notebook/notebook?__debugger__=yes&cmd=resource&f=ubuntu.ttf HTTP/1.1" 200 -
2018-07-13 14:53:31,919 /usr/local/lib/python3.6/site-packages/werkzeug/_internal.py[func:_log line:88] [INFO] 127.0.0.1 - - [13/Jul/2018 14:53:31] "GET /notebook/notebook?__debugger__=yes&cmd=resource&f=console.png HTTP/1.1" 200 -
2018-07-13 14:55:15,804 /Users/Shared/dbj/api.kuaibi/micro_service/common/logger.py[func:__init__ line:23] [INFO] init log
2018-07-13 14:55:17,002 /Users/Shared/dbj/api.kuaibi/micro_service/main.py[func:<module> line:19] [ERROR] error
2018-07-13 14:55:17,003 /Users/Shared/dbj/api.kuaibi/micro_service/main.py[func:<module> line:20] [DEBUG] debug
2018-07-13 14:55:17,240 /usr/local/Cellar/python3/3.6.1/Frameworks/Python.framework/Versions/3.6/lib/python3.6/site-packages/werkzeug/_internal.py[func:_log line:88] [INFO]  * Running on http://0.0.0.0:5002/ (Press CTRL+C to quit)
2018-07-13 14:55:17,315 /usr/local/Cellar/python3/3.6.1/Frameworks/Python.framework/Versions/3.6/lib/python3.6/site-packages/werkzeug/_internal.py[func:_log line:88] [INFO]  * Restarting with fsevents reloader
2018-07-13 14:55:18,540 /Users/Shared/dbj/api.kuaibi/micro_service/common/logger.py[func:__init__ line:23] [INFO] init log
2018-07-13 14:55:19,768 /Users/Shared/dbj/api.kuaibi/micro_service/main.py[func:<module> line:19] [ERROR] error
2018-07-13 14:55:19,769 /Users/Shared/dbj/api.kuaibi/micro_service/main.py[func:<module> line:20] [DEBUG] debug
2018-07-13 14:55:20,026 /usr/local/lib/python3.6/site-packages/werkzeug/_internal.py[func:_log line:88] [WARNING]  * Debugger is active!
2018-07-13 14:55:20,070 /usr/local/lib/python3.6/site-packages/werkzeug/_internal.py[func:_log line:88] [INFO]  * Debugger PIN: 202-833-239
2018-07-13 14:55:51,621 /usr/local/lib/python3.6/site-packages/werkzeug/_internal.py[func:_log line:88] [INFO] 127.0.0.1 - - [13/Jul/2018 14:55:51] "GET /notebook/notebook HTTP/1.1" 500 -
2018-07-13 14:55:51,678 /usr/local/lib/python3.6/site-packages/werkzeug/_internal.py[func:_log line:88] [INFO] 127.0.0.1 - - [13/Jul/2018 14:55:51] "GET /notebook/notebook?__debugger__=yes&cmd=resource&f=debugger.js HTTP/1.1" 200 -
2018-07-13 14:55:51,682 /usr/local/lib/python3.6/site-packages/werkzeug/_internal.py[func:_log line:88] [INFO] 127.0.0.1 - - [13/Jul/2018 14:55:51] "GET /notebook/notebook?__debugger__=yes&cmd=resource&f=style.css HTTP/1.1" 200 -
2018-07-13 14:55:51,686 /usr/local/lib/python3.6/site-packages/werkzeug/_internal.py[func:_log line:88] [INFO] 127.0.0.1 - - [13/Jul/2018 14:55:51] "GET /notebook/notebook?__debugger__=yes&cmd=resource&f=jquery.js HTTP/1.1" 200 -
2018-07-13 14:55:51,726 /usr/local/lib/python3.6/site-packages/werkzeug/_internal.py[func:_log line:88] [INFO] 127.0.0.1 - - [13/Jul/2018 14:55:51] "GET /notebook/notebook?__debugger__=yes&cmd=resource&f=ubuntu.ttf HTTP/1.1" 200 -
2018-07-13 14:55:51,774 /usr/local/lib/python3.6/site-packages/werkzeug/_internal.py[func:_log line:88] [INFO] 127.0.0.1 - - [13/Jul/2018 14:55:51] "GET /notebook/notebook?__debugger__=yes&cmd=resource&f=console.png HTTP/1.1" 200 -
2018-07-13 17:35:37,583 /Users/Shared/dbj/api.kuaibi/micro_service/common/logger.py[func:__init__ line:23] [INFO] init log
2018-07-13 17:35:38,829 /Users/Shared/dbj/api.kuaibi/micro_service/main.py[func:<module> line:19] [ERROR] error
2018-07-13 17:35:38,829 /Users/Shared/dbj/api.kuaibi/micro_service/main.py[func:<module> line:20] [DEBUG] debug
2018-07-13 17:35:39,065 /usr/local/Cellar/python3/3.6.1/Frameworks/Python.framework/Versions/3.6/lib/python3.6/site-packages/werkzeug/_internal.py[func:_log line:88] [INFO]  * Running on http://0.0.0.0:5002/ (Press CTRL+C to quit)
2018-07-13 17:35:39,137 /usr/local/Cellar/python3/3.6.1/Frameworks/Python.framework/Versions/3.6/lib/python3.6/site-packages/werkzeug/_internal.py[func:_log line:88] [INFO]  * Restarting with fsevents reloader
2018-07-13 17:35:40,276 /Users/Shared/dbj/api.kuaibi/micro_service/common/logger.py[func:__init__ line:23] [INFO] init log
2018-07-13 17:35:41,105 /Users/Shared/dbj/api.kuaibi/micro_service/main.py[func:<module> line:19] [ERROR] error
2018-07-13 17:35:41,106 /Users/Shared/dbj/api.kuaibi/micro_service/main.py[func:<module> line:20] [DEBUG] debug
2018-07-13 17:35:41,368 /usr/local/lib/python3.6/site-packages/werkzeug/_internal.py[func:_log line:88] [WARNING]  * Debugger is active!
2018-07-13 17:35:41,409 /usr/local/lib/python3.6/site-packages/werkzeug/_internal.py[func:_log line:88] [INFO]  * Debugger PIN: 202-833-239
2018-07-13 17:36:18,729 /usr/local/lib/python3.6/site-packages/werkzeug/_internal.py[func:_log line:88] [INFO] 127.0.0.1 - - [13/Jul/2018 17:36:18] "GET /api/notebook HTTP/1.1" 500 -
2018-07-13 17:36:18,785 /usr/local/lib/python3.6/site-packages/werkzeug/_internal.py[func:_log line:88] [INFO] 127.0.0.1 - - [13/Jul/2018 17:36:18] "GET /api/notebook?__debugger__=yes&cmd=resource&f=debugger.js HTTP/1.1" 200 -
2018-07-13 17:36:18,788 /usr/local/lib/python3.6/site-packages/werkzeug/_internal.py[func:_log line:88] [INFO] 127.0.0.1 - - [13/Jul/2018 17:36:18] "GET /api/notebook?__debugger__=yes&cmd=resource&f=style.css HTTP/1.1" 200 -
2018-07-13 17:36:18,792 /usr/local/lib/python3.6/site-packages/werkzeug/_internal.py[func:_log line:88] [INFO] 127.0.0.1 - - [13/Jul/2018 17:36:18] "GET /api/notebook?__debugger__=yes&cmd=resource&f=jquery.js HTTP/1.1" 200 -
2018-07-13 17:36:18,833 /usr/local/lib/python3.6/site-packages/werkzeug/_internal.py[func:_log line:88] [INFO] 127.0.0.1 - - [13/Jul/2018 17:36:18] "GET /api/notebook?__debugger__=yes&cmd=resource&f=ubuntu.ttf HTTP/1.1" 200 -
2018-07-13 17:36:18,885 /usr/local/lib/python3.6/site-packages/werkzeug/_internal.py[func:_log line:88] [INFO] 127.0.0.1 - - [13/Jul/2018 17:36:18] "GET /api/notebook?__debugger__=yes&cmd=resource&f=console.png HTTP/1.1" 200 -
2018-07-13 17:36:19,010 /usr/local/lib/python3.6/site-packages/werkzeug/_internal.py[func:_log line:88] [INFO] 127.0.0.1 - - [13/Jul/2018 17:36:19] "GET /api/notebook?__debugger__=yes&cmd=resource&f=console.png HTTP/1.1" 200 -
2018-07-13 17:38:58,944 /Users/Shared/dbj/api.kuaibi/micro_service/common/logger.py[func:__init__ line:23] [INFO] init log
2018-07-13 17:38:59,949 /Users/Shared/dbj/api.kuaibi/micro_service/main.py[func:<module> line:19] [ERROR] error
2018-07-13 17:38:59,949 /Users/Shared/dbj/api.kuaibi/micro_service/main.py[func:<module> line:20] [DEBUG] debug
2018-07-13 17:39:00,191 /usr/local/Cellar/python3/3.6.1/Frameworks/Python.framework/Versions/3.6/lib/python3.6/site-packages/werkzeug/_internal.py[func:_log line:88] [INFO]  * Running on http://0.0.0.0:5002/ (Press CTRL+C to quit)
2018-07-13 17:39:00,258 /usr/local/Cellar/python3/3.6.1/Frameworks/Python.framework/Versions/3.6/lib/python3.6/site-packages/werkzeug/_internal.py[func:_log line:88] [INFO]  * Restarting with fsevents reloader
2018-07-13 17:39:01,406 /Users/Shared/dbj/api.kuaibi/micro_service/common/logger.py[func:__init__ line:23] [INFO] init log
2018-07-13 17:39:02,254 /Users/Shared/dbj/api.kuaibi/micro_service/main.py[func:<module> line:19] [ERROR] error
2018-07-13 17:39:02,254 /Users/Shared/dbj/api.kuaibi/micro_service/main.py[func:<module> line:20] [DEBUG] debug
2018-07-13 17:39:02,485 /usr/local/lib/python3.6/site-packages/werkzeug/_internal.py[func:_log line:88] [WARNING]  * Debugger is active!
2018-07-13 17:39:02,527 /usr/local/lib/python3.6/site-packages/werkzeug/_internal.py[func:_log line:88] [INFO]  * Debugger PIN: 202-833-239
2018-07-13 17:39:15,080 /usr/local/Cellar/python3/3.6.1/Frameworks/Python.framework/Versions/3.6/lib/python3.6/site-packages/grpc/_server.py[func:_call_behavior line:393] [ERROR] Exception calling application: 'list' object has no attribute 'id'
Traceback (most recent call last):
  File "/usr/local/Cellar/python3/3.6.1/Frameworks/Python.framework/Versions/3.6/lib/python3.6/site-packages/grpc/_server.py", line 385, in _call_behavior
    return behavior(argument, context), True
  File "/Users/Shared/dbj/api.kuaibi/micro_service/micro_services/notebook/services/notebook_service.py", line 23, in GetNotebookInfo
    return get_notebook(request, context)
  File "/Users/Shared/dbj/api.kuaibi/micro_service/micro_services/notebook/handlers/get_notebook_handler.py", line 38, in get_notebook
    books = notebook_manger.notebook_from(user_id)
  File "/Users/Shared/dbj/api.kuaibi/micro_service/micro_services/notebook/database/notebook_manger.py", line 47, in notebook_from
    d = {c.name: getattr(res, c.name) for c in r.__table__.columns}
  File "/Users/Shared/dbj/api.kuaibi/micro_service/micro_services/notebook/database/notebook_manger.py", line 47, in <dictcomp>
    d = {c.name: getattr(res, c.name) for c in r.__table__.columns}
AttributeError: 'list' object has no attribute 'id'
2018-07-13 17:39:15,140 /usr/local/lib/python3.6/site-packages/werkzeug/_internal.py[func:_log line:88] [INFO] 127.0.0.1 - - [13/Jul/2018 17:39:15] "GET /api/notebook HTTP/1.1" 500 -
2018-07-13 17:39:15,184 /usr/local/lib/python3.6/site-packages/werkzeug/_internal.py[func:_log line:88] [INFO] 127.0.0.1 - - [13/Jul/2018 17:39:15] "GET /api/notebook?__debugger__=yes&cmd=resource&f=debugger.js HTTP/1.1" 200 -
2018-07-13 17:39:15,190 /usr/local/lib/python3.6/site-packages/werkzeug/_internal.py[func:_log line:88] [INFO] 127.0.0.1 - - [13/Jul/2018 17:39:15] "GET /api/notebook?__debugger__=yes&cmd=resource&f=style.css HTTP/1.1" 200 -
2018-07-13 17:39:15,194 /usr/local/lib/python3.6/site-packages/werkzeug/_internal.py[func:_log line:88] [INFO] 127.0.0.1 - - [13/Jul/2018 17:39:15] "GET /api/notebook?__debugger__=yes&cmd=resource&f=jquery.js HTTP/1.1" 200 -
2018-07-13 17:39:15,234 /usr/local/lib/python3.6/site-packages/werkzeug/_internal.py[func:_log line:88] [INFO] 127.0.0.1 - - [13/Jul/2018 17:39:15] "GET /api/notebook?__debugger__=yes&cmd=resource&f=ubuntu.ttf HTTP/1.1" 200 -
2018-07-13 17:39:15,281 /usr/local/lib/python3.6/site-packages/werkzeug/_internal.py[func:_log line:88] [INFO] 127.0.0.1 - - [13/Jul/2018 17:39:15] "GET /api/notebook?__debugger__=yes&cmd=resource&f=console.png HTTP/1.1" 200 -
2018-07-13 17:39:36,584 /usr/local/Cellar/python3/3.6.1/Frameworks/Python.framework/Versions/3.6/lib/python3.6/site-packages/grpc/_server.py[func:_call_behavior line:393] [ERROR] Exception calling application: 'list' object has no attribute 'id'
Traceback (most recent call last):
  File "/usr/local/Cellar/python3/3.6.1/Frameworks/Python.framework/Versions/3.6/lib/python3.6/site-packages/grpc/_server.py", line 385, in _call_behavior
    return behavior(argument, context), True
  File "/Users/Shared/dbj/api.kuaibi/micro_service/micro_services/notebook/services/notebook_service.py", line 23, in GetNotebookInfo
    return get_notebook(request, context)
  File "/Users/Shared/dbj/api.kuaibi/micro_service/micro_services/notebook/handlers/get_notebook_handler.py", line 38, in get_notebook
    books = notebook_manger.notebook_from(user_id)
  File "/Users/Shared/dbj/api.kuaibi/micro_service/micro_services/notebook/database/notebook_manger.py", line 47, in notebook_from
    d = {c.name: getattr(res, c.name) for c in r.__table__.columns}
  File "/Users/Shared/dbj/api.kuaibi/micro_service/micro_services/notebook/database/notebook_manger.py", line 47, in <dictcomp>
    d = {c.name: getattr(res, c.name) for c in r.__table__.columns}
AttributeError: 'list' object has no attribute 'id'
2018-07-13 17:39:36,677 /usr/local/lib/python3.6/site-packages/werkzeug/_internal.py[func:_log line:88] [INFO] 127.0.0.1 - - [13/Jul/2018 17:39:36] "GET /api/notebook HTTP/1.1" 500 -
2018-07-13 17:39:36,715 /usr/local/lib/python3.6/site-packages/werkzeug/_internal.py[func:_log line:88] [INFO] 127.0.0.1 - - [13/Jul/2018 17:39:36] "GET /api/notebook?__debugger__=yes&cmd=resource&f=style.css HTTP/1.1" 200 -
2018-07-13 17:39:36,718 /usr/local/lib/python3.6/site-packages/werkzeug/_internal.py[func:_log line:88] [INFO] 127.0.0.1 - - [13/Jul/2018 17:39:36] "GET /api/notebook?__debugger__=yes&cmd=resource&f=jquery.js HTTP/1.1" 200 -
2018-07-13 17:39:36,720 /usr/local/lib/python3.6/site-packages/werkzeug/_internal.py[func:_log line:88] [INFO] 127.0.0.1 - - [13/Jul/2018 17:39:36] "GET /api/notebook?__debugger__=yes&cmd=resource&f=debugger.js HTTP/1.1" 200 -
2018-07-13 17:39:36,778 /usr/local/lib/python3.6/site-packages/werkzeug/_internal.py[func:_log line:88] [INFO] 127.0.0.1 - - [13/Jul/2018 17:39:36] "GET /api/notebook?__debugger__=yes&cmd=resource&f=ubuntu.ttf HTTP/1.1" 200 -
2018-07-13 17:39:36,840 /usr/local/lib/python3.6/site-packages/werkzeug/_internal.py[func:_log line:88] [INFO] 127.0.0.1 - - [13/Jul/2018 17:39:36] "GET /api/notebook?__debugger__=yes&cmd=resource&f=console.png HTTP/1.1" 200 -
2018-07-13 17:39:45,662 /usr/local/Cellar/python3/3.6.1/Frameworks/Python.framework/Versions/3.6/lib/python3.6/site-packages/grpc/_server.py[func:_call_behavior line:393] [ERROR] Exception calling application: 'list' object has no attribute 'id'
Traceback (most recent call last):
  File "/usr/local/Cellar/python3/3.6.1/Frameworks/Python.framework/Versions/3.6/lib/python3.6/site-packages/grpc/_server.py", line 385, in _call_behavior
    return behavior(argument, context), True
  File "/Users/Shared/dbj/api.kuaibi/micro_service/micro_services/notebook/services/notebook_service.py", line 23, in GetNotebookInfo
    return get_notebook(request, context)
  File "/Users/Shared/dbj/api.kuaibi/micro_service/micro_services/notebook/handlers/get_notebook_handler.py", line 38, in get_notebook
    books = notebook_manger.notebook_from(user_id)
  File "/Users/Shared/dbj/api.kuaibi/micro_service/micro_services/notebook/database/notebook_manger.py", line 47, in notebook_from
    d = {c.name: getattr(res, c.name) for c in r.__table__.columns}
  File "/Users/Shared/dbj/api.kuaibi/micro_service/micro_services/notebook/database/notebook_manger.py", line 47, in <dictcomp>
    d = {c.name: getattr(res, c.name) for c in r.__table__.columns}
AttributeError: 'list' object has no attribute 'id'
2018-07-13 17:39:45,709 /usr/local/lib/python3.6/site-packages/werkzeug/_internal.py[func:_log line:88] [INFO] 127.0.0.1 - - [13/Jul/2018 17:39:45] "GET /api/notebook HTTP/1.1" 500 -
2018-07-13 17:39:45,748 /usr/local/lib/python3.6/site-packages/werkzeug/_internal.py[func:_log line:88] [INFO] 127.0.0.1 - - [13/Jul/2018 17:39:45] "GET /api/notebook?__debugger__=yes&cmd=resource&f=style.css HTTP/1.1" 200 -
2018-07-13 17:39:45,753 /usr/local/lib/python3.6/site-packages/werkzeug/_internal.py[func:_log line:88] [INFO] 127.0.0.1 - - [13/Jul/2018 17:39:45] "GET /api/notebook?__debugger__=yes&cmd=resource&f=jquery.js HTTP/1.1" 200 -
2018-07-13 17:39:45,756 /usr/local/lib/python3.6/site-packages/werkzeug/_internal.py[func:_log line:88] [INFO] 127.0.0.1 - - [13/Jul/2018 17:39:45] "GET /api/notebook?__debugger__=yes&cmd=resource&f=debugger.js HTTP/1.1" 200 -
2018-07-13 17:39:45,809 /usr/local/lib/python3.6/site-packages/werkzeug/_internal.py[func:_log line:88] [INFO] 127.0.0.1 - - [13/Jul/2018 17:39:45] "GET /api/notebook?__debugger__=yes&cmd=resource&f=ubuntu.ttf HTTP/1.1" 200 -
2018-07-13 17:39:45,873 /usr/local/lib/python3.6/site-packages/werkzeug/_internal.py[func:_log line:88] [INFO] 127.0.0.1 - - [13/Jul/2018 17:39:45] "GET /api/notebook?__debugger__=yes&cmd=resource&f=console.png HTTP/1.1" 200 -
2018-07-13 17:40:17,938 /usr/local/lib/python3.6/site-packages/werkzeug/_internal.py[func:_log line:88] [INFO] 127.0.0.1 - - [13/Jul/2018 17:40:17] "GET /api/notebook HTTP/1.1" 500 -
2018-07-13 17:40:17,965 /usr/local/lib/python3.6/site-packages/werkzeug/_internal.py[func:_log line:88] [INFO] 127.0.0.1 - - [13/Jul/2018 17:40:17] "GET /api/notebook?__debugger__=yes&cmd=resource&f=style.css HTTP/1.1" 200 -
2018-07-13 17:40:17,975 /usr/local/lib/python3.6/site-packages/werkzeug/_internal.py[func:_log line:88] [INFO] 127.0.0.1 - - [13/Jul/2018 17:40:17] "GET /api/notebook?__debugger__=yes&cmd=resource&f=debugger.js HTTP/1.1" 200 -
2018-07-13 17:40:17,978 /usr/local/lib/python3.6/site-packages/werkzeug/_internal.py[func:_log line:88] [INFO] 127.0.0.1 - - [13/Jul/2018 17:40:17] "GET /api/notebook?__debugger__=yes&cmd=resource&f=jquery.js HTTP/1.1" 200 -
2018-07-13 17:40:18,020 /usr/local/lib/python3.6/site-packages/werkzeug/_internal.py[func:_log line:88] [INFO] 127.0.0.1 - - [13/Jul/2018 17:40:18] "GET /api/notebook?__debugger__=yes&cmd=resource&f=ubuntu.ttf HTTP/1.1" 200 -
2018-07-13 17:40:18,065 /usr/local/lib/python3.6/site-packages/werkzeug/_internal.py[func:_log line:88] [INFO] 127.0.0.1 - - [13/Jul/2018 17:40:18] "GET /api/notebook?__debugger__=yes&cmd=resource&f=console.png HTTP/1.1" 200 -
2018-07-13 17:42:02,242 /usr/local/lib/python3.6/site-packages/werkzeug/_internal.py[func:_log line:88] [INFO]  * Detected change in '/Users/Shared/dbj/api.kuaibi/micro_service/micro_services/notebook/database/notebook_manger.py', reloading
2018-07-13 17:42:02,245 /usr/local/lib/python3.6/site-packages/werkzeug/_internal.py[func:_log line:88] [INFO]  * Detected change in '/Users/Shared/dbj/api.kuaibi/micro_service/micro_services/notebook/database/notebook_manger.py', reloading
2018-07-13 17:46:17,777 /usr/local/Cellar/python3/3.6.1/Frameworks/Python.framework/Versions/3.6/lib/python3.6/site-packages/grpc/_server.py[func:_call_behavior line:393] [ERROR] Exception calling application: 'list' object has no attribute 'id'
Traceback (most recent call last):
  File "/usr/local/Cellar/python3/3.6.1/Frameworks/Python.framework/Versions/3.6/lib/python3.6/site-packages/grpc/_server.py", line 385, in _call_behavior
    return behavior(argument, context), True
  File "/Users/Shared/dbj/api.kuaibi/micro_service/micro_services/notebook/services/notebook_service.py", line 23, in GetNotebookInfo
    return get_notebook(request, context)
  File "/Users/Shared/dbj/api.kuaibi/micro_service/micro_services/notebook/handlers/get_notebook_handler.py", line 38, in get_notebook
    books = notebook_manger.notebook_from(user_id)
  File "/Users/Shared/dbj/api.kuaibi/micro_service/micro_services/notebook/database/notebook_manger.py", line 47, in notebook_from
    d = {c.name: getattr(r, c.name) for c in r.__table__.columns}
  File "/Users/Shared/dbj/api.kuaibi/micro_service/micro_services/notebook/database/notebook_manger.py", line 47, in <dictcomp>
    d = {c.name: getattr(r, c.name) for c in r.__table__.columns}
AttributeError: 'list' object has no attribute 'id'
2018-07-13 17:46:43,531 /Users/Shared/dbj/api.kuaibi/micro_service/common/logger.py[func:__init__ line:23] [INFO] init log
2018-07-13 17:46:44,565 /Users/Shared/dbj/api.kuaibi/micro_service/main.py[func:<module> line:19] [ERROR] error
2018-07-13 17:46:44,565 /Users/Shared/dbj/api.kuaibi/micro_service/main.py[func:<module> line:20] [DEBUG] debug
2018-07-13 17:46:44,802 /usr/local/Cellar/python3/3.6.1/Frameworks/Python.framework/Versions/3.6/lib/python3.6/site-packages/werkzeug/_internal.py[func:_log line:88] [INFO]  * Running on http://0.0.0.0:5002/ (Press CTRL+C to quit)
2018-07-13 17:46:44,867 /usr/local/Cellar/python3/3.6.1/Frameworks/Python.framework/Versions/3.6/lib/python3.6/site-packages/werkzeug/_internal.py[func:_log line:88] [INFO]  * Restarting with fsevents reloader
2018-07-13 17:46:45,999 /Users/Shared/dbj/api.kuaibi/micro_service/common/logger.py[func:__init__ line:23] [INFO] init log
2018-07-13 17:46:47,006 /Users/Shared/dbj/api.kuaibi/micro_service/main.py[func:<module> line:19] [ERROR] error
2018-07-13 17:46:47,007 /Users/Shared/dbj/api.kuaibi/micro_service/main.py[func:<module> line:20] [DEBUG] debug
2018-07-13 17:46:47,218 /usr/local/lib/python3.6/site-packages/werkzeug/_internal.py[func:_log line:88] [WARNING]  * Debugger is active!
2018-07-13 17:46:47,249 /usr/local/lib/python3.6/site-packages/werkzeug/_internal.py[func:_log line:88] [INFO]  * Debugger PIN: 202-833-239
2018-07-13 17:47:19,462 /usr/local/lib/python3.6/site-packages/werkzeug/_internal.py[func:_log line:88] [INFO] 127.0.0.1 - - [13/Jul/2018 17:47:19] "GET /api/notebook HTTP/1.1" 500 -
2018-07-13 17:47:19,543 /usr/local/lib/python3.6/site-packages/werkzeug/_internal.py[func:_log line:88] [INFO] 127.0.0.1 - - [13/Jul/2018 17:47:19] "GET /api/notebook HTTP/1.1" 500 -
2018-07-13 17:47:19,589 /usr/local/lib/python3.6/site-packages/werkzeug/_internal.py[func:_log line:88] [INFO] 127.0.0.1 - - [13/Jul/2018 17:47:19] "GET /api/notebook?__debugger__=yes&cmd=resource&f=debugger.js HTTP/1.1" 200 -
2018-07-13 17:47:19,592 /usr/local/lib/python3.6/site-packages/werkzeug/_internal.py[func:_log line:88] [INFO] 127.0.0.1 - - [13/Jul/2018 17:47:19] "GET /api/notebook?__debugger__=yes&cmd=resource&f=style.css HTTP/1.1" 200 -
2018-07-13 17:47:19,596 /usr/local/lib/python3.6/site-packages/werkzeug/_internal.py[func:_log line:88] [INFO] 127.0.0.1 - - [13/Jul/2018 17:47:19] "GET /api/notebook?__debugger__=yes&cmd=resource&f=jquery.js HTTP/1.1" 200 -
2018-07-13 17:47:19,635 /usr/local/lib/python3.6/site-packages/werkzeug/_internal.py[func:_log line:88] [INFO] 127.0.0.1 - - [13/Jul/2018 17:47:19] "GET /api/notebook?__debugger__=yes&cmd=resource&f=ubuntu.ttf HTTP/1.1" 200 -
2018-07-13 17:47:19,686 /usr/local/lib/python3.6/site-packages/werkzeug/_internal.py[func:_log line:88] [INFO] 127.0.0.1 - - [13/Jul/2018 17:47:19] "GET /api/notebook?__debugger__=yes&cmd=resource&f=console.png HTTP/1.1" 200 -
2018-07-13 17:50:50,760 /usr/local/lib/python3.6/site-packages/werkzeug/_internal.py[func:_log line:88] [INFO]  * Detected change in '/Users/Shared/dbj/api.kuaibi/micro_service/micro_services/notebook/database/notebook_manger.py', reloading
2018-07-13 17:50:50,762 /usr/local/lib/python3.6/site-packages/werkzeug/_internal.py[func:_log line:88] [INFO]  * Detected change in '/Users/Shared/dbj/api.kuaibi/micro_service/micro_services/notebook/database/notebook_manger.py', reloading
2018-07-13 17:50:52,082 /Users/Shared/dbj/api.kuaibi/micro_service/common/logger.py[func:__init__ line:23] [INFO] init log
2018-07-13 17:50:53,302 /Users/Shared/dbj/api.kuaibi/micro_service/main.py[func:<module> line:19] [ERROR] error
2018-07-13 17:50:53,302 /Users/Shared/dbj/api.kuaibi/micro_service/main.py[func:<module> line:20] [DEBUG] debug
2018-07-13 17:50:53,557 /usr/local/Cellar/python3/3.6.1/Frameworks/Python.framework/Versions/3.6/lib/python3.6/site-packages/werkzeug/_internal.py[func:_log line:88] [INFO]  * Running on http://0.0.0.0:5002/ (Press CTRL+C to quit)
2018-07-13 17:50:53,638 /usr/local/Cellar/python3/3.6.1/Frameworks/Python.framework/Versions/3.6/lib/python3.6/site-packages/werkzeug/_internal.py[func:_log line:88] [INFO]  * Restarting with fsevents reloader
2018-07-13 17:50:54,854 /Users/Shared/dbj/api.kuaibi/micro_service/common/logger.py[func:__init__ line:23] [INFO] init log
2018-07-13 17:50:55,790 /Users/Shared/dbj/api.kuaibi/micro_service/main.py[func:<module> line:19] [ERROR] error
2018-07-13 17:50:55,790 /Users/Shared/dbj/api.kuaibi/micro_service/main.py[func:<module> line:20] [DEBUG] debug
2018-07-13 17:50:56,020 /usr/local/lib/python3.6/site-packages/werkzeug/_internal.py[func:_log line:88] [WARNING]  * Debugger is active!
2018-07-13 17:50:56,062 /usr/local/lib/python3.6/site-packages/werkzeug/_internal.py[func:_log line:88] [INFO]  * Debugger PIN: 202-833-239
2018-07-13 17:51:07,199 /usr/local/Cellar/python3/3.6.1/Frameworks/Python.framework/Versions/3.6/lib/python3.6/site-packages/grpc/_server.py[func:_call_behavior line:393] [ERROR] Exception calling application: 'NotebookModel' object has no attribute 'r'
Traceback (most recent call last):
  File "/usr/local/Cellar/python3/3.6.1/Frameworks/Python.framework/Versions/3.6/lib/python3.6/site-packages/grpc/_server.py", line 385, in _call_behavior
    return behavior(argument, context), True
  File "/Users/Shared/dbj/api.kuaibi/micro_service/micro_services/notebook/services/notebook_service.py", line 23, in GetNotebookInfo
    return get_notebook(request, context)
  File "/Users/Shared/dbj/api.kuaibi/micro_service/micro_services/notebook/handlers/get_notebook_handler.py", line 38, in get_notebook
    books = notebook_manger.notebook_from(user_id)
  File "/Users/Shared/dbj/api.kuaibi/micro_service/micro_services/notebook/database/notebook_manger.py", line 49, in notebook_from
    for c in r.r.__table__.columns:
AttributeError: 'NotebookModel' object has no attribute 'r'
2018-07-13 17:51:07,263 /usr/local/lib/python3.6/site-packages/werkzeug/_internal.py[func:_log line:88] [INFO] 127.0.0.1 - - [13/Jul/2018 17:51:07] "GET /api/notebook HTTP/1.1" 500 -
2018-07-13 17:51:07,313 /usr/local/lib/python3.6/site-packages/werkzeug/_internal.py[func:_log line:88] [INFO] 127.0.0.1 - - [13/Jul/2018 17:51:07] "GET /api/notebook?__debugger__=yes&cmd=resource&f=jquery.js HTTP/1.1" 200 -
2018-07-13 17:51:07,316 /usr/local/lib/python3.6/site-packages/werkzeug/_internal.py[func:_log line:88] [INFO] 127.0.0.1 - - [13/Jul/2018 17:51:07] "GET /api/notebook?__debugger__=yes&cmd=resource&f=style.css HTTP/1.1" 200 -
2018-07-13 17:51:07,321 /usr/local/lib/python3.6/site-packages/werkzeug/_internal.py[func:_log line:88] [INFO] 127.0.0.1 - - [13/Jul/2018 17:51:07] "GET /api/notebook?__debugger__=yes&cmd=resource&f=debugger.js HTTP/1.1" 200 -
2018-07-13 17:51:07,353 /usr/local/lib/python3.6/site-packages/werkzeug/_internal.py[func:_log line:88] [INFO] 127.0.0.1 - - [13/Jul/2018 17:51:07] "GET /api/notebook?__debugger__=yes&cmd=resource&f=ubuntu.ttf HTTP/1.1" 200 -
2018-07-13 17:51:07,397 /usr/local/lib/python3.6/site-packages/werkzeug/_internal.py[func:_log line:88] [INFO] 127.0.0.1 - - [13/Jul/2018 17:51:07] "GET /api/notebook?__debugger__=yes&cmd=resource&f=console.png HTTP/1.1" 200 -
2018-07-13 17:51:37,066 /usr/local/Cellar/python3/3.6.1/Frameworks/Python.framework/Versions/3.6/lib/python3.6/site-packages/grpc/_server.py[func:_call_behavior line:393] [ERROR] Exception calling application: 'NotebookModel' object has no attribute 'r'
Traceback (most recent call last):
  File "/usr/local/Cellar/python3/3.6.1/Frameworks/Python.framework/Versions/3.6/lib/python3.6/site-packages/grpc/_server.py", line 385, in _call_behavior
    return behavior(argument, context), True
  File "/Users/Shared/dbj/api.kuaibi/micro_service/micro_services/notebook/services/notebook_service.py", line 23, in GetNotebookInfo
    return get_notebook(request, context)
  File "/Users/Shared/dbj/api.kuaibi/micro_service/micro_services/notebook/handlers/get_notebook_handler.py", line 38, in get_notebook
    books = notebook_manger.notebook_from(user_id)
  File "/Users/Shared/dbj/api.kuaibi/micro_service/micro_services/notebook/database/notebook_manger.py", line 49, in notebook_from
    for c in r.r.__table__.columns:
AttributeError: 'NotebookModel' object has no attribute 'r'
2018-07-13 17:51:37,229 /usr/local/lib/python3.6/site-packages/werkzeug/_internal.py[func:_log line:88] [INFO] 127.0.0.1 - - [13/Jul/2018 17:51:37] "GET /api/notebook HTTP/1.1" 500 -
2018-07-13 17:51:37,264 /usr/local/lib/python3.6/site-packages/werkzeug/_internal.py[func:_log line:88] [INFO] 127.0.0.1 - - [13/Jul/2018 17:51:37] "GET /api/notebook?__debugger__=yes&cmd=resource&f=style.css HTTP/1.1" 200 -
2018-07-13 17:51:37,268 /usr/local/lib/python3.6/site-packages/werkzeug/_internal.py[func:_log line:88] [INFO] 127.0.0.1 - - [13/Jul/2018 17:51:37] "GET /api/notebook?__debugger__=yes&cmd=resource&f=jquery.js HTTP/1.1" 200 -
2018-07-13 17:51:37,269 /usr/local/lib/python3.6/site-packages/werkzeug/_internal.py[func:_log line:88] [INFO] 127.0.0.1 - - [13/Jul/2018 17:51:37] "GET /api/notebook?__debugger__=yes&cmd=resource&f=debugger.js HTTP/1.1" 200 -
2018-07-13 17:51:37,326 /usr/local/lib/python3.6/site-packages/werkzeug/_internal.py[func:_log line:88] [INFO] 127.0.0.1 - - [13/Jul/2018 17:51:37] "GET /api/notebook?__debugger__=yes&cmd=resource&f=ubuntu.ttf HTTP/1.1" 200 -
2018-07-13 17:51:37,377 /usr/local/lib/python3.6/site-packages/werkzeug/_internal.py[func:_log line:88] [INFO] 127.0.0.1 - - [13/Jul/2018 17:51:37] "GET /api/notebook?__debugger__=yes&cmd=resource&f=console.png HTTP/1.1" 200 -
2018-07-13 17:52:05,232 /usr/local/lib/python3.6/site-packages/werkzeug/_internal.py[func:_log line:88] [INFO]  * Detected change in '/Users/Shared/dbj/api.kuaibi/micro_service/micro_services/notebook/database/notebook_manger.py', reloading
2018-07-13 17:52:05,241 /usr/local/lib/python3.6/site-packages/werkzeug/_internal.py[func:_log line:88] [INFO]  * Detected change in '/Users/Shared/dbj/api.kuaibi/micro_service/micro_services/notebook/database/notebook_manger.py', reloading
2018-07-13 17:52:08,973 /Users/Shared/dbj/api.kuaibi/micro_service/common/logger.py[func:__init__ line:23] [INFO] init log
2018-07-13 17:52:11,451 /Users/Shared/dbj/api.kuaibi/micro_service/common/logger.py[func:__init__ line:23] [INFO] init log
2018-07-13 17:52:12,554 /Users/Shared/dbj/api.kuaibi/micro_service/main.py[func:<module> line:19] [ERROR] error
2018-07-13 17:52:12,554 /Users/Shared/dbj/api.kuaibi/micro_service/main.py[func:<module> line:20] [DEBUG] debug
2018-07-13 17:52:12,787 /usr/local/Cellar/python3/3.6.1/Frameworks/Python.framework/Versions/3.6/lib/python3.6/site-packages/werkzeug/_internal.py[func:_log line:88] [INFO]  * Running on http://0.0.0.0:5002/ (Press CTRL+C to quit)
2018-07-13 17:52:12,862 /usr/local/Cellar/python3/3.6.1/Frameworks/Python.framework/Versions/3.6/lib/python3.6/site-packages/werkzeug/_internal.py[func:_log line:88] [INFO]  * Restarting with fsevents reloader
2018-07-13 17:52:14,049 /Users/Shared/dbj/api.kuaibi/micro_service/common/logger.py[func:__init__ line:23] [INFO] init log
2018-07-13 17:52:14,992 /Users/Shared/dbj/api.kuaibi/micro_service/main.py[func:<module> line:19] [ERROR] error
2018-07-13 17:52:14,992 /Users/Shared/dbj/api.kuaibi/micro_service/main.py[func:<module> line:20] [DEBUG] debug
2018-07-13 17:52:15,226 /usr/local/lib/python3.6/site-packages/werkzeug/_internal.py[func:_log line:88] [WARNING]  * Debugger is active!
2018-07-13 17:52:15,277 /usr/local/lib/python3.6/site-packages/werkzeug/_internal.py[func:_log line:88] [INFO]  * Debugger PIN: 202-833-239
2018-07-13 17:52:46,776 /usr/local/lib/python3.6/site-packages/werkzeug/_internal.py[func:_log line:88] [INFO] 127.0.0.1 - - [13/Jul/2018 17:52:46] "GET /api/notebook HTTP/1.1" 500 -
2018-07-13 17:52:47,011 /usr/local/lib/python3.6/site-packages/werkzeug/_internal.py[func:_log line:88] [INFO] 127.0.0.1 - - [13/Jul/2018 17:52:47] "GET /api/notebook HTTP/1.1" 500 -
2018-07-13 17:52:47,056 /usr/local/lib/python3.6/site-packages/werkzeug/_internal.py[func:_log line:88] [INFO] 127.0.0.1 - - [13/Jul/2018 17:52:47] "GET /api/notebook?__debugger__=yes&cmd=resource&f=debugger.js HTTP/1.1" 200 -
2018-07-13 17:52:47,058 /usr/local/lib/python3.6/site-packages/werkzeug/_internal.py[func:_log line:88] [INFO] 127.0.0.1 - - [13/Jul/2018 17:52:47] "GET /api/notebook?__debugger__=yes&cmd=resource&f=style.css HTTP/1.1" 200 -
2018-07-13 17:52:47,061 /usr/local/lib/python3.6/site-packages/werkzeug/_internal.py[func:_log line:88] [INFO] 127.0.0.1 - - [13/Jul/2018 17:52:47] "GET /api/notebook?__debugger__=yes&cmd=resource&f=jquery.js HTTP/1.1" 200 -
2018-07-13 17:52:47,096 /usr/local/lib/python3.6/site-packages/werkzeug/_internal.py[func:_log line:88] [INFO] 127.0.0.1 - - [13/Jul/2018 17:52:47] "GET /api/notebook?__debugger__=yes&cmd=resource&f=ubuntu.ttf HTTP/1.1" 200 -
2018-07-13 17:52:47,144 /usr/local/lib/python3.6/site-packages/werkzeug/_internal.py[func:_log line:88] [INFO] 127.0.0.1 - - [13/Jul/2018 17:52:47] "GET /api/notebook?__debugger__=yes&cmd=resource&f=console.png HTTP/1.1" 200 -
2018-07-13 18:01:22,680 /usr/local/lib/python3.6/site-packages/werkzeug/_internal.py[func:_log line:88] [INFO]  * Detected change in '/Users/Shared/dbj/api.kuaibi/micro_service/utilities/util.py', reloading
2018-07-13 18:01:22,683 /usr/local/lib/python3.6/site-packages/werkzeug/_internal.py[func:_log line:88] [INFO]  * Detected change in '/Users/Shared/dbj/api.kuaibi/micro_service/utilities/util.py', reloading
2018-07-13 18:34:09,256 /Users/Shared/dbj/api.kuaibi/micro_service/common/logger.py[func:__init__ line:23] [INFO] init log
2018-07-13 18:34:10,453 /Users/Shared/dbj/api.kuaibi/micro_service/main.py[func:<module> line:19] [ERROR] error
2018-07-13 18:34:10,454 /Users/Shared/dbj/api.kuaibi/micro_service/main.py[func:<module> line:20] [DEBUG] debug
2018-07-13 18:34:10,702 /usr/local/Cellar/python3/3.6.1/Frameworks/Python.framework/Versions/3.6/lib/python3.6/site-packages/werkzeug/_internal.py[func:_log line:88] [INFO]  * Running on http://0.0.0.0:5002/ (Press CTRL+C to quit)
2018-07-13 18:34:10,784 /usr/local/Cellar/python3/3.6.1/Frameworks/Python.framework/Versions/3.6/lib/python3.6/site-packages/werkzeug/_internal.py[func:_log line:88] [INFO]  * Restarting with fsevents reloader
2018-07-13 18:34:11,939 /Users/Shared/dbj/api.kuaibi/micro_service/common/logger.py[func:__init__ line:23] [INFO] init log
2018-07-13 18:34:15,245 /Users/Shared/dbj/api.kuaibi/micro_service/main.py[func:<module> line:19] [ERROR] error
2018-07-13 18:34:15,246 /Users/Shared/dbj/api.kuaibi/micro_service/main.py[func:<module> line:20] [DEBUG] debug
2018-07-13 18:34:15,548 /usr/local/lib/python3.6/site-packages/werkzeug/_internal.py[func:_log line:88] [WARNING]  * Debugger is active!
2018-07-13 18:34:15,587 /usr/local/lib/python3.6/site-packages/werkzeug/_internal.py[func:_log line:88] [INFO]  * Debugger PIN: 202-833-239
2018-07-13 18:34:24,785 /Users/Shared/dbj/api.kuaibi/micro_service/common/logger.py[func:__init__ line:23] [INFO] init log
2018-07-13 18:34:25,759 /Users/Shared/dbj/api.kuaibi/micro_service/main.py[func:<module> line:19] [ERROR] error
2018-07-13 18:34:25,760 /Users/Shared/dbj/api.kuaibi/micro_service/main.py[func:<module> line:20] [DEBUG] debug
2018-07-13 18:34:25,988 /usr/local/Cellar/python3/3.6.1/Frameworks/Python.framework/Versions/3.6/lib/python3.6/site-packages/werkzeug/_internal.py[func:_log line:88] [INFO]  * Running on http://0.0.0.0:5002/ (Press CTRL+C to quit)
2018-07-13 18:34:26,056 /usr/local/Cellar/python3/3.6.1/Frameworks/Python.framework/Versions/3.6/lib/python3.6/site-packages/werkzeug/_internal.py[func:_log line:88] [INFO]  * Restarting with fsevents reloader
2018-07-13 18:34:27,059 /Users/Shared/dbj/api.kuaibi/micro_service/common/logger.py[func:__init__ line:23] [INFO] init log
2018-07-13 18:34:27,853 /Users/Shared/dbj/api.kuaibi/micro_service/main.py[func:<module> line:19] [ERROR] error
2018-07-13 18:34:27,853 /Users/Shared/dbj/api.kuaibi/micro_service/main.py[func:<module> line:20] [DEBUG] debug
2018-07-13 18:34:28,071 /usr/local/lib/python3.6/site-packages/werkzeug/_internal.py[func:_log line:88] [WARNING]  * Debugger is active!
2018-07-13 18:34:28,102 /usr/local/lib/python3.6/site-packages/werkzeug/_internal.py[func:_log line:88] [INFO]  * Debugger PIN: 202-833-239
2018-07-13 18:35:03,645 /usr/local/lib/python3.6/site-packages/werkzeug/_internal.py[func:_log line:88] [INFO] 127.0.0.1 - - [13/Jul/2018 18:35:03] "GET /api/notebook HTTP/1.1" 500 -
2018-07-13 18:35:03,690 /usr/local/lib/python3.6/site-packages/werkzeug/_internal.py[func:_log line:88] [INFO] 127.0.0.1 - - [13/Jul/2018 18:35:03] "GET /api/notebook?__debugger__=yes&cmd=resource&f=style.css HTTP/1.1" 200 -
2018-07-13 18:35:03,694 /usr/local/lib/python3.6/site-packages/werkzeug/_internal.py[func:_log line:88] [INFO] 127.0.0.1 - - [13/Jul/2018 18:35:03] "GET /api/notebook?__debugger__=yes&cmd=resource&f=jquery.js HTTP/1.1" 200 -
2018-07-13 18:35:03,700 /usr/local/lib/python3.6/site-packages/werkzeug/_internal.py[func:_log line:88] [INFO] 127.0.0.1 - - [13/Jul/2018 18:35:03] "GET /api/notebook?__debugger__=yes&cmd=resource&f=debugger.js HTTP/1.1" 200 -
2018-07-13 18:35:03,735 /usr/local/lib/python3.6/site-packages/werkzeug/_internal.py[func:_log line:88] [INFO] 127.0.0.1 - - [13/Jul/2018 18:35:03] "GET /api/notebook?__debugger__=yes&cmd=resource&f=ubuntu.ttf HTTP/1.1" 200 -
2018-07-13 18:35:03,779 /usr/local/lib/python3.6/site-packages/werkzeug/_internal.py[func:_log line:88] [INFO] 127.0.0.1 - - [13/Jul/2018 18:35:03] "GET /api/notebook?__debugger__=yes&cmd=resource&f=console.png HTTP/1.1" 200 -
2018-07-13 18:37:02,798 /usr/local/lib/python3.6/site-packages/werkzeug/_internal.py[func:_log line:88] [INFO]  * Detected change in '/Users/Shared/dbj/api.kuaibi/micro_service/micro_services/notebook/database/base_manger.py', reloading
2018-07-13 19:55:18,263 /Users/Shared/dbj/api.kuaibi/micro_service/common/logger.py[func:__init__ line:23] [INFO] init log
2018-07-13 19:55:19,507 /Users/Shared/dbj/api.kuaibi/micro_service/main.py[func:<module> line:19] [ERROR] error
2018-07-13 19:55:19,507 /Users/Shared/dbj/api.kuaibi/micro_service/main.py[func:<module> line:20] [DEBUG] debug
2018-07-13 19:55:19,754 /usr/local/Cellar/python3/3.6.1/Frameworks/Python.framework/Versions/3.6/lib/python3.6/site-packages/werkzeug/_internal.py[func:_log line:88] [INFO]  * Running on http://0.0.0.0:5002/ (Press CTRL+C to quit)
2018-07-13 19:55:19,830 /usr/local/Cellar/python3/3.6.1/Frameworks/Python.framework/Versions/3.6/lib/python3.6/site-packages/werkzeug/_internal.py[func:_log line:88] [INFO]  * Restarting with fsevents reloader
2018-07-13 19:55:20,995 /Users/Shared/dbj/api.kuaibi/micro_service/common/logger.py[func:__init__ line:23] [INFO] init log
2018-07-13 19:55:21,886 /Users/Shared/dbj/api.kuaibi/micro_service/main.py[func:<module> line:19] [ERROR] error
2018-07-13 19:55:21,886 /Users/Shared/dbj/api.kuaibi/micro_service/main.py[func:<module> line:20] [DEBUG] debug
2018-07-13 19:55:22,126 /usr/local/lib/python3.6/site-packages/werkzeug/_internal.py[func:_log line:88] [WARNING]  * Debugger is active!
2018-07-13 19:55:22,170 /usr/local/lib/python3.6/site-packages/werkzeug/_internal.py[func:_log line:88] [INFO]  * Debugger PIN: 202-833-239
2018-07-13 19:55:32,246 /usr/local/Cellar/python3/3.6.1/Frameworks/Python.framework/Versions/3.6/lib/python3.6/site-packages/grpc/_server.py[func:_call_behavior line:393] [ERROR] Exception calling application: query not dict
Traceback (most recent call last):
  File "/usr/local/Cellar/python3/3.6.1/Frameworks/Python.framework/Versions/3.6/lib/python3.6/site-packages/grpc/_server.py", line 385, in _call_behavior
    return behavior(argument, context), True
  File "/Users/Shared/dbj/api.kuaibi/micro_service/micro_services/notebook/services/notebook_service.py", line 23, in GetNotebookInfo
    return get_notebook(request, context)
  File "/Users/Shared/dbj/api.kuaibi/micro_service/micro_services/notebook/handlers/get_notebook_handler.py", line 38, in get_notebook
    books = notebook_manger.notebook_from(user_id)
  File "/Users/Shared/dbj/api.kuaibi/micro_service/micro_services/notebook/database/notebook_manger.py", line 72, in notebook_from
    raise Exception('query not dict')
Exception: query not dict
2018-07-13 19:55:32,300 /usr/local/lib/python3.6/site-packages/werkzeug/_internal.py[func:_log line:88] [INFO] 127.0.0.1 - - [13/Jul/2018 19:55:32] "GET /api/notebook HTTP/1.1" 500 -
2018-07-13 19:55:32,364 /usr/local/lib/python3.6/site-packages/werkzeug/_internal.py[func:_log line:88] [INFO] 127.0.0.1 - - [13/Jul/2018 19:55:32] "GET /api/notebook?__debugger__=yes&cmd=resource&f=style.css HTTP/1.1" 200 -
2018-07-13 19:55:32,367 /usr/local/lib/python3.6/site-packages/werkzeug/_internal.py[func:_log line:88] [INFO] 127.0.0.1 - - [13/Jul/2018 19:55:32] "GET /api/notebook?__debugger__=yes&cmd=resource&f=debugger.js HTTP/1.1" 200 -
2018-07-13 19:55:32,370 /usr/local/lib/python3.6/site-packages/werkzeug/_internal.py[func:_log line:88] [INFO] 127.0.0.1 - - [13/Jul/2018 19:55:32] "GET /api/notebook?__debugger__=yes&cmd=resource&f=jquery.js HTTP/1.1" 200 -
2018-07-13 19:55:32,409 /usr/local/lib/python3.6/site-packages/werkzeug/_internal.py[func:_log line:88] [INFO] 127.0.0.1 - - [13/Jul/2018 19:55:32] "GET /api/notebook?__debugger__=yes&cmd=resource&f=ubuntu.ttf HTTP/1.1" 200 -
2018-07-13 19:55:32,455 /usr/local/lib/python3.6/site-packages/werkzeug/_internal.py[func:_log line:88] [INFO] 127.0.0.1 - - [13/Jul/2018 19:55:32] "GET /api/notebook?__debugger__=yes&cmd=resource&f=console.png HTTP/1.1" 200 -
2018-07-13 19:55:47,628 /usr/local/Cellar/python3/3.6.1/Frameworks/Python.framework/Versions/3.6/lib/python3.6/site-packages/grpc/_server.py[func:_call_behavior line:393] [ERROR] Exception calling application: query not dict
Traceback (most recent call last):
  File "/usr/local/Cellar/python3/3.6.1/Frameworks/Python.framework/Versions/3.6/lib/python3.6/site-packages/grpc/_server.py", line 385, in _call_behavior
    return behavior(argument, context), True
  File "/Users/Shared/dbj/api.kuaibi/micro_service/micro_services/notebook/services/notebook_service.py", line 23, in GetNotebookInfo
    return get_notebook(request, context)
  File "/Users/Shared/dbj/api.kuaibi/micro_service/micro_services/notebook/handlers/get_notebook_handler.py", line 38, in get_notebook
    books = notebook_manger.notebook_from(user_id)
  File "/Users/Shared/dbj/api.kuaibi/micro_service/micro_services/notebook/database/notebook_manger.py", line 72, in notebook_from
    raise Exception('query not dict')
Exception: query not dict
2018-07-13 19:55:47,674 /usr/local/lib/python3.6/site-packages/werkzeug/_internal.py[func:_log line:88] [INFO] 127.0.0.1 - - [13/Jul/2018 19:55:47] "GET /api/notebook HTTP/1.1" 500 -
2018-07-13 19:55:47,713 /usr/local/lib/python3.6/site-packages/werkzeug/_internal.py[func:_log line:88] [INFO] 127.0.0.1 - - [13/Jul/2018 19:55:47] "GET /api/notebook?__debugger__=yes&cmd=resource&f=style.css HTTP/1.1" 200 -
2018-07-13 19:55:47,717 /usr/local/lib/python3.6/site-packages/werkzeug/_internal.py[func:_log line:88] [INFO] 127.0.0.1 - - [13/Jul/2018 19:55:47] "GET /api/notebook?__debugger__=yes&cmd=resource&f=jquery.js HTTP/1.1" 200 -
2018-07-13 19:55:47,721 /usr/local/lib/python3.6/site-packages/werkzeug/_internal.py[func:_log line:88] [INFO] 127.0.0.1 - - [13/Jul/2018 19:55:47] "GET /api/notebook?__debugger__=yes&cmd=resource&f=debugger.js HTTP/1.1" 200 -
2018-07-13 19:55:47,779 /usr/local/lib/python3.6/site-packages/werkzeug/_internal.py[func:_log line:88] [INFO] 127.0.0.1 - - [13/Jul/2018 19:55:47] "GET /api/notebook?__debugger__=yes&cmd=resource&f=ubuntu.ttf HTTP/1.1" 200 -
2018-07-13 19:55:47,846 /usr/local/lib/python3.6/site-packages/werkzeug/_internal.py[func:_log line:88] [INFO] 127.0.0.1 - - [13/Jul/2018 19:55:47] "GET /api/notebook?__debugger__=yes&cmd=resource&f=console.png HTTP/1.1" 200 -
2018-07-13 19:55:54,656 /usr/local/Cellar/python3/3.6.1/Frameworks/Python.framework/Versions/3.6/lib/python3.6/site-packages/grpc/_server.py[func:_call_behavior line:393] [ERROR] Exception calling application: query not dict
Traceback (most recent call last):
  File "/usr/local/Cellar/python3/3.6.1/Frameworks/Python.framework/Versions/3.6/lib/python3.6/site-packages/grpc/_server.py", line 385, in _call_behavior
    return behavior(argument, context), True
  File "/Users/Shared/dbj/api.kuaibi/micro_service/micro_services/notebook/services/notebook_service.py", line 23, in GetNotebookInfo
    return get_notebook(request, context)
  File "/Users/Shared/dbj/api.kuaibi/micro_service/micro_services/notebook/handlers/get_notebook_handler.py", line 38, in get_notebook
    books = notebook_manger.notebook_from(user_id)
  File "/Users/Shared/dbj/api.kuaibi/micro_service/micro_services/notebook/database/notebook_manger.py", line 72, in notebook_from
    raise Exception('query not dict')
Exception: query not dict
2018-07-13 19:55:54,709 /usr/local/lib/python3.6/site-packages/werkzeug/_internal.py[func:_log line:88] [INFO] 127.0.0.1 - - [13/Jul/2018 19:55:54] "GET /api/notebook HTTP/1.1" 500 -
2018-07-13 19:55:54,748 /usr/local/lib/python3.6/site-packages/werkzeug/_internal.py[func:_log line:88] [INFO] 127.0.0.1 - - [13/Jul/2018 19:55:54] "GET /api/notebook?__debugger__=yes&cmd=resource&f=style.css HTTP/1.1" 200 -
2018-07-13 19:55:54,751 /usr/local/lib/python3.6/site-packages/werkzeug/_internal.py[func:_log line:88] [INFO] 127.0.0.1 - - [13/Jul/2018 19:55:54] "GET /api/notebook?__debugger__=yes&cmd=resource&f=debugger.js HTTP/1.1" 200 -
2018-07-13 19:55:54,756 /usr/local/lib/python3.6/site-packages/werkzeug/_internal.py[func:_log line:88] [INFO] 127.0.0.1 - - [13/Jul/2018 19:55:54] "GET /api/notebook?__debugger__=yes&cmd=resource&f=jquery.js HTTP/1.1" 200 -
2018-07-13 19:55:54,808 /usr/local/lib/python3.6/site-packages/werkzeug/_internal.py[func:_log line:88] [INFO] 127.0.0.1 - - [13/Jul/2018 19:55:54] "GET /api/notebook?__debugger__=yes&cmd=resource&f=ubuntu.ttf HTTP/1.1" 200 -
2018-07-13 19:55:54,861 /usr/local/lib/python3.6/site-packages/werkzeug/_internal.py[func:_log line:88] [INFO] 127.0.0.1 - - [13/Jul/2018 19:55:54] "GET /api/notebook?__debugger__=yes&cmd=resource&f=console.png HTTP/1.1" 200 -
2018-07-13 19:56:03,343 /usr/local/Cellar/python3/3.6.1/Frameworks/Python.framework/Versions/3.6/lib/python3.6/site-packages/grpc/_server.py[func:_call_behavior line:393] [ERROR] Exception calling application: query not dict
Traceback (most recent call last):
  File "/usr/local/Cellar/python3/3.6.1/Frameworks/Python.framework/Versions/3.6/lib/python3.6/site-packages/grpc/_server.py", line 385, in _call_behavior
    return behavior(argument, context), True
  File "/Users/Shared/dbj/api.kuaibi/micro_service/micro_services/notebook/services/notebook_service.py", line 23, in GetNotebookInfo
    return get_notebook(request, context)
  File "/Users/Shared/dbj/api.kuaibi/micro_service/micro_services/notebook/handlers/get_notebook_handler.py", line 38, in get_notebook
    books = notebook_manger.notebook_from(user_id)
  File "/Users/Shared/dbj/api.kuaibi/micro_service/micro_services/notebook/database/notebook_manger.py", line 72, in notebook_from
    raise Exception('query not dict')
Exception: query not dict
2018-07-13 19:56:03,567 /usr/local/lib/python3.6/site-packages/werkzeug/_internal.py[func:_log line:88] [INFO] 127.0.0.1 - - [13/Jul/2018 19:56:03] "GET /api/notebook HTTP/1.1" 500 -
2018-07-13 19:56:03,599 /usr/local/lib/python3.6/site-packages/werkzeug/_internal.py[func:_log line:88] [INFO] 127.0.0.1 - - [13/Jul/2018 19:56:03] "GET /api/notebook?__debugger__=yes&cmd=resource&f=style.css HTTP/1.1" 200 -
2018-07-13 19:56:03,602 /usr/local/lib/python3.6/site-packages/werkzeug/_internal.py[func:_log line:88] [INFO] 127.0.0.1 - - [13/Jul/2018 19:56:03] "GET /api/notebook?__debugger__=yes&cmd=resource&f=debugger.js HTTP/1.1" 200 -
2018-07-13 19:56:03,607 /usr/local/lib/python3.6/site-packages/werkzeug/_internal.py[func:_log line:88] [INFO] 127.0.0.1 - - [13/Jul/2018 19:56:03] "GET /api/notebook?__debugger__=yes&cmd=resource&f=jquery.js HTTP/1.1" 200 -
2018-07-13 19:56:03,667 /usr/local/lib/python3.6/site-packages/werkzeug/_internal.py[func:_log line:88] [INFO] 127.0.0.1 - - [13/Jul/2018 19:56:03] "GET /api/notebook?__debugger__=yes&cmd=resource&f=ubuntu.ttf HTTP/1.1" 200 -
2018-07-13 19:56:03,719 /usr/local/lib/python3.6/site-packages/werkzeug/_internal.py[func:_log line:88] [INFO] 127.0.0.1 - - [13/Jul/2018 19:56:03] "GET /api/notebook?__debugger__=yes&cmd=resource&f=console.png HTTP/1.1" 200 -
2018-07-13 19:56:30,396 /usr/local/lib/python3.6/site-packages/werkzeug/_internal.py[func:_log line:88] [INFO]  * Detected change in '/Users/Shared/dbj/api.kuaibi/micro_service/micro_services/notebook/database/notebook_manger.py', reloading
2018-07-13 19:56:30,399 /usr/local/lib/python3.6/site-packages/werkzeug/_internal.py[func:_log line:88] [INFO]  * Detected change in '/Users/Shared/dbj/api.kuaibi/micro_service/micro_services/notebook/database/notebook_manger.py', reloading
2018-07-13 19:56:52,724 /Users/Shared/dbj/api.kuaibi/micro_service/common/logger.py[func:__init__ line:23] [INFO] init log
2018-07-13 19:56:53,977 /Users/Shared/dbj/api.kuaibi/micro_service/main.py[func:<module> line:19] [ERROR] error
2018-07-13 19:56:53,978 /Users/Shared/dbj/api.kuaibi/micro_service/main.py[func:<module> line:20] [DEBUG] debug
2018-07-13 19:56:54,215 /usr/local/Cellar/python3/3.6.1/Frameworks/Python.framework/Versions/3.6/lib/python3.6/site-packages/werkzeug/_internal.py[func:_log line:88] [INFO]  * Running on http://0.0.0.0:5002/ (Press CTRL+C to quit)
2018-07-13 19:56:54,295 /usr/local/Cellar/python3/3.6.1/Frameworks/Python.framework/Versions/3.6/lib/python3.6/site-packages/werkzeug/_internal.py[func:_log line:88] [INFO]  * Restarting with fsevents reloader
2018-07-13 19:56:55,524 /Users/Shared/dbj/api.kuaibi/micro_service/common/logger.py[func:__init__ line:23] [INFO] init log
2018-07-13 19:56:56,419 /Users/Shared/dbj/api.kuaibi/micro_service/main.py[func:<module> line:19] [ERROR] error
2018-07-13 19:56:56,420 /Users/Shared/dbj/api.kuaibi/micro_service/main.py[func:<module> line:20] [DEBUG] debug
2018-07-13 19:56:56,647 /usr/local/lib/python3.6/site-packages/werkzeug/_internal.py[func:_log line:88] [WARNING]  * Debugger is active!
2018-07-13 19:56:56,686 /usr/local/lib/python3.6/site-packages/werkzeug/_internal.py[func:_log line:88] [INFO]  * Debugger PIN: 202-833-239
2018-07-13 19:57:28,472 /usr/local/lib/python3.6/site-packages/werkzeug/_internal.py[func:_log line:88] [INFO] 127.0.0.1 - - [13/Jul/2018 19:57:28] "GET /api/notebook HTTP/1.1" 500 -
2018-07-13 19:57:28,537 /usr/local/lib/python3.6/site-packages/werkzeug/_internal.py[func:_log line:88] [INFO] 127.0.0.1 - - [13/Jul/2018 19:57:28] "GET /api/notebook?__debugger__=yes&cmd=resource&f=style.css HTTP/1.1" 200 -
2018-07-13 19:57:28,544 /usr/local/lib/python3.6/site-packages/werkzeug/_internal.py[func:_log line:88] [INFO] 127.0.0.1 - - [13/Jul/2018 19:57:28] "GET /api/notebook?__debugger__=yes&cmd=resource&f=jquery.js HTTP/1.1" 200 -
2018-07-13 19:57:28,552 /usr/local/lib/python3.6/site-packages/werkzeug/_internal.py[func:_log line:88] [INFO] 127.0.0.1 - - [13/Jul/2018 19:57:28] "GET /api/notebook?__debugger__=yes&cmd=resource&f=debugger.js HTTP/1.1" 200 -
2018-07-13 19:57:28,605 /usr/local/lib/python3.6/site-packages/werkzeug/_internal.py[func:_log line:88] [INFO] 127.0.0.1 - - [13/Jul/2018 19:57:28] "GET /api/notebook?__debugger__=yes&cmd=resource&f=ubuntu.ttf HTTP/1.1" 200 -
2018-07-13 19:57:28,686 /usr/local/lib/python3.6/site-packages/werkzeug/_internal.py[func:_log line:88] [INFO]  * Detected change in '/Users/Shared/dbj/api.kuaibi/micro_service/micro_services/notebook/database/notebook_manger.py', reloading
2018-07-13 19:57:28,691 /usr/local/lib/python3.6/site-packages/werkzeug/_internal.py[func:_log line:88] [INFO]  * Detected change in '/Users/Shared/dbj/api.kuaibi/micro_service/micro_services/notebook/database/notebook_manger.py', reloading
2018-07-13 19:57:28,695 /usr/local/lib/python3.6/site-packages/werkzeug/_internal.py[func:_log line:88] [INFO] 127.0.0.1 - - [13/Jul/2018 19:57:28] "GET /api/notebook?__debugger__=yes&cmd=resource&f=console.png HTTP/1.1" 200 -
2018-07-13 19:57:32,954 /Users/Shared/dbj/api.kuaibi/micro_service/common/logger.py[func:__init__ line:23] [INFO] init log
2018-07-13 19:57:33,960 /Users/Shared/dbj/api.kuaibi/micro_service/main.py[func:<module> line:19] [ERROR] error
2018-07-13 19:57:33,960 /Users/Shared/dbj/api.kuaibi/micro_service/main.py[func:<module> line:20] [DEBUG] debug
2018-07-13 19:57:34,200 /usr/local/Cellar/python3/3.6.1/Frameworks/Python.framework/Versions/3.6/lib/python3.6/site-packages/werkzeug/_internal.py[func:_log line:88] [INFO]  * Running on http://0.0.0.0:5002/ (Press CTRL+C to quit)
2018-07-13 19:57:34,272 /usr/local/Cellar/python3/3.6.1/Frameworks/Python.framework/Versions/3.6/lib/python3.6/site-packages/werkzeug/_internal.py[func:_log line:88] [INFO]  * Restarting with fsevents reloader
2018-07-13 19:57:35,488 /Users/Shared/dbj/api.kuaibi/micro_service/common/logger.py[func:__init__ line:23] [INFO] init log
2018-07-13 19:57:36,569 /Users/Shared/dbj/api.kuaibi/micro_service/main.py[func:<module> line:19] [ERROR] error
2018-07-13 19:57:36,569 /Users/Shared/dbj/api.kuaibi/micro_service/main.py[func:<module> line:20] [DEBUG] debug
2018-07-13 19:57:36,818 /usr/local/lib/python3.6/site-packages/werkzeug/_internal.py[func:_log line:88] [WARNING]  * Debugger is active!
2018-07-13 19:57:36,862 /usr/local/lib/python3.6/site-packages/werkzeug/_internal.py[func:_log line:88] [INFO]  * Debugger PIN: 202-833-239
2018-07-13 19:57:40,619 /usr/local/Cellar/python3/3.6.1/Frameworks/Python.framework/Versions/3.6/lib/python3.6/site-packages/grpc/_server.py[func:_call_behavior line:393] [ERROR] Exception calling application: argument of type 'property' is not iterable
Traceback (most recent call last):
  File "/usr/local/Cellar/python3/3.6.1/Frameworks/Python.framework/Versions/3.6/lib/python3.6/site-packages/grpc/_server.py", line 385, in _call_behavior
    return behavior(argument, context), True
  File "/Users/Shared/dbj/api.kuaibi/micro_service/micro_services/notebook/services/notebook_service.py", line 23, in GetNotebookInfo
    return get_notebook(request, context)
  File "/Users/Shared/dbj/api.kuaibi/micro_service/micro_services/notebook/handlers/get_notebook_handler.py", line 38, in get_notebook
    books = notebook_manger.notebook_from(user_id)
  File "/Users/Shared/dbj/api.kuaibi/micro_service/micro_services/notebook/database/notebook_manger.py", line 82, in notebook_from
    a = self.new_notebook(query)
  File "/Users/Shared/dbj/api.kuaibi/micro_service/micro_services/notebook/database/notebook_manger.py", line 44, in new_notebook
    d = self.filter_data(model, data)
  File "/Users/Shared/dbj/api.kuaibi/micro_service/micro_services/notebook/database/base_manger.py", line 21, in filter_data
    if k in model.columns:
TypeError: argument of type 'property' is not iterable
2018-07-13 19:57:40,687 /usr/local/lib/python3.6/site-packages/werkzeug/_internal.py[func:_log line:88] [INFO] 127.0.0.1 - - [13/Jul/2018 19:57:40] "GET /api/notebook HTTP/1.1" 500 -
2018-07-13 19:57:40,723 /usr/local/lib/python3.6/site-packages/werkzeug/_internal.py[func:_log line:88] [INFO] 127.0.0.1 - - [13/Jul/2018 19:57:40] "GET /api/notebook?__debugger__=yes&cmd=resource&f=jquery.js HTTP/1.1" 200 -
2018-07-13 19:57:40,729 /usr/local/lib/python3.6/site-packages/werkzeug/_internal.py[func:_log line:88] [INFO] 127.0.0.1 - - [13/Jul/2018 19:57:40] "GET /api/notebook?__debugger__=yes&cmd=resource&f=style.css HTTP/1.1" 200 -
2018-07-13 19:57:40,731 /usr/local/lib/python3.6/site-packages/werkzeug/_internal.py[func:_log line:88] [INFO] 127.0.0.1 - - [13/Jul/2018 19:57:40] "GET /api/notebook?__debugger__=yes&cmd=resource&f=debugger.js HTTP/1.1" 200 -
2018-07-13 19:57:40,766 /usr/local/lib/python3.6/site-packages/werkzeug/_internal.py[func:_log line:88] [INFO] 127.0.0.1 - - [13/Jul/2018 19:57:40] "GET /api/notebook?__debugger__=yes&cmd=resource&f=ubuntu.ttf HTTP/1.1" 200 -
2018-07-13 19:57:40,816 /usr/local/lib/python3.6/site-packages/werkzeug/_internal.py[func:_log line:88] [INFO] 127.0.0.1 - - [13/Jul/2018 19:57:40] "GET /api/notebook?__debugger__=yes&cmd=resource&f=console.png HTTP/1.1" 200 -
2018-07-13 19:59:08,563 /Users/Shared/dbj/api.kuaibi/micro_service/common/logger.py[func:__init__ line:23] [INFO] init log
2018-07-13 19:59:09,820 /Users/Shared/dbj/api.kuaibi/micro_service/main.py[func:<module> line:19] [ERROR] error
2018-07-13 19:59:09,821 /Users/Shared/dbj/api.kuaibi/micro_service/main.py[func:<module> line:20] [DEBUG] debug
2018-07-13 19:59:10,069 /usr/local/Cellar/python3/3.6.1/Frameworks/Python.framework/Versions/3.6/lib/python3.6/site-packages/werkzeug/_internal.py[func:_log line:88] [INFO]  * Running on http://0.0.0.0:5002/ (Press CTRL+C to quit)
2018-07-13 19:59:10,142 /usr/local/Cellar/python3/3.6.1/Frameworks/Python.framework/Versions/3.6/lib/python3.6/site-packages/werkzeug/_internal.py[func:_log line:88] [INFO]  * Restarting with fsevents reloader
2018-07-13 19:59:11,306 /Users/Shared/dbj/api.kuaibi/micro_service/common/logger.py[func:__init__ line:23] [INFO] init log
2018-07-13 19:59:12,194 /Users/Shared/dbj/api.kuaibi/micro_service/main.py[func:<module> line:19] [ERROR] error
2018-07-13 19:59:12,194 /Users/Shared/dbj/api.kuaibi/micro_service/main.py[func:<module> line:20] [DEBUG] debug
2018-07-13 19:59:12,427 /usr/local/lib/python3.6/site-packages/werkzeug/_internal.py[func:_log line:88] [WARNING]  * Debugger is active!
2018-07-13 19:59:12,465 /usr/local/lib/python3.6/site-packages/werkzeug/_internal.py[func:_log line:88] [INFO]  * Debugger PIN: 202-833-239
2018-07-13 19:59:44,091 /usr/local/lib/python3.6/site-packages/werkzeug/_internal.py[func:_log line:88] [INFO] 127.0.0.1 - - [13/Jul/2018 19:59:44] "GET /api/notebook HTTP/1.1" 500 -
2018-07-13 19:59:44,142 /usr/local/lib/python3.6/site-packages/werkzeug/_internal.py[func:_log line:88] [INFO] 127.0.0.1 - - [13/Jul/2018 19:59:44] "GET /api/notebook?__debugger__=yes&cmd=resource&f=debugger.js HTTP/1.1" 200 -
2018-07-13 19:59:44,145 /usr/local/lib/python3.6/site-packages/werkzeug/_internal.py[func:_log line:88] [INFO] 127.0.0.1 - - [13/Jul/2018 19:59:44] "GET /api/notebook?__debugger__=yes&cmd=resource&f=jquery.js HTTP/1.1" 200 -
2018-07-13 19:59:44,152 /usr/local/lib/python3.6/site-packages/werkzeug/_internal.py[func:_log line:88] [INFO] 127.0.0.1 - - [13/Jul/2018 19:59:44] "GET /api/notebook?__debugger__=yes&cmd=resource&f=style.css HTTP/1.1" 200 -
2018-07-13 19:59:44,190 /usr/local/lib/python3.6/site-packages/werkzeug/_internal.py[func:_log line:88] [INFO] 127.0.0.1 - - [13/Jul/2018 19:59:44] "GET /api/notebook?__debugger__=yes&cmd=resource&f=ubuntu.ttf HTTP/1.1" 200 -
2018-07-13 19:59:44,241 /usr/local/lib/python3.6/site-packages/werkzeug/_internal.py[func:_log line:88] [INFO] 127.0.0.1 - - [13/Jul/2018 19:59:44] "GET /api/notebook?__debugger__=yes&cmd=resource&f=console.png HTTP/1.1" 200 -
2018-07-13 20:01:25,144 /Users/Shared/dbj/api.kuaibi/micro_service/common/logger.py[func:__init__ line:23] [INFO] init log
2018-07-13 20:01:26,424 /Users/Shared/dbj/api.kuaibi/micro_service/main.py[func:<module> line:19] [ERROR] error
2018-07-13 20:01:26,424 /Users/Shared/dbj/api.kuaibi/micro_service/main.py[func:<module> line:20] [DEBUG] debug
2018-07-13 20:01:26,655 /usr/local/Cellar/python3/3.6.1/Frameworks/Python.framework/Versions/3.6/lib/python3.6/site-packages/werkzeug/_internal.py[func:_log line:88] [INFO]  * Running on http://0.0.0.0:5002/ (Press CTRL+C to quit)
2018-07-13 20:01:26,731 /usr/local/Cellar/python3/3.6.1/Frameworks/Python.framework/Versions/3.6/lib/python3.6/site-packages/werkzeug/_internal.py[func:_log line:88] [INFO]  * Restarting with fsevents reloader
2018-07-13 20:01:27,876 /Users/Shared/dbj/api.kuaibi/micro_service/common/logger.py[func:__init__ line:23] [INFO] init log
2018-07-13 20:01:28,739 /Users/Shared/dbj/api.kuaibi/micro_service/main.py[func:<module> line:19] [ERROR] error
2018-07-13 20:01:28,739 /Users/Shared/dbj/api.kuaibi/micro_service/main.py[func:<module> line:20] [DEBUG] debug
2018-07-13 20:01:28,961 /usr/local/lib/python3.6/site-packages/werkzeug/_internal.py[func:_log line:88] [WARNING]  * Debugger is active!
2018-07-13 20:01:29,000 /usr/local/lib/python3.6/site-packages/werkzeug/_internal.py[func:_log line:88] [INFO]  * Debugger PIN: 202-833-239
2018-07-13 20:01:48,201 /usr/local/Cellar/python3/3.6.1/Frameworks/Python.framework/Versions/3.6/lib/python3.6/site-packages/grpc/_server.py[func:_call_behavior line:393] [ERROR] Exception calling application: argument of type 'DeclarativeMeta' is not iterable
Traceback (most recent call last):
  File "/usr/local/Cellar/python3/3.6.1/Frameworks/Python.framework/Versions/3.6/lib/python3.6/site-packages/grpc/_server.py", line 385, in _call_behavior
    return behavior(argument, context), True
  File "/Users/Shared/dbj/api.kuaibi/micro_service/micro_services/notebook/services/notebook_service.py", line 23, in GetNotebookInfo
    return get_notebook(request, context)
  File "/Users/Shared/dbj/api.kuaibi/micro_service/micro_services/notebook/handlers/get_notebook_handler.py", line 38, in get_notebook
    books = notebook_manger.notebook_from(user_id)
  File "/Users/Shared/dbj/api.kuaibi/micro_service/micro_services/notebook/database/notebook_manger.py", line 82, in notebook_from
    a = self.new_notebook(query)
  File "/Users/Shared/dbj/api.kuaibi/micro_service/micro_services/notebook/database/notebook_manger.py", line 44, in new_notebook
    d = self.filter_data(model, data)
  File "/Users/Shared/dbj/api.kuaibi/micro_service/micro_services/notebook/database/base_manger.py", line 21, in filter_data
    if k in model:
TypeError: argument of type 'DeclarativeMeta' is not iterable
2018-07-13 20:01:48,399 /usr/local/lib/python3.6/site-packages/werkzeug/_internal.py[func:_log line:88] [INFO] 127.0.0.1 - - [13/Jul/2018 20:01:48] "GET /api/notebook HTTP/1.1" 500 -
2018-07-13 20:01:48,450 /usr/local/lib/python3.6/site-packages/werkzeug/_internal.py[func:_log line:88] [INFO] 127.0.0.1 - - [13/Jul/2018 20:01:48] "GET /api/notebook?__debugger__=yes&cmd=resource&f=style.css HTTP/1.1" 200 -
2018-07-13 20:01:48,453 /usr/local/lib/python3.6/site-packages/werkzeug/_internal.py[func:_log line:88] [INFO] 127.0.0.1 - - [13/Jul/2018 20:01:48] "GET /api/notebook?__debugger__=yes&cmd=resource&f=jquery.js HTTP/1.1" 200 -
2018-07-13 20:01:48,457 /usr/local/lib/python3.6/site-packages/werkzeug/_internal.py[func:_log line:88] [INFO] 127.0.0.1 - - [13/Jul/2018 20:01:48] "GET /api/notebook?__debugger__=yes&cmd=resource&f=debugger.js HTTP/1.1" 200 -
2018-07-13 20:01:48,494 /usr/local/lib/python3.6/site-packages/werkzeug/_internal.py[func:_log line:88] [INFO] 127.0.0.1 - - [13/Jul/2018 20:01:48] "GET /api/notebook?__debugger__=yes&cmd=resource&f=ubuntu.ttf HTTP/1.1" 200 -
2018-07-13 20:01:48,540 /usr/local/lib/python3.6/site-packages/werkzeug/_internal.py[func:_log line:88] [INFO] 127.0.0.1 - - [13/Jul/2018 20:01:48] "GET /api/notebook?__debugger__=yes&cmd=resource&f=console.png HTTP/1.1" 200 -
2018-07-13 20:02:24,810 /usr/local/lib/python3.6/site-packages/werkzeug/_internal.py[func:_log line:88] [INFO] 127.0.0.1 - - [13/Jul/2018 20:02:24] "GET /api/notebook HTTP/1.1" 500 -
2018-07-13 20:02:24,834 /usr/local/lib/python3.6/site-packages/werkzeug/_internal.py[func:_log line:88] [INFO] 127.0.0.1 - - [13/Jul/2018 20:02:24] "GET /api/notebook?__debugger__=yes&cmd=resource&f=style.css HTTP/1.1" 200 -
2018-07-13 20:02:24,850 /usr/local/lib/python3.6/site-packages/werkzeug/_internal.py[func:_log line:88] [INFO] 127.0.0.1 - - [13/Jul/2018 20:02:24] "GET /api/notebook?__debugger__=yes&cmd=resource&f=debugger.js HTTP/1.1" 200 -
2018-07-13 20:02:24,853 /usr/local/lib/python3.6/site-packages/werkzeug/_internal.py[func:_log line:88] [INFO] 127.0.0.1 - - [13/Jul/2018 20:02:24] "GET /api/notebook?__debugger__=yes&cmd=resource&f=jquery.js HTTP/1.1" 200 -
2018-07-13 20:02:24,900 /usr/local/lib/python3.6/site-packages/werkzeug/_internal.py[func:_log line:88] [INFO] 127.0.0.1 - - [13/Jul/2018 20:02:24] "GET /api/notebook?__debugger__=yes&cmd=resource&f=ubuntu.ttf HTTP/1.1" 200 -
2018-07-13 20:02:24,948 /usr/local/lib/python3.6/site-packages/werkzeug/_internal.py[func:_log line:88] [INFO] 127.0.0.1 - - [13/Jul/2018 20:02:24] "GET /api/notebook?__debugger__=yes&cmd=resource&f=console.png HTTP/1.1" 200 -
2018-07-13 20:02:26,527 /Users/Shared/dbj/api.kuaibi/micro_service/common/logger.py[func:__init__ line:23] [INFO] init log
2018-07-13 20:02:28,266 /Users/Shared/dbj/api.kuaibi/micro_service/main.py[func:<module> line:19] [ERROR] error
2018-07-13 20:02:28,267 /Users/Shared/dbj/api.kuaibi/micro_service/main.py[func:<module> line:20] [DEBUG] debug
2018-07-13 20:02:28,539 /usr/local/Cellar/python3/3.6.1/Frameworks/Python.framework/Versions/3.6/lib/python3.6/site-packages/werkzeug/_internal.py[func:_log line:88] [INFO]  * Running on http://0.0.0.0:5002/ (Press CTRL+C to quit)
2018-07-13 20:02:28,616 /usr/local/Cellar/python3/3.6.1/Frameworks/Python.framework/Versions/3.6/lib/python3.6/site-packages/werkzeug/_internal.py[func:_log line:88] [INFO]  * Restarting with fsevents reloader
2018-07-13 20:02:29,837 /Users/Shared/dbj/api.kuaibi/micro_service/common/logger.py[func:__init__ line:23] [INFO] init log
2018-07-13 20:02:30,770 /Users/Shared/dbj/api.kuaibi/micro_service/main.py[func:<module> line:19] [ERROR] error
2018-07-13 20:02:30,770 /Users/Shared/dbj/api.kuaibi/micro_service/main.py[func:<module> line:20] [DEBUG] debug
2018-07-13 20:02:31,010 /usr/local/lib/python3.6/site-packages/werkzeug/_internal.py[func:_log line:88] [WARNING]  * Debugger is active!
2018-07-13 20:02:31,051 /usr/local/lib/python3.6/site-packages/werkzeug/_internal.py[func:_log line:88] [INFO]  * Debugger PIN: 202-833-239
2018-07-13 20:02:39,051 /usr/local/Cellar/python3/3.6.1/Frameworks/Python.framework/Versions/3.6/lib/python3.6/site-packages/grpc/_server.py[func:_call_behavior line:393] [ERROR] Exception calling application: argument of type 'property' is not iterable
Traceback (most recent call last):
  File "/usr/local/Cellar/python3/3.6.1/Frameworks/Python.framework/Versions/3.6/lib/python3.6/site-packages/grpc/_server.py", line 385, in _call_behavior
    return behavior(argument, context), True
  File "/Users/Shared/dbj/api.kuaibi/micro_service/micro_services/notebook/services/notebook_service.py", line 23, in GetNotebookInfo
    return get_notebook(request, context)
  File "/Users/Shared/dbj/api.kuaibi/micro_service/micro_services/notebook/handlers/get_notebook_handler.py", line 38, in get_notebook
    books = notebook_manger.notebook_from(user_id)
  File "/Users/Shared/dbj/api.kuaibi/micro_service/micro_services/notebook/database/notebook_manger.py", line 82, in notebook_from
    a = self.new_notebook(query)
  File "/Users/Shared/dbj/api.kuaibi/micro_service/micro_services/notebook/database/notebook_manger.py", line 44, in new_notebook
    d = self.filter_data(model, data)
  File "/Users/Shared/dbj/api.kuaibi/micro_service/micro_services/notebook/database/base_manger.py", line 21, in filter_data
    if k in model.members:
TypeError: argument of type 'property' is not iterable
2018-07-13 20:02:39,104 /usr/local/lib/python3.6/site-packages/werkzeug/_internal.py[func:_log line:88] [INFO] 127.0.0.1 - - [13/Jul/2018 20:02:39] "GET /api/notebook HTTP/1.1" 500 -
2018-07-13 20:02:39,142 /usr/local/lib/python3.6/site-packages/werkzeug/_internal.py[func:_log line:88] [INFO] 127.0.0.1 - - [13/Jul/2018 20:02:39] "GET /api/notebook?__debugger__=yes&cmd=resource&f=style.css HTTP/1.1" 200 -
2018-07-13 20:02:39,147 /usr/local/lib/python3.6/site-packages/werkzeug/_internal.py[func:_log line:88] [INFO] 127.0.0.1 - - [13/Jul/2018 20:02:39] "GET /api/notebook?__debugger__=yes&cmd=resource&f=debugger.js HTTP/1.1" 200 -
2018-07-13 20:02:39,149 /usr/local/lib/python3.6/site-packages/werkzeug/_internal.py[func:_log line:88] [INFO] 127.0.0.1 - - [13/Jul/2018 20:02:39] "GET /api/notebook?__debugger__=yes&cmd=resource&f=jquery.js HTTP/1.1" 200 -
2018-07-13 20:02:39,187 /usr/local/lib/python3.6/site-packages/werkzeug/_internal.py[func:_log line:88] [INFO] 127.0.0.1 - - [13/Jul/2018 20:02:39] "GET /api/notebook?__debugger__=yes&cmd=resource&f=ubuntu.ttf HTTP/1.1" 200 -
2018-07-13 20:02:39,235 /usr/local/lib/python3.6/site-packages/werkzeug/_internal.py[func:_log line:88] [INFO] 127.0.0.1 - - [13/Jul/2018 20:02:39] "GET /api/notebook?__debugger__=yes&cmd=resource&f=console.png HTTP/1.1" 200 -
2018-07-13 20:02:58,501 /usr/local/lib/python3.6/site-packages/werkzeug/_internal.py[func:_log line:88] [INFO]  * Detected change in '/Users/Shared/dbj/api.kuaibi/micro_service/micro_services/notebook/database/base_manger.py', reloading
2018-07-13 20:02:58,504 /usr/local/lib/python3.6/site-packages/werkzeug/_internal.py[func:_log line:88] [INFO]  * Detected change in '/Users/Shared/dbj/api.kuaibi/micro_service/micro_services/notebook/database/base_manger.py', reloading
2018-07-13 20:03:01,188 /Users/Shared/dbj/api.kuaibi/micro_service/common/logger.py[func:__init__ line:23] [INFO] init log
2018-07-13 20:03:02,208 /Users/Shared/dbj/api.kuaibi/micro_service/main.py[func:<module> line:19] [ERROR] error
2018-07-13 20:03:02,208 /Users/Shared/dbj/api.kuaibi/micro_service/main.py[func:<module> line:20] [DEBUG] debug
2018-07-13 20:03:02,476 /usr/local/Cellar/python3/3.6.1/Frameworks/Python.framework/Versions/3.6/lib/python3.6/site-packages/werkzeug/_internal.py[func:_log line:88] [INFO]  * Running on http://0.0.0.0:5002/ (Press CTRL+C to quit)
2018-07-13 20:03:02,557 /usr/local/Cellar/python3/3.6.1/Frameworks/Python.framework/Versions/3.6/lib/python3.6/site-packages/werkzeug/_internal.py[func:_log line:88] [INFO]  * Restarting with fsevents reloader
2018-07-13 20:03:03,751 /Users/Shared/dbj/api.kuaibi/micro_service/common/logger.py[func:__init__ line:23] [INFO] init log
2018-07-13 20:03:04,678 /Users/Shared/dbj/api.kuaibi/micro_service/main.py[func:<module> line:19] [ERROR] error
2018-07-13 20:03:04,678 /Users/Shared/dbj/api.kuaibi/micro_service/main.py[func:<module> line:20] [DEBUG] debug
2018-07-13 20:03:04,918 /usr/local/lib/python3.6/site-packages/werkzeug/_internal.py[func:_log line:88] [WARNING]  * Debugger is active!
2018-07-13 20:03:04,957 /usr/local/lib/python3.6/site-packages/werkzeug/_internal.py[func:_log line:88] [INFO]  * Debugger PIN: 202-833-239
2018-07-13 20:03:36,504 /usr/local/lib/python3.6/site-packages/werkzeug/_internal.py[func:_log line:88] [INFO] 127.0.0.1 - - [13/Jul/2018 20:03:36] "GET /api/notebook HTTP/1.1" 500 -
2018-07-13 20:03:36,558 /usr/local/lib/python3.6/site-packages/werkzeug/_internal.py[func:_log line:88] [INFO] 127.0.0.1 - - [13/Jul/2018 20:03:36] "GET /api/notebook?__debugger__=yes&cmd=resource&f=jquery.js HTTP/1.1" 200 -
2018-07-13 20:03:36,561 /usr/local/lib/python3.6/site-packages/werkzeug/_internal.py[func:_log line:88] [INFO] 127.0.0.1 - - [13/Jul/2018 20:03:36] "GET /api/notebook?__debugger__=yes&cmd=resource&f=debugger.js HTTP/1.1" 200 -
2018-07-13 20:03:36,567 /usr/local/lib/python3.6/site-packages/werkzeug/_internal.py[func:_log line:88] [INFO] 127.0.0.1 - - [13/Jul/2018 20:03:36] "GET /api/notebook?__debugger__=yes&cmd=resource&f=style.css HTTP/1.1" 200 -
2018-07-13 20:03:36,596 /usr/local/lib/python3.6/site-packages/werkzeug/_internal.py[func:_log line:88] [INFO] 127.0.0.1 - - [13/Jul/2018 20:03:36] "GET /api/notebook?__debugger__=yes&cmd=resource&f=ubuntu.ttf HTTP/1.1" 200 -
2018-07-13 20:03:36,646 /usr/local/lib/python3.6/site-packages/werkzeug/_internal.py[func:_log line:88] [INFO] 127.0.0.1 - - [13/Jul/2018 20:03:36] "GET /api/notebook?__debugger__=yes&cmd=resource&f=console.png HTTP/1.1" 200 -
2018-07-13 20:04:40,939 /Users/Shared/dbj/api.kuaibi/micro_service/common/logger.py[func:__init__ line:23] [INFO] init log
2018-07-13 20:04:41,904 /Users/Shared/dbj/api.kuaibi/micro_service/main.py[func:<module> line:19] [ERROR] error
2018-07-13 20:04:41,904 /Users/Shared/dbj/api.kuaibi/micro_service/main.py[func:<module> line:20] [DEBUG] debug
2018-07-13 20:04:42,141 /usr/local/Cellar/python3/3.6.1/Frameworks/Python.framework/Versions/3.6/lib/python3.6/site-packages/werkzeug/_internal.py[func:_log line:88] [INFO]  * Running on http://0.0.0.0:5002/ (Press CTRL+C to quit)
2018-07-13 20:04:42,207 /usr/local/Cellar/python3/3.6.1/Frameworks/Python.framework/Versions/3.6/lib/python3.6/site-packages/werkzeug/_internal.py[func:_log line:88] [INFO]  * Restarting with fsevents reloader
2018-07-13 20:04:43,202 /Users/Shared/dbj/api.kuaibi/micro_service/common/logger.py[func:__init__ line:23] [INFO] init log
2018-07-13 20:04:44,148 /Users/Shared/dbj/api.kuaibi/micro_service/main.py[func:<module> line:19] [ERROR] error
2018-07-13 20:04:44,149 /Users/Shared/dbj/api.kuaibi/micro_service/main.py[func:<module> line:20] [DEBUG] debug
2018-07-13 20:04:44,426 /usr/local/lib/python3.6/site-packages/werkzeug/_internal.py[func:_log line:88] [WARNING]  * Debugger is active!
2018-07-13 20:04:44,457 /usr/local/lib/python3.6/site-packages/werkzeug/_internal.py[func:_log line:88] [INFO]  * Debugger PIN: 202-833-239
2018-07-13 20:04:48,737 /usr/local/Cellar/python3/3.6.1/Frameworks/Python.framework/Versions/3.6/lib/python3.6/site-packages/grpc/_server.py[func:_call_behavior line:393] [ERROR] Exception calling application: members() missing 1 required positional argument: 'self'
Traceback (most recent call last):
  File "/usr/local/Cellar/python3/3.6.1/Frameworks/Python.framework/Versions/3.6/lib/python3.6/site-packages/grpc/_server.py", line 385, in _call_behavior
    return behavior(argument, context), True
  File "/Users/Shared/dbj/api.kuaibi/micro_service/micro_services/notebook/services/notebook_service.py", line 23, in GetNotebookInfo
    return get_notebook(request, context)
  File "/Users/Shared/dbj/api.kuaibi/micro_service/micro_services/notebook/handlers/get_notebook_handler.py", line 38, in get_notebook
    books = notebook_manger.notebook_from(user_id)
  File "/Users/Shared/dbj/api.kuaibi/micro_service/micro_services/notebook/database/notebook_manger.py", line 82, in notebook_from
    a = self.new_notebook(query)
  File "/Users/Shared/dbj/api.kuaibi/micro_service/micro_services/notebook/database/notebook_manger.py", line 44, in new_notebook
    d = self.filter_data(model, data)
  File "/Users/Shared/dbj/api.kuaibi/micro_service/micro_services/notebook/database/base_manger.py", line 21, in filter_data
    l = model.members()
TypeError: members() missing 1 required positional argument: 'self'
2018-07-13 20:04:48,801 /usr/local/lib/python3.6/site-packages/werkzeug/_internal.py[func:_log line:88] [INFO] 127.0.0.1 - - [13/Jul/2018 20:04:48] "GET /api/notebook HTTP/1.1" 500 -
2018-07-13 20:04:48,856 /usr/local/lib/python3.6/site-packages/werkzeug/_internal.py[func:_log line:88] [INFO] 127.0.0.1 - - [13/Jul/2018 20:04:48] "GET /api/notebook?__debugger__=yes&cmd=resource&f=jquery.js HTTP/1.1" 200 -
2018-07-13 20:04:48,858 /usr/local/lib/python3.6/site-packages/werkzeug/_internal.py[func:_log line:88] [INFO] 127.0.0.1 - - [13/Jul/2018 20:04:48] "GET /api/notebook?__debugger__=yes&cmd=resource&f=debugger.js HTTP/1.1" 200 -
2018-07-13 20:04:48,862 /usr/local/lib/python3.6/site-packages/werkzeug/_internal.py[func:_log line:88] [INFO] 127.0.0.1 - - [13/Jul/2018 20:04:48] "GET /api/notebook?__debugger__=yes&cmd=resource&f=style.css HTTP/1.1" 200 -
2018-07-13 20:04:48,894 /usr/local/lib/python3.6/site-packages/werkzeug/_internal.py[func:_log line:88] [INFO] 127.0.0.1 - - [13/Jul/2018 20:04:48] "GET /api/notebook?__debugger__=yes&cmd=resource&f=ubuntu.ttf HTTP/1.1" 200 -
2018-07-13 20:04:48,933 /usr/local/lib/python3.6/site-packages/werkzeug/_internal.py[func:_log line:88] [INFO] 127.0.0.1 - - [13/Jul/2018 20:04:48] "GET /api/notebook?__debugger__=yes&cmd=resource&f=console.png HTTP/1.1" 200 -
2018-07-13 20:05:01,883 /usr/local/Cellar/python3/3.6.1/Frameworks/Python.framework/Versions/3.6/lib/python3.6/site-packages/grpc/_server.py[func:_call_behavior line:393] [ERROR] Exception calling application: members() missing 1 required positional argument: 'self'
Traceback (most recent call last):
  File "/usr/local/Cellar/python3/3.6.1/Frameworks/Python.framework/Versions/3.6/lib/python3.6/site-packages/grpc/_server.py", line 385, in _call_behavior
    return behavior(argument, context), True
  File "/Users/Shared/dbj/api.kuaibi/micro_service/micro_services/notebook/services/notebook_service.py", line 23, in GetNotebookInfo
    return get_notebook(request, context)
  File "/Users/Shared/dbj/api.kuaibi/micro_service/micro_services/notebook/handlers/get_notebook_handler.py", line 38, in get_notebook
    books = notebook_manger.notebook_from(user_id)
  File "/Users/Shared/dbj/api.kuaibi/micro_service/micro_services/notebook/database/notebook_manger.py", line 82, in notebook_from
    a = self.new_notebook(query)
  File "/Users/Shared/dbj/api.kuaibi/micro_service/micro_services/notebook/database/notebook_manger.py", line 44, in new_notebook
    d = self.filter_data(model, data)
  File "/Users/Shared/dbj/api.kuaibi/micro_service/micro_services/notebook/database/base_manger.py", line 21, in filter_data
    l = model.members()
TypeError: members() missing 1 required positional argument: 'self'
2018-07-13 20:05:01,938 /usr/local/lib/python3.6/site-packages/werkzeug/_internal.py[func:_log line:88] [INFO] 127.0.0.1 - - [13/Jul/2018 20:05:01] "GET /api/notebook HTTP/1.1" 500 -
2018-07-13 20:05:01,971 /usr/local/lib/python3.6/site-packages/werkzeug/_internal.py[func:_log line:88] [INFO] 127.0.0.1 - - [13/Jul/2018 20:05:01] "GET /api/notebook?__debugger__=yes&cmd=resource&f=debugger.js HTTP/1.1" 200 -
2018-07-13 20:05:01,974 /usr/local/lib/python3.6/site-packages/werkzeug/_internal.py[func:_log line:88] [INFO] 127.0.0.1 - - [13/Jul/2018 20:05:01] "GET /api/notebook?__debugger__=yes&cmd=resource&f=jquery.js HTTP/1.1" 200 -
2018-07-13 20:05:01,977 /usr/local/lib/python3.6/site-packages/werkzeug/_internal.py[func:_log line:88] [INFO] 127.0.0.1 - - [13/Jul/2018 20:05:01] "GET /api/notebook?__debugger__=yes&cmd=resource&f=style.css HTTP/1.1" 200 -
2018-07-13 20:05:02,031 /usr/local/lib/python3.6/site-packages/werkzeug/_internal.py[func:_log line:88] [INFO] 127.0.0.1 - - [13/Jul/2018 20:05:02] "GET /api/notebook?__debugger__=yes&cmd=resource&f=ubuntu.ttf HTTP/1.1" 200 -
2018-07-13 20:05:02,091 /usr/local/lib/python3.6/site-packages/werkzeug/_internal.py[func:_log line:88] [INFO] 127.0.0.1 - - [13/Jul/2018 20:05:02] "GET /api/notebook?__debugger__=yes&cmd=resource&f=console.png HTTP/1.1" 200 -
2018-07-13 20:05:46,220 /usr/local/lib/python3.6/site-packages/werkzeug/_internal.py[func:_log line:88] [INFO]  * Detected change in '/Users/Shared/dbj/api.kuaibi/micro_service/micro_services/notebook/models/base_model.py', reloading
2018-07-13 20:05:46,224 /usr/local/lib/python3.6/site-packages/werkzeug/_internal.py[func:_log line:88] [INFO]  * Detected change in '/Users/Shared/dbj/api.kuaibi/micro_service/micro_services/notebook/models/base_model.py', reloading
2018-07-13 20:06:30,807 /Users/Shared/dbj/api.kuaibi/micro_service/common/logger.py[func:__init__ line:23] [INFO] init log
2018-07-13 20:06:32,029 /Users/Shared/dbj/api.kuaibi/micro_service/main.py[func:<module> line:19] [ERROR] error
2018-07-13 20:06:32,029 /Users/Shared/dbj/api.kuaibi/micro_service/main.py[func:<module> line:20] [DEBUG] debug
2018-07-13 20:06:32,267 /usr/local/Cellar/python3/3.6.1/Frameworks/Python.framework/Versions/3.6/lib/python3.6/site-packages/werkzeug/_internal.py[func:_log line:88] [INFO]  * Running on http://0.0.0.0:5002/ (Press CTRL+C to quit)
2018-07-13 20:06:32,339 /usr/local/Cellar/python3/3.6.1/Frameworks/Python.framework/Versions/3.6/lib/python3.6/site-packages/werkzeug/_internal.py[func:_log line:88] [INFO]  * Restarting with fsevents reloader
2018-07-13 20:06:33,503 /Users/Shared/dbj/api.kuaibi/micro_service/common/logger.py[func:__init__ line:23] [INFO] init log
2018-07-13 20:06:34,341 /Users/Shared/dbj/api.kuaibi/micro_service/main.py[func:<module> line:19] [ERROR] error
2018-07-13 20:06:34,341 /Users/Shared/dbj/api.kuaibi/micro_service/main.py[func:<module> line:20] [DEBUG] debug
2018-07-13 20:06:34,572 /usr/local/lib/python3.6/site-packages/werkzeug/_internal.py[func:_log line:88] [WARNING]  * Debugger is active!
2018-07-13 20:06:34,612 /usr/local/lib/python3.6/site-packages/werkzeug/_internal.py[func:_log line:88] [INFO]  * Debugger PIN: 202-833-239
2018-07-13 20:06:39,375 /Users/Shared/dbj/api.kuaibi/micro_service/common/logger.py[func:__init__ line:23] [INFO] init log
2018-07-13 20:06:40,290 /Users/Shared/dbj/api.kuaibi/micro_service/main.py[func:<module> line:19] [ERROR] error
2018-07-13 20:06:40,290 /Users/Shared/dbj/api.kuaibi/micro_service/main.py[func:<module> line:20] [DEBUG] debug
2018-07-13 20:07:15,314 /usr/local/lib/python3.6/site-packages/werkzeug/_internal.py[func:_log line:88] [INFO] 127.0.0.1 - - [13/Jul/2018 20:07:15] "GET /api/notebook HTTP/1.1" 500 -
2018-07-13 20:07:15,344 /usr/local/lib/python3.6/site-packages/werkzeug/_internal.py[func:_log line:88] [INFO] 127.0.0.1 - - [13/Jul/2018 20:07:15] "GET /api/notebook?__debugger__=yes&cmd=resource&f=style.css HTTP/1.1" 200 -
2018-07-13 20:07:15,346 /usr/local/lib/python3.6/site-packages/werkzeug/_internal.py[func:_log line:88] [INFO] 127.0.0.1 - - [13/Jul/2018 20:07:15] "GET /api/notebook?__debugger__=yes&cmd=resource&f=jquery.js HTTP/1.1" 200 -
2018-07-13 20:07:15,350 /usr/local/lib/python3.6/site-packages/werkzeug/_internal.py[func:_log line:88] [INFO] 127.0.0.1 - - [13/Jul/2018 20:07:15] "GET /api/notebook?__debugger__=yes&cmd=resource&f=debugger.js HTTP/1.1" 200 -
2018-07-13 20:07:15,402 /usr/local/lib/python3.6/site-packages/werkzeug/_internal.py[func:_log line:88] [INFO] 127.0.0.1 - - [13/Jul/2018 20:07:15] "GET /api/notebook?__debugger__=yes&cmd=resource&f=ubuntu.ttf HTTP/1.1" 200 -
2018-07-13 20:07:15,446 /usr/local/lib/python3.6/site-packages/werkzeug/_internal.py[func:_log line:88] [INFO] 127.0.0.1 - - [13/Jul/2018 20:07:15] "GET /api/notebook?__debugger__=yes&cmd=resource&f=console.png HTTP/1.1" 200 -
2018-07-13 20:14:28,070 /usr/local/lib/python3.6/site-packages/werkzeug/_internal.py[func:_log line:88] [INFO]  * Detected change in '/Users/Shared/dbj/api.kuaibi/micro_service/micro_services/notebook/database/notebook_manger.py', reloading
2018-07-13 20:14:28,074 /usr/local/lib/python3.6/site-packages/werkzeug/_internal.py[func:_log line:88] [INFO]  * Detected change in '/Users/Shared/dbj/api.kuaibi/micro_service/micro_services/notebook/database/notebook_manger.py', reloading
2018-07-13 20:14:29,374 /Users/Shared/dbj/api.kuaibi/micro_service/common/logger.py[func:__init__ line:23] [INFO] init log
2018-07-13 20:14:30,599 /Users/Shared/dbj/api.kuaibi/micro_service/main.py[func:<module> line:19] [ERROR] error
2018-07-13 20:14:30,599 /Users/Shared/dbj/api.kuaibi/micro_service/main.py[func:<module> line:20] [DEBUG] debug
2018-07-13 20:14:30,830 /usr/local/Cellar/python3/3.6.1/Frameworks/Python.framework/Versions/3.6/lib/python3.6/site-packages/werkzeug/_internal.py[func:_log line:88] [INFO]  * Running on http://0.0.0.0:5002/ (Press CTRL+C to quit)
2018-07-13 20:14:30,905 /usr/local/Cellar/python3/3.6.1/Frameworks/Python.framework/Versions/3.6/lib/python3.6/site-packages/werkzeug/_internal.py[func:_log line:88] [INFO]  * Restarting with fsevents reloader
2018-07-13 20:14:32,059 /Users/Shared/dbj/api.kuaibi/micro_service/common/logger.py[func:__init__ line:23] [INFO] init log
2018-07-13 20:14:33,122 /Users/Shared/dbj/api.kuaibi/micro_service/main.py[func:<module> line:19] [ERROR] error
2018-07-13 20:14:33,123 /Users/Shared/dbj/api.kuaibi/micro_service/main.py[func:<module> line:20] [DEBUG] debug
2018-07-13 20:14:33,375 /usr/local/lib/python3.6/site-packages/werkzeug/_internal.py[func:_log line:88] [WARNING]  * Debugger is active!
2018-07-13 20:14:33,417 /usr/local/lib/python3.6/site-packages/werkzeug/_internal.py[func:_log line:88] [INFO]  * Debugger PIN: 202-833-239
2018-07-13 20:15:04,596 /usr/local/lib/python3.6/site-packages/werkzeug/_internal.py[func:_log line:88] [INFO] 127.0.0.1 - - [13/Jul/2018 20:15:04] "GET /api/notebook HTTP/1.1" 500 -
2018-07-13 20:15:04,659 /usr/local/lib/python3.6/site-packages/werkzeug/_internal.py[func:_log line:88] [INFO] 127.0.0.1 - - [13/Jul/2018 20:15:04] "GET /api/notebook?__debugger__=yes&cmd=resource&f=debugger.js HTTP/1.1" 200 -
2018-07-13 20:15:04,663 /usr/local/lib/python3.6/site-packages/werkzeug/_internal.py[func:_log line:88] [INFO] 127.0.0.1 - - [13/Jul/2018 20:15:04] "GET /api/notebook?__debugger__=yes&cmd=resource&f=style.css HTTP/1.1" 200 -
2018-07-13 20:15:04,665 /usr/local/lib/python3.6/site-packages/werkzeug/_internal.py[func:_log line:88] [INFO] 127.0.0.1 - - [13/Jul/2018 20:15:04] "GET /api/notebook?__debugger__=yes&cmd=resource&f=jquery.js HTTP/1.1" 200 -
