2018-07-15 02:05:36,538 /Users/Shared/dbj/api.kuaibi/micro_service/common/logger.py[func:__init__ line:29] [INFO] init log
2018-07-15 02:05:36,567 /Users/Shared/dbj/api.kuaibi/micro_service/common/logger.py[func:__init__ line:29] [INFO] init log
2018-07-15 02:05:37,460 /Users/Shared/dbj/api.kuaibi/micro_service/micro_services/api_kuaibiji/service.py[func:teardown_request line:56] [ERROR] Traceback (most recent call last):
  File "/Users/Shared/dbj/api.kuaibi/micro_service/rpc/user/user_client.py", line 61, in user_by_id
    timeout=option.timeout_client_side,
  File "/usr/local/lib/python3.6/site-packages/grpc/_channel.py", line 500, in __call__
    return _end_unary_response_blocking(state, call, False, None)
  File "/usr/local/lib/python3.6/site-packages/grpc/_channel.py", line 434, in _end_unary_response_blocking
    raise _Rendezvous(state, None, None, deadline)
grpc._channel._Rendezvous: <_Rendezvous of RPC that terminated with (StatusCode.UNKNOWN, Exception calling application: 'UserManager' object has no attribute 'user_by_userid')>

During handling of the above exception, another exception occurred:

Traceback (most recent call last):
  File "/usr/local/lib/python3.6/site-packages/flask/app.py", line 2295, in wsgi_app
    response = self.handle_exception(e)
  File "/usr/local/lib/python3.6/site-packages/flask/app.py", line 1741, in handle_exception
    reraise(exc_type, exc_value, tb)
  File "/usr/local/lib/python3.6/site-packages/flask/_compat.py", line 35, in reraise
    raise value
  File "/usr/local/lib/python3.6/site-packages/flask/app.py", line 2292, in wsgi_app
    response = self.full_dispatch_request()
  File "/usr/local/lib/python3.6/site-packages/flask/app.py", line 1815, in full_dispatch_request
    rv = self.handle_user_exception(e)
  File "/usr/local/lib/python3.6/site-packages/flask/app.py", line 1718, in handle_user_exception
    reraise(exc_type, exc_value, tb)
  File "/usr/local/lib/python3.6/site-packages/flask/_compat.py", line 35, in reraise
    raise value
  File "/usr/local/lib/python3.6/site-packages/flask/app.py", line 1813, in full_dispatch_request
    rv = self.dispatch_request()
  File "/usr/local/lib/python3.6/site-packages/flask/app.py", line 1799, in dispatch_request
    return self.view_functions[rule.endpoint](**req.view_args)
  File "/Users/Shared/dbj/api.kuaibi/micro_service/micro_services/api_kuaibiji/app/views/user/get_user_info.py", line 29, in get_user
    user = s.user_by_id(user_id)
  File "/Users/Shared/dbj/api.kuaibi/micro_service/rpc/user/user_client.py", line 65, in user_by_id
    raise RPCException(msg='calling rpc application')
common.exceptions.RPCException: RPCException calling rpc application

